Workbook
Name aa: #REF!
Name aa: #REF!
Name aa: #REF!
Name aa: #REF!
Name aa: #REF!
Name aa: #REF!
Name aa: #REF!
Name aa: #REF!
Name aa: #REF!
Name Civil4: #REF!
Name Civil4: #REF!
Name Civil4: #REF!
Name Civil4: #REF!
Name Civil4: #REF!
Name Civil4: #REF!
Name Civil4: #REF!
Name Civil4: #REF!
Name Civil4: #REF!
Name d: #REF!
Name d: #REF!
Name d: #REF!
Name d: #REF!
Name d: #REF!
Name d: #REF!
Name d: #REF!
Name d: #REF!
Name d: #REF!
Name date: #REF!
Name date: #REF!
Name date: #REF!
Name date: #REF!
Name date: #REF!
Name date: #REF!
Name date: #REF!
Name date: #REF!
Name date: #REF!
Name daz: #REF!
Name daz: #REF!
Name daz: #REF!
Name daz: #REF!
Name daz: #REF!
Name daz: #REF!
Name daz: #REF!
Name daz: #REF!
Name ddd: #REF!
Name ddd: #REF!
Name ddd: #REF!
Name ddd: #REF!
Name ddd: #REF!
Name ddd: #REF!
Name ddd: #REF!
Name ddd: #REF!
Name for: #REF!
Name for: #REF!
Name for: #REF!
Name for: #REF!
Name for: #REF!
Name for: #REF!
Name for: #REF!
Name for: #REF!

Sheet TCS $ Sched
B6: SUMMARY | V6: BIG TICKET ITEMS
B8: JOB DESCRIPTION: | I8: ROK Sports Precinct | N8: DATE: | O8: 26/07/2026 | V8: Club house (NBC )
B9: SITE ADDRESS: | I9: 554-700 Yaamba Rd, Norman Gardens QLD 4701 | N9: TPS-TEN16699-V2
R10: Cost | S10: (Cost + O/H) + Profit | V10: 1500 Liters Git Viking Panel TIm in Ground ( grease trap ) | Y10: Hot Water Pump set to suit Rheem Hot Water Unit | AB10: Rheem HWU
N11: TOTALS | V11: Purchase Cost Total | W11: =6110+2413.28 -> 8523.28 | Y11: Purchase Cost Total | Z11: 6775.83 | AB11: Purchase Cost Total | AC11: 3438.29
AB12: Safe Tray | AC12: 52.8
V13: TPS Markup | W13: 1.15 | Y13: TPS Markup | Z13: 1.15 | AB13: TPS Markup | AC13: 1.15
V14: Qty | W14: 1 | Y14: Qty | Z14: 1 | AB14: Qty | AC14: 2
I15: N16 rewired = S16+W17+Z17+AC17 - NBC Rheem HWU block was orphaned (never reached summary) | V15: Freight | W15: 250 | Y15: Freight | Z15: 150 | AB15: Freight | AC15: 300
I16: CLUBHOUSE | N16: =S16+W17+Z17+AC17 -> 692573.54 | R16: ='ClubHouse (NBC )'!F943 -> 470848.1 | S16: =((R16/$R$39)*($R$49-$R$39))+R16 -> 666250.06 | V16: Installation_MH | W16: 0 | X16: RULE 4: token $250 set to $0 26/07/26 - installation labour is priced in Phase 7 activity T1-08: NBC trade waste 110 HDPE + Geberit 50 + 1500L Viking GIT install (8 crew-days, Crew 1; rate basis explicitly includes 'GIT excavation/set'; plant 3-5T exc 4d + crane truck 1d). Commissioning in T5-02. Retaining the token would DOUBLE-COUNT. Supply, freight, safe tray and mounting are priced separately - see EQUIPMENT_TEST_TPS.md. | Y16: Installation_MH | Z16: 0 | AA16: RULE 4: token $200 set to $0 26/07/26 - installation labour is priced in Phase 7 activity T4-03: 2x Rheem 315L HWU + HW circulating pump + flow/return loop (3 crew-days, Crew 4). Commissioning in T5-06. Retaining the token would DOUBLE-COUNT. Supply, freight, safe tray and mounting are priced separately - see EQUIPMENT_TEST_TPS.md. | AB16: Installation_MH | AC16: 0 | AD16: RULE 4: token $600 set to $0 26/07/26 - installation labour is priced in Phase 7 activity T4-03: 2x Rheem 315L HWU + HW circulating pump + flow/return loop (3 crew-days, Crew 4; crane truck 0.5d for HWU delivery/set). Commissioning in T5-06 ('HWU'). Retaining the token would DOUBLE-COUNT. Supply, freight, safe tray and mounting are priced separately - see EQUIPMENT_TEST_TPS.md.
V17: TOTAL | W17: =W11*W13*W14+W15+W16 -> 10051.772 | Y17: TOTAL | Z17: =Z11*Z13*Z14+Z15+Z16 -> 7942.2045 | AB17: TOTAL | AC17: =(AC11+AC12)*AC13*AC14+AC15+AC16 -> 8329.507
AB18: HWU qty 2 adopted (QUANTITY_RECONCILIATION TPS_NBC - take-off double-count removed; 2 drawn H-NBC-200/202)
V21: Public Amenities Block
I23: PUBLIC AMENITIES | N23: =S23+W31 -> 157680.56 | R23: ='Public Amenities (PAM)'!F864 -> 109647.6 | S23: =((R23/$R$39)*($R$49-$R$39))+R23 -> 155151.35
V24: Rheem HWU | X24: PAM HWU is Rheem 50L 613/050 (H-PAM-200) - rate corrected from $3,438.29 (315L model) to $2,016.08 (Reece Q-459014431)
V25: Purchase Cost Total | W25: 2016.08
V26: Safe Tray | W26: 52.8
V27: TPS Markup | W27: 1.15
V28: Qty | W28: 1
I29: SITEWORKS | N29: =S29 -> 641445.4 | R29: ='Siteworks '!F874 -> 453318.3 | S29: =((R29/$R$39)*($R$49-$R$39))+R29 -> 641445.4 | V29: Freight | W29: 150
V30: Installation_MH | W30: 0 | X30: RULE 4: token $200 set to $0 26/07/26 - installation labour is priced in Phase 7 activity T4-06: PAM Rheem 50L HWU + TMV + O32 check-meter assembly (1 crew-day, Crew 4). Commissioning in T5-06. Retaining the token would DOUBLE-COUNT. Supply, freight, safe tray and mounting are priced separately - see EQUIPMENT_TEST_TPS.md.
V31: TOTAL | W31: =(W25+W26)*W27*W28+W29+W30 -> 2529.212
I32: ACCOMMODATION - FIFO Option A (apartments + LH nightly) | N32: =S32 -> 124117.25 | R32: =14*'LabourProject Rates_Master'!E103+225*'LabourProject Rates_Master'!E109 -> 87715.368 | S32: =((R32/$R$39)*($R$49-$R$39))+R32 -> 124117.25 | T32: Phase 7 Accommodation TPS: 14 apt-months x $4,606.06 (crew of 3/apt) + LH 225 nights x $103.2468 = $87,715 (Option A recommended). Option B all-individual = 1,275 nights x $103.2468 = $131,640 - premium $43,925 not taken. No sharing with TCS (SS5.2).
I33: FLIGHTS - FIFO roster (return every 2nd w/e) | N33: =S33 -> 63505.2 | R33: =51*2*2*220 -> 44880 | S33: =((R33/$R$39)*($R$49-$R$39))+R33 -> 63505.2 | T33: 51 person-months (Phase 7) x 2 returns/person-month x 2 legs x $220/leg = $44,880 - assumption stated (Misc Rates flight basis)
V34: Sewer pump station EXCLUDED - installed by Council per Addendum 2 (10 Jul 2026); interfaces per interface ledger L6; add-price held in EBC register (APS 14065 basis) - see EBC_Alternates. Prior orphaned block W37 $468,000 -> W43 $545,700 removed (fed no roll-up; never in N64).
R39: =SUM(R13:R38) -> 1166409.4
P42: Prelim | Q42: 0.055 | R42: =R39*Q42 -> 64152.515 | S42: of total cost
P43: O/H | Q43: 0.18 | R43: =R39*Q43 -> 209953.69 | S43: of total cost
P45: Sub Total | R45: =SUM(R39:R44) -> 1440515.6 | S45: total cost + Prelim + O/H
P47: Gross Profit | Q47: 0.18 | R47: =R39*Q47 -> 209953.69 | S47: of total cost (SS5.4 re-base 26/07/26; was =R45*Q47 -> effective 45.73%)
R49: =SUM(R45:R47) -> 1650469.3
P51: Total Markup | Q51: =SUM(Q42:Q50) -> 0.415
P53: Net Profit Incl Equip | R53: =R48 -> 0
M64: TOTAL - TPS BASE SELL ex GST (excl PC Sums) | N64: =SUM(N16:N63) -> 1679321.9
M66: GST rows removed - ALL PRICING EX GST per SS5.4
P67: Prelim | Q67: =R42/R39 -> 0.055
P68: O/H | Q68: =R43/R39 -> 0.18
Q69: .
M70: PC SUMS - separate identified lines (ex GST) | P70: Sub Total | R70: Fixtures PC build (ex GST)
M71: PC-1A Fixtures supply - Tradelink 1066143 adjusted + 15% | N71: =(S71+S72+S73+S74)*1.15 -> 207268.84 | O71: Quote validity 13/08/26 vs 2027 start - escalation/validity qualification carried; Phase 4 line-by-line reconciliation mandatory | R71: Tradelink 1066143 quote total | S71: 252694.77
...

Sheet 00_ TCS Prelim & OH
B1: Project:
B2: Tricore -
B3: Stage 1 Version 1
A4: Item | K4: Source
A7: A | B7: PRELIMINARIES
B8: SUMMARY (Not added in prelim$)
C9: TOTAL Days Mobilized On Site | D9: 285 | G9: Re-based from Phase 7 TPS_Programme (link [1] severed): 197 work days across 3 discrete site windows; 10 months elapsed less inter-window demob = 285 calendar days on site | K9: frozen from [1] CQU ROK_PROGRAM - MASTER.V1 (SharePoint) - link severed 26/07/26; re-based from Phase 7 TPS_Programme
C10: Months Mobilized | D10: 9.4 | K10: frozen from [1] CQU ROK_PROGRAM - MASTER.V1 (SharePoint) - link severed 26/07/26; re-based from Phase 7 TPS_Programme
C11: Work Weeks' Mobilized On Site | D11: 40 | K11: frozen from [1] CQU ROK_PROGRAM - MASTER.V1 (SharePoint) - link severed 26/07/26; re-based from Phase 7 TPS_Programme
C12: Work Days | D12: 197 | G12: 197 work days = Phase 7 programme finish (T5-07 as-cons) | K12: frozen from [1] CQU ROK_PROGRAM - MASTER.V1 (SharePoint) - link severed 26/07/26; re-based from Phase 7 TPS_Programme
C13: Breakdown as per program
B14: ='LabourProject Rates_Master'!$B$14 -> TRADESMAN_LEADING HAND | C14: Day | E14: =E36 -> 1329.6343 | F14: =D14*E14 -> 0
B15: ='LabourProject Rates_Master'!$B$23 -> TRADESMAN_PLUMBER_OPERATOR | C15: Day | E15: =E37 -> 1016.4579 | F15: =D15*E15 -> 0
B16: ='LabourProject Rates_Master'!$B$30 -> T/A & Apprentice | C16: Day | E16: =E38 -> 829.51029 | F16: =D16*E16 -> 0
B17: ='LabourProject Rates_Master'!$B$36 -> Crew #1 - InGround Drainage | C17: Day | E17: =E39 -> 2862.4261 | F17: =D17*E17 -> 0
B18: ='LabourProject Rates_Master'!$B$43 -> Crew #2 - InGround Water/Fire | C18: Day | E18: =E40 -> 2862.4261 | F18: =D18*E18 -> 0
E19: Total Labour | F19: =SUM(F14:F18) -> 0
C20: Total as per stage boq
E21: Total Part A Labour | F21: 0
E22: Total Stage 1 Labour | F22: 0
E23: Total Stage 2 Labour | F23: 0
E24: Total Stage 3 Labour | F24: 0
E25: Total Stage 4 Labour | F25: 0
F26: =SUM(F21:F25) -> 0
E27: Difference | F27: =F26-F19 -> 0
C29: Unit | D29: REQ | E29: Cost ex GST | F29: Total ex GST
B30: Labour
B33: Contingencies; Wet Weather ?
B35: Superviser; Return Trip, 2 day stay - Inclusive | C35: item | E35: 2423.831 | F35: =D35*E35 -> 0
B36: ='LabourProject Rates_Master'!$B$14 -> TRADESMAN_LEADING HAND | C36: Day | D36: 0 | E36: ='LabourProject Rates_Master'!$E$15 -> 1329.6343 | F36: =E36*D36 -> 0 | G36: MEMO ONLY - 140 LH supervision days (1,400 hr) are priced IN the three work-area labour blocks per Phase 7 (Siteworks 489.2 + NBC 742.1 + PAM 168.5 = 1,399.8 hr). Not repeated here - double-count control.
B37: ='LabourProject Rates_Master'!$B$23 -> TRADESMAN_PLUMBER_OPERATOR | C37: Day | E37: ='LabourProject Rates_Master'!$E$22 -> 1016.4579 | F37: =E37*D37 -> 0
B38: ='LabourProject Rates_Master'!$B$30 -> T/A & Apprentice | C38: Day | E38: ='LabourProject Rates_Master'!$E$29 -> 829.51029 | F38: =E38*D38 -> 0
B39: ='LabourProject Rates_Master'!$B$36 -> Crew #1 - InGround Drainage | C39: Day | E39: ='LabourProject Rates_Master'!$E$37 -> 2862.4261 | F39: =E39*D39 -> 0
B40: ='LabourProject Rates_Master'!$B$43 -> Crew #2 - InGround Water/Fire | C40: Day | E40: ='LabourProject Rates_Master'!$E$44 -> 2862.4261 | F40: =E40*D40 -> 0
B42: Management Labour
B44: ='LabourProject Rates_Master'!$B$14 -> TRADESMAN_LEADING HAND | C44: Day | E44: ='LabourProject Rates_Master'!$E$15 -> 1329.6343 | F44: =E44*D44 -> 0 | G44: Included within stages?
B45: MH / DQ | C45: Day | E45: 120 | F45: =E45*D45 -> 0 | G45: Refer Program for approx attendance on site. Technically covered in overheads. E/O for meals etc?
B46: MH / DQ - FLIGHTS | C46: ea | E46: 200 | F46: =E46*D46 -> 0
B51: ACCOMODATION (Refer Program)
B52: Per Month - Full Project (6 Persons)
...

Sheet ClubHouse (NBC )
B1: Project:
B2: Tricore -
B3: Stage 1 Version 1
A4: Item
A9: 1 | B9: Complete -
B12: Labour
G13: Denis qty | H13: Qty / rate source note
B14: DAY | J14: april 2026 direct impact Increase % (not contigency)
B15: ='LabourProject Rates_Master'!$B$14 -> TRADESMAN_LEADING HAND | C15: Day | E15: ='LabourProject Rates_Master'!$E$15 -> 1329.6343 | F15: =E15*D15 -> 0
B16: ='LabourProject Rates_Master'!$B$23 -> TRADESMAN_PLUMBER_OPERATOR | C16: Day | E16: ='LabourProject Rates_Master'!$E$22 -> 1016.4579 | F16: =E16*D16 -> 0 | K16: PE Pipe & Fitting | L16: 0.38 | M16: 1.38
B17: ='LabourProject Rates_Master'!$B$30 -> T/A & Apprentice | C17: Day | E17: ='LabourProject Rates_Master'!$E$29 -> 829.51029 | F17: =E17*D17 -> 0 | K17: PVC Pipe & Fittings | L17: 0.38 | M17: 1.38
B18: ='LabourProject Rates_Master'!$B$36 -> Crew #1 - InGround Drainage | C18: Day | D18: 26 | E18: ='LabourProject Rates_Master'!$E$37 -> 2862.4261 | F18: =E18*D18 -> 74423.079 | H18: Phase 7 crew-days: T1-07 14 + T1-08 8 + T1-10 4 (DP stubs NBC+PAM) | K18: Subby Rates | L18: 0.15 | M18: 1.15
B19: ='LabourProject Rates_Master'!$B$43 -> Crew #2 - InGround Water/Fire | C19: Day | E19: ='LabourProject Rates_Master'!$E$44 -> 2862.4261 | F19: =E19*D19 -> 0 | K19: Delivey Rate | L19: 0.2 | M19: 1.2
B20: ='LabourProject Rates_Master'!B51 -> Crew #3 - Above Ground Drainage | C20: Day | D20: 14 | E20: ='LabourProject Rates_Master'!E52 -> 2862.4261 | F20: =E20*D20 -> 40073.965 | H20: Phase 7 crew-days: T3-01 6 + T3-02 5 + T3-04 3
B21: ='LabourProject Rates_Master'!B59 -> Crew #4 - Above Ground WATER/FIRE | C21: Day | D21: 21 | E21: ='LabourProject Rates_Master'!E60 -> 2862.4261 | F21: =E21*D21 -> 60110.948 | H21: Phase 7 crew-days: T4-01 12 + T4-02 3 + T4-03 3 + T4-04 1 + T4-07 2
B22: ='LabourProject Rates_Master'!B67 -> Crew #5 - Above Ground FitOff / Misc | C22: Day | D22: 27 | E22: ='LabourProject Rates_Master'!E68 -> 2862.4261 | F22: =E22*D22 -> 77285.505 | H22: Phase 7 crew-days: T5-01 13 + T5-02 3 + T5-04a 1 + T5-05 3 + T5-06 4 + T5-07 3
B23: ='LabourProject Rates_Master'!B75 -> Crew #6 - DEMO | C23: Day | E23: ='LabourProject Rates_Master'!E76 -> 1845.9682 | F23: =E23*D23 -> 0
B27: HOUR
B28: ='LabourProject Rates_Master'!$B$14 -> TRADESMAN_LEADING HAND | C28: HR | D28: 742.1 | E28: ='LabourProject Rates_Master'!$E$14 -> 132.96343 | F28: =E28*D28 -> 98672.16 | H28: Phase 7 LH supervision - NBC activities 742.1 hr
B29: ='LabourProject Rates_Master'!$B$23 -> TRADESMAN_PLUMBER_OPERATOR | C29: HR | D29: 0 | E29: ='LabourProject Rates_Master'!$E$21 -> 101.64579 | F29: =E29*D29 -> 0
B30: ='LabourProject Rates_Master'!$B$30 -> T/A & Apprentice | C30: HR | D30: 0 | E30: ='LabourProject Rates_Master'!$E$28 -> 82.951029 | F30: =E30*D30 -> 0
B31: ='LabourProject Rates_Master'!$B$36 -> Crew #1 - InGround Drainage | C31: HR | D31: 0 | E31: ='LabourProject Rates_Master'!$E$36 -> 286.24261 | F31: =E31*D31 -> 0
B32: ='LabourProject Rates_Master'!$B$43 -> Crew #2 - InGround Water/Fire | C32: HR | D32: 0 | E32: ='LabourProject Rates_Master'!$E$43 -> 286.24261 | F32: =E32*D32 -> 0
B35: Demolition & Reinstatement
B36: DEMO
B37: ='Misc Subbie Rates_Master'!A49 -> Asphalt Cutting | C37: m | E37: ='Misc Subbie Rates_Master'!D49+('Misc Subbie Rates_Master'!D49*$L$18) -> 15.525 | F37: =E37*D37 -> 0
B38: ='Misc Subbie Rates_Master'!A50 -> Concrete Cutting | C38: m | E38: ='Misc Subbie Rates_Master'!D50+('Misc Subbie Rates_Master'!D50*$L$18) -> 18.4 | F38: =E38*D38 -> 0
B39: Con Cut Establishemnt Fee | C39: ea | E39: ='Misc Subbie Rates_Master'!D51+('Misc Subbie Rates_Master'!D51*$L$18) -> 92 | F39: =E39*D39 -> 0
B40: REINSTATE - CONCRETE
B41: ='Misc Subbie Rates_Master'!A56 -> Road/Drveway Reinstate; 1mW x 150 Thck, N25/20/80, Incl Reinforcement | C41: m | E41: ='Misc Subbie Rates_Master'!D56 -> 145 | F41: =E41*D41 -> 0
B42: ='Misc Subbie Rates_Master'!A57 -> Kerb & Channel - 1m Wide | C42: ea | E42: ='Misc Subbie Rates_Master'!D57 -> 155 | F42: =E42*D42 -> 0
B43: ='Misc Subbie Rates_Master'!A58 -> Footpath - 1.5mW, N25/20/80, Incl Reinforcement | C43: lm | E43: ='Misc Subbie Rates_Master'!D58 -> 180 | F43: =E43*D43 -> 0
B44: ='Misc Subbie Rates_Master'!A59 -> Footpath - 1.5mW, EXPOSED AGG, N25/20/80, Incl Reinforcement | C44: lm | E44: ='Misc Subbie Rates_Master'!D59 -> 185 | F44: =E44*D44 -> 0
B45: REINSTATE - ASPHALT
B46: ='Misc Subbie Rates_Master'!A64 -> 50mm Thck - Trench Reinstatement Through Road/Driveway | C46: m2 | E46: ='Misc Subbie Rates_Master'!D64 -> 97 | F46: =E46*D46 -> 0
B47: ='Misc Subbie Rates_Master'!A65 -> 50mm Thck - 1.5-2m Wide Footpath reinstatements | C47: m2 | E47: ='Misc Subbie Rates_Master'!D65 -> 97 | F47: =E47*D47 -> 0
B48: ='Misc Subbie Rates_Master'!A66 -> Establishment Fee (1 per stage) | C48: Ea | E48: ='Misc Subbie Rates_Master'!D66 -> 5500 | F48: =E48*D48 -> 0
B50: Equipment & Hire - INCL WET PLANT HIRE
A52: HIDDEN | B52: PLANT HIRE - WET
B53: 1.8T Excavator | C53: Hr | E53: ='Misc Subbie Rates_Master'!D10 -> 100 | F53: =E53*D53 -> 0
...

Sheet Public Amenities (PAM)
B1: Project:
B2: Tricore -
B3: Stage 1 Version 1
A4: Item
A9: 1 | B9: Complete -
B12: Labour
G13: Denis qty | H13: Qty / rate source note
B14: DAY | J14: april 2026 direct impact Increase % (not contigency)
B15: ='LabourProject Rates_Master'!$B$14 -> TRADESMAN_LEADING HAND | C15: Day | E15: ='LabourProject Rates_Master'!$E$15 -> 1329.6343 | F15: =E15*D15 -> 0
B16: ='LabourProject Rates_Master'!$B$23 -> TRADESMAN_PLUMBER_OPERATOR | C16: Day | E16: ='LabourProject Rates_Master'!$E$22 -> 1016.4579 | F16: =E16*D16 -> 0 | K16: PE Pipe & Fitting | L16: 0.38 | M16: 1.38
B17: ='LabourProject Rates_Master'!$B$30 -> T/A & Apprentice | C17: Day | E17: ='LabourProject Rates_Master'!$E$29 -> 829.51029 | F17: =E17*D17 -> 0 | K17: PVC Pipe & Fittings | L17: 0.38 | M17: 1.38
B18: ='LabourProject Rates_Master'!$B$36 -> Crew #1 - InGround Drainage | C18: Day | D18: 4 | E18: ='LabourProject Rates_Master'!$E$37 -> 2862.4261 | F18: =E18*D18 -> 11449.704 | H18: Phase 7 crew-days (1B): T1-09 PAM UG drainage 4 | K18: Subby Rates | L18: 0.15 | M18: 1.15
B19: ='LabourProject Rates_Master'!$B$43 -> Crew #2 - InGround Water/Fire | C19: Day | D19: 4 | E19: ='LabourProject Rates_Master'!$E$44 -> 2862.4261 | F19: =E19*D19 -> 11449.704 | H19: Phase 7 crew-days (1B): T2-09 1B site branch take-offs 4 (1B scope carried on PAM sheet as 1B roll-up collector - interface L9) | K19: Delivey Rate | L19: 0.2 | M19: 1.2
B20: ='LabourProject Rates_Master'!B51 -> Crew #3 - Above Ground Drainage | C20: Day | D20: 2 | E20: ='LabourProject Rates_Master'!E52 -> 2862.4261 | F20: =E20*D20 -> 5724.8522 | H20: Phase 7 crew-days (1B): T3-03 PAM vent + AG waste 2
B21: ='LabourProject Rates_Master'!B59 -> Crew #4 - Above Ground WATER/FIRE | C21: Day | D21: 5 | E21: ='LabourProject Rates_Master'!E60 -> 2862.4261 | F21: =E21*D21 -> 14312.13 | H21: Phase 7 crew-days (1B): T4-05 4 + T4-06 1
B22: ='LabourProject Rates_Master'!B67 -> Crew #5 - Above Ground FitOff / Misc | C22: Day | D22: 5 | E22: ='LabourProject Rates_Master'!E68 -> 2862.4261 | F22: =E22*D22 -> 14312.13 | H22: Phase 7 crew-days (1B): T5-03 4 + T5-04b 1 (bubbler install)
B23: ='LabourProject Rates_Master'!B75 -> Crew #6 - DEMO | C23: Day | E23: ='LabourProject Rates_Master'!E76 -> 1845.9682 | F23: =E23*D23 -> 0
B25: HOUR
B26: ='LabourProject Rates_Master'!$B$14 -> TRADESMAN_LEADING HAND | C26: HR | D26: 168.5 | E26: ='LabourProject Rates_Master'!$E$14 -> 132.96343 | F26: =E26*D26 -> 22404.338 | H26: Phase 7 LH supervision - 1B activities 168.5 hr
B27: ='LabourProject Rates_Master'!$B$23 -> TRADESMAN_PLUMBER_OPERATOR | C27: HR | D27: 0 | E27: ='LabourProject Rates_Master'!$E$21 -> 101.64579 | F27: =E27*D27 -> 0
B28: ='LabourProject Rates_Master'!$B$30 -> T/A & Apprentice | C28: HR | D28: 0 | E28: ='LabourProject Rates_Master'!$E$28 -> 82.951029 | F28: =E28*D28 -> 0
B29: ='LabourProject Rates_Master'!$B$36 -> Crew #1 - InGround Drainage | C29: HR | D29: 0 | E29: ='LabourProject Rates_Master'!$E$36 -> 286.24261 | F29: =E29*D29 -> 0
B30: ='LabourProject Rates_Master'!$B$43 -> Crew #2 - InGround Water/Fire | C30: HR | D30: 0 | E30: ='LabourProject Rates_Master'!$E$43 -> 286.24261 | F30: =E30*D30 -> 0
B33: Demolition & Reinstatement
B34: DEMO
B35: ='Misc Subbie Rates_Master'!A49 -> Asphalt Cutting | C35: m | E35: ='Misc Subbie Rates_Master'!D49+('Misc Subbie Rates_Master'!D49*$L$18) -> 15.525 | F35: =E35*D35 -> 0
B36: ='Misc Subbie Rates_Master'!A50 -> Concrete Cutting | C36: m | E36: ='Misc Subbie Rates_Master'!D50+('Misc Subbie Rates_Master'!D50*$L$18) -> 18.4 | F36: =E36*D36 -> 0
B37: Con Cut Establishemnt Fee | C37: ea | E37: ='Misc Subbie Rates_Master'!D51+('Misc Subbie Rates_Master'!D51*$L$18) -> 92 | F37: =E37*D37 -> 0
B38: REINSTATE - CONCRETE
B39: ='Misc Subbie Rates_Master'!A56 -> Road/Drveway Reinstate; 1mW x 150 Thck, N25/20/80, Incl Reinforcement | C39: m | E39: ='Misc Subbie Rates_Master'!D56 -> 145 | F39: =E39*D39 -> 0
B40: ='Misc Subbie Rates_Master'!A57 -> Kerb & Channel - 1m Wide | C40: ea | E40: ='Misc Subbie Rates_Master'!D57 -> 155 | F40: =E40*D40 -> 0
B41: ='Misc Subbie Rates_Master'!A58 -> Footpath - 1.5mW, N25/20/80, Incl Reinforcement | C41: lm | E41: ='Misc Subbie Rates_Master'!D58 -> 180 | F41: =E41*D41 -> 0
B42: ='Misc Subbie Rates_Master'!A59 -> Footpath - 1.5mW, EXPOSED AGG, N25/20/80, Incl Reinforcement | C42: lm | E42: ='Misc Subbie Rates_Master'!D59 -> 185 | F42: =E42*D42 -> 0
B43: REINSTATE - ASPHALT
B44: ='Misc Subbie Rates_Master'!A64 -> 50mm Thck - Trench Reinstatement Through Road/Driveway | C44: m2 | E44: ='Misc Subbie Rates_Master'!D64 -> 97 | F44: =E44*D44 -> 0
B45: ='Misc Subbie Rates_Master'!A65 -> 50mm Thck - 1.5-2m Wide Footpath reinstatements | C45: m2 | E45: ='Misc Subbie Rates_Master'!D65 -> 97 | F45: =E45*D45 -> 0
B46: ='Misc Subbie Rates_Master'!A66 -> Establishment Fee (1 per stage) | C46: Ea | E46: ='Misc Subbie Rates_Master'!D66 -> 5500 | F46: =E46*D46 -> 0
B48: Equipment & Hire - INCL WET PLANT HIRE
B50: PLANT HIRE - WET
B51: 1.8T Excavator | C51: Hr | E51: ='Misc Subbie Rates_Master'!D10 -> 100 | F51: =E51*D51 -> 0
...

Sheet Siteworks 
B1: Project:
B2: Tricore -
B3: Stage 1 Version 1
A4: Item
A9: 1 | B9: Complete -
B12: Labour
G13: Denis qty | H13: Qty / rate source note
B14: DAY | J14: april 2026 direct impact Increase % (not contigency)
B15: ='LabourProject Rates_Master'!$B$14 -> TRADESMAN_LEADING HAND | C15: Day | E15: ='LabourProject Rates_Master'!$E$15 -> 1329.6343 | F15: =E15*D15 -> 0
B16: ='LabourProject Rates_Master'!$B$23 -> TRADESMAN_PLUMBER_OPERATOR | C16: Day | E16: ='LabourProject Rates_Master'!$E$22 -> 1016.4579 | F16: =E16*D16 -> 0 | K16: PE Pipe & Fitting | L16: 0.38 | M16: 1.38
B17: ='LabourProject Rates_Master'!$B$30 -> T/A & Apprentice | C17: Day | E17: ='LabourProject Rates_Master'!$E$29 -> 829.51029 | F17: =E17*D17 -> 0 | K17: PVC Pipe & Fittings | L17: 0.38 | M17: 1.38
B18: ='LabourProject Rates_Master'!$B$36 -> Crew #1 - InGround Drainage | C18: Day | D18: 23 | E18: ='LabourProject Rates_Master'!$E$37 -> 2862.4261 | F18: =E18*D18 -> 65835.8 | H18: Phase 7 Crew 1 site: T1-01..T1-05 + T1-11 + T1-12 = 23 crew-days (T1-06 rising main EBC excluded) | K18: Subby Rates | L18: 0.15 | M18: 1.15
B19: ='LabourProject Rates_Master'!$B$43 -> Crew #2 - InGround Water/Fire | C19: Day | D19: 35 | E19: ='LabourProject Rates_Master'!$E$44 -> 2862.4261 | F19: =E19*D19 -> 100184.91 | H19: Phase 7 Crew 2 site: T2-01..T2-08 + T2-10 = 35 crew-days | K19: Delivey Rate | L19: 0.2 | M19: 1.2
B20: ='LabourProject Rates_Master'!B51 -> Crew #3 - Above Ground Drainage | C20: Day | E20: ='LabourProject Rates_Master'!E52 -> 2862.4261 | F20: =E20*D20 -> 0
B21: ='LabourProject Rates_Master'!B59 -> Crew #4 - Above Ground WATER/FIRE | C21: Day | E21: ='LabourProject Rates_Master'!E60 -> 2862.4261 | F21: =E21*D21 -> 0
B22: ='LabourProject Rates_Master'!B67 -> Crew #5 - Above Ground FitOff / Misc | C22: Day | E22: ='LabourProject Rates_Master'!E68 -> 2862.4261 | F22: =E22*D22 -> 0
B23: ='LabourProject Rates_Master'!B75 -> Crew #6 - DEMO | C23: Day | E23: ='LabourProject Rates_Master'!E76 -> 1845.9682 | F23: =E23*D23 -> 0
B25: HOUR
B26: ='LabourProject Rates_Master'!$B$14 -> TRADESMAN_LEADING HAND | C26: HR | D26: 489.2 | E26: ='LabourProject Rates_Master'!$E$14 -> 132.96343 | F26: =E26*D26 -> 65045.709 | H26: Phase 7 LH supervision - site activities 489.2 hr (of 1,400 hr / 140 d total)
B27: ='LabourProject Rates_Master'!$B$23 -> TRADESMAN_PLUMBER_OPERATOR | C27: HR | D27: 0 | E27: ='LabourProject Rates_Master'!$E$21 -> 101.64579 | F27: =E27*D27 -> 0
B28: ='LabourProject Rates_Master'!$B$30 -> T/A & Apprentice | C28: HR | D28: 0 | E28: ='LabourProject Rates_Master'!$E$28 -> 82.951029 | F28: =E28*D28 -> 0
B29: ='LabourProject Rates_Master'!$B$36 -> Crew #1 - InGround Drainage | C29: HR | D29: 0 | E29: ='LabourProject Rates_Master'!$E$36 -> 286.24261 | F29: =E29*D29 -> 0
B30: ='LabourProject Rates_Master'!$B$43 -> Crew #2 - InGround Water/Fire | C30: HR | D30: 0 | E30: ='LabourProject Rates_Master'!$E$43 -> 286.24261 | F30: =E30*D30 -> 0
B33: Demolition & Reinstatement
B34: DEMO
B35: ='Misc Subbie Rates_Master'!A49 -> Asphalt Cutting | C35: m | E35: ='Misc Subbie Rates_Master'!D49+('Misc Subbie Rates_Master'!D49*$L$18) -> 15.525 | F35: =E35*D35 -> 0
B36: ='Misc Subbie Rates_Master'!A50 -> Concrete Cutting | C36: m | E36: ='Misc Subbie Rates_Master'!D50+('Misc Subbie Rates_Master'!D50*$L$18) -> 18.4 | F36: =E36*D36 -> 0
B37: Con Cut Establishemnt Fee | C37: ea | E37: ='Misc Subbie Rates_Master'!D51+('Misc Subbie Rates_Master'!D51*$L$18) -> 92 | F37: =E37*D37 -> 0
B38: REINSTATE - CONCRETE
B39: ='Misc Subbie Rates_Master'!A56 -> Road/Drveway Reinstate; 1mW x 150 Thck, N25/20/80, Incl Reinforcement | C39: m | E39: ='Misc Subbie Rates_Master'!D56 -> 145 | F39: =E39*D39 -> 0
B40: ='Misc Subbie Rates_Master'!A57 -> Kerb & Channel - 1m Wide | C40: ea | E40: ='Misc Subbie Rates_Master'!D57 -> 155 | F40: =E40*D40 -> 0
B41: ='Misc Subbie Rates_Master'!A58 -> Footpath - 1.5mW, N25/20/80, Incl Reinforcement | C41: lm | E41: ='Misc Subbie Rates_Master'!D58 -> 180 | F41: =E41*D41 -> 0
B42: ='Misc Subbie Rates_Master'!A59 -> Footpath - 1.5mW, EXPOSED AGG, N25/20/80, Incl Reinforcement | C42: lm | E42: ='Misc Subbie Rates_Master'!D59 -> 185 | F42: =E42*D42 -> 0
B43: REINSTATE - ASPHALT
B44: ='Misc Subbie Rates_Master'!A64 -> 50mm Thck - Trench Reinstatement Through Road/Driveway | C44: m2 | E44: ='Misc Subbie Rates_Master'!D64 -> 97 | F44: =E44*D44 -> 0
B45: ='Misc Subbie Rates_Master'!A65 -> 50mm Thck - 1.5-2m Wide Footpath reinstatements | C45: m2 | E45: ='Misc Subbie Rates_Master'!D65 -> 97 | F45: =E45*D45 -> 0
B46: ='Misc Subbie Rates_Master'!A66 -> Establishment Fee (1 per stage) | C46: Ea | E46: ='Misc Subbie Rates_Master'!D66 -> 5500 | F46: =E46*D46 -> 0
B48: Equipment & Hire - INCL WET PLANT HIRE
B50: PLANT HIRE - WET
B51: 1.8T Excavator | C51: Hr | E51: ='Misc Subbie Rates_Master'!D10 -> 100 | F51: =E51*D51 -> 0
...

Sheet LabourProject Rates_Master
B1: Project:
B2: Tricore -
B3: Stage 1 Version 1
A4: Item | I4: Source
B6: BASED ON:
B7: Work ROSTER Example #3 - 6-Day Week, 10Hr Days, Stay @ Rocky for W/E, Return Every 2nd W/E. (FLY) | I7: frozen from [2] CQU ROK_Staff Costing.V1_Steph (2024 FIFO build) - link severed 26/07/26; re-based x1.08 below
B8: Working Days/Month | C8: 21 | I8: frozen from [2] CQU ROK_Staff Costing.V1_Steph (2024 FIFO build) - link severed 26/07/26; re-based x1.08 below
B9: No-Work Days/Month | C9: 7 | I9: frozen from [2] CQU ROK_Staff Costing.V1_Steph (2024 FIFO build) - link severed 26/07/26; re-based x1.08 below
B10: Avrg Hours / Month | C10: 210 | I10: frozen from [2] CQU ROK_Staff Costing.V1_Steph (2024 FIFO build) - link severed 26/07/26; re-based x1.08 below
B12: STAFF
C13: Unit | D13: REQ | E13: Cost ex GST | F13: Total ex GST
B14: TRADESMAN_LEADING HAND | C14: HR | D14: 1 | E14: =E17/$C$10 -> 132.96343 | F14: =D14*E14 -> 132.96343 | I14: frozen from [2] CQU ROK_Staff Costing.V1_Steph (2024 FIFO build) - link severed 26/07/26; re-based x1.08 below
B15: ** for Roster Examples # 3 | C15: DAY | D15: 1 | E15: =E17/$C$8 -> 1329.6343 | F15: =D15*E15 -> 1329.6343
B16: =B14 -> TRADESMAN_LEADING HAND | C16: WEEK | D16: 1 | E16: =E17/4 -> 6980.58 | F16: =D16*E16 -> 6980.58
C17: MONTH | D17: 1 | E17: 27922.32 | F17: =D17*E17 -> 27922.32 | I17: LH monthly: $25,854 (frozen [2]) x 1.08 ROK uplift = $27,922.32 literal; hr/day/week formula-derived (/210, /21, /4) -> $132.9634/hr
B19: QTY Staff in Crew | C19: =COUNTA(B16,B17,B18) -> 1
B21: TRADESMAN_PLUMBER_OPERATOR | C21: HR | D21: 1 | E21: =E24/$C$10 -> 101.64579 | F21: =D21*E21 -> 101.64579 | I21: frozen from [2] CQU ROK_Staff Costing.V1_Steph (2024 FIFO build) - link severed 26/07/26; re-based x1.08 below
B22: ** for Roster Examples # 3 | C22: DAY | D22: 1 | E22: =E24/$C$8 -> 1016.4579 | F22: =D22*E22 -> 1016.4579
B23: =B21 -> TRADESMAN_PLUMBER_OPERATOR | C23: WEEK | D23: 1 | E23: =E24/4 -> 5336.404 | F23: =D23*E23 -> 5336.404
C24: MONTH | D24: 1 | E24: 21345.616 | F24: =D24*E24 -> 21345.616 | I24: Trades monthly: $19,764.4593 (frozen [2]) x 1.08 = $21,345.6160 literal -> $101.6458/hr
B26: QTY Staff in Crew | C26: =COUNTA(B23,B24,B25) -> 1
B28: T/A & Apprentice | C28: HR | D28: 1 | E28: =E31/$C$10 -> 82.951029 | F28: =D28*E28 -> 82.951029 | I28: frozen from [2] CQU ROK_Staff Costing.V1_Steph (2024 FIFO build) - link severed 26/07/26; re-based x1.08 below
B29: ** for Roster Examples # 3 | C29: DAY | D29: 1 | E29: =E31/$C$8 -> 829.51029 | F29: =D29*E29 -> 829.51029
B30: =B28 -> T/A & Apprentice | C30: WEEK | D30: 1 | E30: =E31/4 -> 4354.929 | F30: =D30*E30 -> 4354.929
C31: MONTH | D31: 1 | E31: 17419.716 | F31: =D31*E31 -> 17419.716 | I31: T/A monthly: $16,129.3667 (frozen [2]) x 1.08 = $17,419.7160 literal -> $82.9510/hr
B33: QTY Staff in Crew | C33: =COUNTA(B30,B31,B32) -> 1
B36: Crew #1 - InGround Drainage | C36: HR | D36: 1 | E36: =E39/$C$10 -> 286.24261 | F36: =D36*E36 -> 286.24261
B37: ** for Roster Examples # 3 | C37: DAY | D37: 1 | E37: =E39/$C$8 -> 2862.4261 | F37: =D37*E37 -> 2862.4261
B38: =B21 -> TRADESMAN_PLUMBER_OPERATOR | C38: WEEK | D38: 1 | E38: =E39/4 -> 15027.737 | F38: =D38*E38 -> 15027.737
B39: =B21 -> TRADESMAN_PLUMBER_OPERATOR | C39: MONTH | D39: 1 | E39: =(E24*2)+E31 -> 60110.948 | F39: =D39*E39 -> 60110.948
B40: =B28 -> T/A & Apprentice
B41: QTY Staff in Crew | C41: =COUNTA(B38,B39,B40) -> 3
B43: Crew #2 - InGround Water/Fire | C43: HR | D43: 1 | E43: =E46/$C$10 -> 286.24261 | F43: =D43*E43 -> 286.24261
B44: ** for Roster Examples # 3 | C44: DAY | D44: 1 | E44: =E46/$C$8 -> 2862.4261 | F44: =D44*E44 -> 2862.4261
B45: =B21 -> TRADESMAN_PLUMBER_OPERATOR | C45: WEEK | D45: 1 | E45: =E46/4 -> 15027.737 | F45: =D45*E45 -> 15027.737
B46: =B21 -> TRADESMAN_PLUMBER_OPERATOR | C46: MONTH | D46: 1 | E46: =(E24*2)+E31 -> 60110.948 | F46: =D46*E46 -> 60110.948
B47: =B28 -> T/A & Apprentice
B48: QTY Staff in Crew | C48: =COUNTA(B45,B46,B47) -> 3
B51: Crew #3 - Above Ground Drainage | C51: HR | D51: 1 | E51: =E43 -> 286.24261 | F51: =D51*E51 -> 286.24261
B52: =B44 -> ** for Roster Examples # 3 | C52: DAY | D52: 1 | E52: =E44 -> 2862.4261 | F52: =D52*E52 -> 2862.4261
...

Sheet Material Rates_Master
A3: FIRE SERVICES - IN GROUND
A4: Description | B4: Unit | D4: Rate | F4: Total | I4: Qty | N4: Source
A5: 200 HDPE PN16 SDR11 - REDLINE | B5: m | D5: 33.920833 | F5: =I5*D5 -> 16282 | G5: COMPLETED don’t edit | I5: 480 | N5: frozen from [3] 240614 Pipe & Fittings Price Comparison (Jun-2024 cache) - link severed 26/07/26; >=2yr old at 2027 start - Phase 5 re-source pending
A6: 180 HDPE PN16 SDR11 - REDLINE | B6: m | D6: 25.466667 | F6: =I6*D6 -> 128657.6 | I6: 5052 | N6: frozen from [3] 240614 Pipe & Fittings Price Comparison (Jun-2024 cache) - link severed 26/07/26; >=2yr old at 2027 start - Phase 5 re-source pending
A7: 125 HDPE PN16 SDR11 - REDLINE | B7: m | D7: 12.314167 | F7: =I7*D7 -> 13151.53 | I7: 1068 | N7: frozen from [3] 240614 Pipe & Fittings Price Comparison (Jun-2024 cache) - link severed 26/07/26; >=2yr old at 2027 start - Phase 5 re-source pending
A8: 32 HDPE PN16 SDR11 - BLUELINE | B8: m | D8: 1.2159 | F8: =I8*D8 -> 121.59 | I8: 100 | N8: frozen from [3] 240614 Pipe & Fittings Price Comparison (Jun-2024 cache) - link severed 26/07/26; >=2yr old at 2027 start - Phase 5 re-source pending
A10: 200 EF Coupler | B10: ea | D10: 44.06 | F10: =I10*D10 -> 1321.8 | G10: COMPLETED don’t edit | I10: 30 | N10: frozen from [3] 240614 Pipe & Fittings Price Comparison (Jun-2024 cache) - link severed 26/07/26; >=2yr old at 2027 start - Phase 5 re-source pending
A11: 180 EF Coupler | B11: ea | D11: 25.72 | F11: =I11*D11 -> 5144 | I11: 200 | N11: frozen from [3] 240614 Pipe & Fittings Price Comparison (Jun-2024 cache) - link severed 26/07/26; >=2yr old at 2027 start - Phase 5 re-source pending
A12: 125 EF Coupler | B12: ea | D12: 14.11 | F12: =I12*D12 -> 1411 | I12: 100 | N12: frozen from [3] 240614 Pipe & Fittings Price Comparison (Jun-2024 cache) - link severed 26/07/26; >=2yr old at 2027 start - Phase 5 re-source pending
A13: 200 EF 45DFeg Bend | B13: ea | D13: 109.16 | F13: =I13*D13 -> 218.32 | I13: 2 | N13: frozen from [3] 240614 Pipe & Fittings Price Comparison (Jun-2024 cache) - link severed 26/07/26; >=2yr old at 2027 start - Phase 5 re-source pending
A14: 180 EF 45DFeg Bend | B14: ea | D14: 97.97 | F14: =I14*D14 -> 12736.1 | I14: 130 | N14: frozen from [3] 240614 Pipe & Fittings Price Comparison (Jun-2024 cache) - link severed 26/07/26; >=2yr old at 2027 start - Phase 5 re-source pending
A15: 125 EF 45DFeg Bend | B15: ea | D15: 44.69 | F15: =I15*D15 -> 1117.25 | G15: COMPLETED don’t edit | I15: 25 | N15: frozen from [3] 240614 Pipe & Fittings Price Comparison (Jun-2024 cache) - link severed 26/07/26; >=2yr old at 2027 start - Phase 5 re-source pending
A16: 200 EF 90DFeg Bend | B16: ea | D16: 109.16 | F16: =I16*D16 -> 654.96 | I16: 6 | N16: frozen from [3] 240614 Pipe & Fittings Price Comparison (Jun-2024 cache) - link severed 26/07/26; >=2yr old at 2027 start - Phase 5 re-source pending
A17: 180 EF 90DFeg Bend | B17: ea | D17: 97.81 | F17: =I17*D17 -> 7824.8 | I17: 80 | N17: frozen from [3] 240614 Pipe & Fittings Price Comparison (Jun-2024 cache) - link severed 26/07/26; >=2yr old at 2027 start - Phase 5 re-source pending
A18: 125 EF 90DFeg Bend | B18: ea | D18: 44.65 | F18: =I18*D18 -> 3572 | I18: 80 | N18: frozen from [3] 240614 Pipe & Fittings Price Comparison (Jun-2024 cache) - link severed 26/07/26; >=2yr old at 2027 start - Phase 5 re-source pending
A19: 200 EF TEE | B19: ea | D19: 109.75 | F19: =I19*D19 -> 329.25 | I19: 3 | N19: frozen from [3] 240614 Pipe & Fittings Price Comparison (Jun-2024 cache) - link severed 26/07/26; >=2yr old at 2027 start - Phase 5 re-source pending
A20: 180 EF TEE | B20: ea | D20: 114.28 | F20: =I20*D20 -> 4571.2 | G20: COMPLETED don’t edit | I20: 40 | N20: frozen from [3] 240614 Pipe & Fittings Price Comparison (Jun-2024 cache) - link severed 26/07/26; >=2yr old at 2027 start - Phase 5 re-source pending
A21: 125 EF TEE | B21: ea | D21: 49.25 | F21: =I21*D21 -> 49.25 | I21: 1 | N21: frozen from [3] 240614 Pipe & Fittings Price Comparison (Jun-2024 cache) - link severed 26/07/26; >=2yr old at 2027 start - Phase 5 re-source pending
A22: 200*180 EF TEE | B22: ea | D22: 209.47 | F22: =I22*D22 -> 418.94 | I22: 2 | N22: frozen from [3] 240614 Pipe & Fittings Price Comparison (Jun-2024 cache) - link severed 26/07/26; >=2yr old at 2027 start - Phase 5 re-source pending
A23: 200*125 EF TEE | B23: ea | D23: 218.42 | F23: =I23*D23 -> 436.84 | I23: 2 | N23: frozen from [3] 240614 Pipe & Fittings Price Comparison (Jun-2024 cache) - link severed 26/07/26; >=2yr old at 2027 start - Phase 5 re-source pending
A24: 180*125 EF TEE | B24: ea | D24: 122.13 | F24: =I24*D24 -> 4885.2 | I24: 40 | N24: frozen from [3] 240614 Pipe & Fittings Price Comparison (Jun-2024 cache) - link severed 26/07/26; >=2yr old at 2027 start - Phase 5 re-source pending
A25: 200*180 EF Reducer | B25: ea | D25: 125.62 | F25: =I25*D25 -> 502.48 | G25: COMPLETED don’t edit | I25: 4 | N25: frozen from [3] 240614 Pipe & Fittings Price Comparison (Jun-2024 cache) - link severed 26/07/26; >=2yr old at 2027 start - Phase 5 re-source pending
A26: 180*125 EF Reducer | B26: ea | D26: 60.1 | F26: =I26*D26 -> 1202 | I26: 20 | N26: frozen from [3] 240614 Pipe & Fittings Price Comparison (Jun-2024 cache) - link severed 26/07/26; >=2yr old at 2027 start - Phase 5 re-source pending
A27: 200PE*8"(200m) - MaxiStub W/Backing Ring | B27: ea | D27: 342.35 | F27: =I27*D27 -> 3423.5 | I27: 10 | N27: frozen from [3] 240614 Pipe & Fittings Price Comparison (Jun-2024 cache) - link severed 26/07/26; >=2yr old at 2027 start - Phase 5 re-source pending
A28: 180PE*6"(150mm) - MaxiStub W/Backing Ring | B28: ea | D28: 129.77 | F28: =I28*D28 -> 7786.2 | I28: 60 | N28: frozen from [3] 240614 Pipe & Fittings Price Comparison (Jun-2024 cache) - link severed 26/07/26; >=2yr old at 2027 start - Phase 5 re-source pending
A29: 125PE*4" (100mm) - MaxiStub W/Backing Ring | B29: ea | D29: 92.67 | F29: =I29*D29 -> 1853.4 | I29: 20 | N29: frozen from [3] 240614 Pipe & Fittings Price Comparison (Jun-2024 cache) - link severed 26/07/26; >=2yr old at 2027 start - Phase 5 re-source pending
A30: 180mm PE x 150mm GALV ADAPTER - PLASSON Brand | B30: ea | D30: 313.19 | F30: =I30*D30 -> 3131.9 | G30: COMPLETED don’t edit | I30: 10 | N30: frozen from [3] 240614 Pipe & Fittings Price Comparison (Jun-2024 cache) - link severed 26/07/26; >=2yr old at 2027 start - Phase 5 re-source pending
A31: 125mm PE x 100mm GALV ADAPTER - PLASSON Brand | B31: ea | D31: 204.11 | F31: =I31*D31 -> 10205.5 | I31: 50 | N31: frozen from [3] 240614 Pipe & Fittings Price Comparison (Jun-2024 cache) - link severed 26/07/26; >=2yr old at 2027 start - Phase 5 re-source pending
A33: 180mm PE x 150mm GALV ADAPTER | B33: ea | D33: 315.71 | F33: =I33*D33 -> 3157.1 | I33: 10 | N33: frozen from [3] 240614 Pipe & Fittings Price Comparison (Jun-2024 cache) - link severed 26/07/26; >=2yr old at 2027 start - Phase 5 re-source pending
A34: 125mm PE x 100mm GALV ADAPTER | B34: ea | D34: 201.43 | F34: =I34*D34 -> 10071.5 | I34: 50 | N34: frozen from [3] 240614 Pipe & Fittings Price Comparison (Jun-2024 cache) - link severed 26/07/26; >=2yr old at 2027 start - Phase 5 re-source pending
A35: 200 Long SPIG 45DFeg Bend | B35: ea | D35: 68.54 | F35: =I35*D35 -> 137.08 | G35: COMPLETED don’t edit | I35: 2 | N35: frozen from [3] 240614 Pipe & Fittings Price Comparison (Jun-2024 cache) - link severed 26/07/26; >=2yr old at 2027 start - Phase 5 re-source pending
A36: 180 Long SPIG 45DFeg Bend | B36: ea | D36: 64.46 | F36: =I36*D36 -> 8379.8 | I36: 130 | N36: frozen from [3] 240614 Pipe & Fittings Price Comparison (Jun-2024 cache) - link severed 26/07/26; >=2yr old at 2027 start - Phase 5 re-source pending
A37: 125 Long SPIG 45DFeg Bend | B37: ea | D37: 38.76 | F37: =I37*D37 -> 969 | I37: 25 | N37: frozen from [3] 240614 Pipe & Fittings Price Comparison (Jun-2024 cache) - link severed 26/07/26; >=2yr old at 2027 start - Phase 5 re-source pending
A38: 200 Long SPIG 90DFeg Bend | B38: ea | D38: 86.17 | F38: =I38*D38 -> 517.02 | I38: 6 | N38: frozen from [3] 240614 Pipe & Fittings Price Comparison (Jun-2024 cache) - link severed 26/07/26; >=2yr old at 2027 start - Phase 5 re-source pending
A39: 180 Long SPIG 90DFeg Bend | B39: ea | D39: 68.11 | F39: =I39*D39 -> 5448.8 | I39: 80 | N39: frozen from [3] 240614 Pipe & Fittings Price Comparison (Jun-2024 cache) - link severed 26/07/26; >=2yr old at 2027 start - Phase 5 re-source pending
A40: 125 Long SPIG 90DFeg Bend | B40: ea | D40: 31.65 | F40: =I40*D40 -> 2532 | G40: COMPLETED don’t edit | I40: 80 | N40: frozen from [3] 240614 Pipe & Fittings Price Comparison (Jun-2024 cache) - link severed 26/07/26; >=2yr old at 2027 start - Phase 5 re-source pending
A41: 200 Long SPIG TEE | B41: ea | D41: 127.64 | F41: =I41*D41 -> 382.92 | I41: 3 | N41: frozen from [3] 240614 Pipe & Fittings Price Comparison (Jun-2024 cache) - link severed 26/07/26; >=2yr old at 2027 start - Phase 5 re-source pending
A42: 180 Long SPIG TEE | B42: ea | D42: 114.22 | F42: =I42*D42 -> 4568.8 | I42: 40 | N42: frozen from [3] 240614 Pipe & Fittings Price Comparison (Jun-2024 cache) - link severed 26/07/26; >=2yr old at 2027 start - Phase 5 re-source pending
A43: 125 Long SPIG TEE | B43: ea | D43: 38.26 | F43: =I43*D43 -> 38.26 | I43: 1 | N43: frozen from [3] 240614 Pipe & Fittings Price Comparison (Jun-2024 cache) - link severed 26/07/26; >=2yr old at 2027 start - Phase 5 re-source pending
A44: 200*180 Long SPIG TEE | B44: ea | D44: 183.48 | F44: =I44*D44 -> 366.96 | I44: 2 | N44: frozen from [3] 240614 Pipe & Fittings Price Comparison (Jun-2024 cache) - link severed 26/07/26; >=2yr old at 2027 start - Phase 5 re-source pending
...

Sheet Equip&HIRE_Master
B2: TCS PROJECT USE | F2: COMPLETED don’t edit
A3: DESCRIPTION | B3: Unit | C3: Qty | D3: WEEKLY (5 day)
A4: Skid Steer Loader_Tracked (CAT249+) | B4: Day | D4: 225.43333 | G4: Source
A5: Skid Steer Loader_Wheeled (CAT226+) | B5: Day | D5: 163.96667 | G5: frozen from [4] 240614 Suppliers Subbies Price Comparison (Jun-2024 cache) - link severed 26/07/26; Phase 5 re-source pending
A6: Mini Loader, Stand-on Type | B6: Day | D6: 180 | G6: frozen from [4] 240614 Suppliers Subbies Price Comparison (Jun-2024 cache) - link severed 26/07/26; Phase 5 re-source pending
F7: COMPLETED don’t edit
A8: 1.5-1.8 Ton_Excavator | B8: Day | D8: 137.14286 | G8: frozen from [4] 240614 Suppliers Subbies Price Comparison (Jun-2024 cache) - link severed 26/07/26; Phase 5 re-source pending
A9: 1.7-2Ton_Excavator | B9: Day
A10: 3-5Ton_Excavator | B10: Day | D10: 238.66667 | G10: frozen from [4] 240614 Suppliers Subbies Price Comparison (Jun-2024 cache) - link severed 26/07/26; Phase 5 re-source pending
A11: 8Ton_Excavator | B11: Day | D11: 261.16667 | G11: frozen from [4] 240614 Suppliers Subbies Price Comparison (Jun-2024 cache) - link severed 26/07/26; Phase 5 re-source pending
A12: 10-12Ton_Excavator | B12: Day | F12: COMPLETED don’t edit
A13: 13-16Ton_Excavator | B13: Day | D13: 317.2 | G13: frozen from [4] 240614 Suppliers Subbies Price Comparison (Jun-2024 cache) - link severed 26/07/26; Phase 5 re-source pending
A14: 20-24Ton_Excavator | B14: Day | D14: 314.28571 | G14: frozen from [4] 240614 Suppliers Subbies Price Comparison (Jun-2024 cache) - link severed 26/07/26; Phase 5 re-source pending
A16: Ripper_1.7-2T | B16: Day
A17: Ripper_1.5-4T | B17: Day | D17: 32.74 | F17: COMPLETED don’t edit | G17: frozen from [4] 240614 Suppliers Subbies Price Comparison (Jun-2024 cache) - link severed 26/07/26; Phase 5 re-source pending
A18: Ripper_3-5T | B18: Day
A19: Ripper_8T | B19: Day | D19: 40.38 | G19: frozen from [4] 240614 Suppliers Subbies Price Comparison (Jun-2024 cache) - link severed 26/07/26; Phase 5 re-source pending
A20: Breaker_1.7-2T | B20: Day | D20: 123.33 | G20: frozen from [4] 240614 Suppliers Subbies Price Comparison (Jun-2024 cache) - link severed 26/07/26; Phase 5 re-source pending
A21: Breaker_3-5T | B21: Day | D21: 165.89 | G21: frozen from [4] 240614 Suppliers Subbies Price Comparison (Jun-2024 cache) - link severed 26/07/26; Phase 5 re-source pending
A22: Breaker_8T | B22: Day | D22: 165.89 | F22: COMPLETED don’t edit | G22: frozen from [4] 240614 Suppliers Subbies Price Comparison (Jun-2024 cache) - link severed 26/07/26; Phase 5 re-source pending
A23: Breaker_10-12T | B23: Day
A24: Breaker_13-15T | B24: Day | D24: 203 | G24: frozen from [4] 240614 Suppliers Subbies Price Comparison (Jun-2024 cache) - link severed 26/07/26; Phase 5 re-source pending
A25: Auger Drive_10-12T
A26: 300Dia Auger Drill
F27: COMPLETED don’t edit
A28: 1.25T_Tipper Truck | B28: Day | D28: 205 | G28: frozen from [4] 240614 Suppliers Subbies Price Comparison (Jun-2024 cache) - link severed 26/07/26; Phase 5 re-source pending
A29: 2-4T_Tipper Truck | B29: Day | D29: 166.98 | G29: frozen from [4] 240614 Suppliers Subbies Price Comparison (Jun-2024 cache) - link severed 26/07/26; Phase 5 re-source pending
A30: <6T_Tipper Truck | B30: Day | D30: 171.42857 | G30: frozen from [4] 240614 Suppliers Subbies Price Comparison (Jun-2024 cache) - link severed 26/07/26; Phase 5 re-source pending
A32: <10T_Articulated Site Tipper | B32: Day | F32: COMPLETED don’t edit
A33: Upright Rammer_Wacker | B33: Day | D33: 34.285714 | G33: frozen from [4] 240614 Suppliers Subbies Price Comparison (Jun-2024 cache) - link severed 26/07/26; Phase 5 re-source pending
A34: Trench Roller_Dbl Drum_Remote | B34: Day | D34: 165 | G34: frozen from [4] 240614 Suppliers Subbies Price Comparison (Jun-2024 cache) - link severed 26/07/26; Phase 5 re-source pending
A35: <26Ft_Scissor Lift - Diesel | B35: Day
A36: <26Ft_Scissor Lift - Elec | B36: Day
A37: <34Ft_Boom Lift - Diesel | B37: Day | F37: COMPLETED don’t edit
A38: <34Ft_Boom Lift - Elec | B38: Day
A40: Porta Loo_No Tank | B40: Day | D40: 5.46 | G40: frozen from [4] 240614 Suppliers Subbies Price Comparison (Jun-2024 cache) - link severed 26/07/26; Phase 5 re-source pending
A41: 6*3m Demantable Lunchroom - COMPLETE | B41: Day | D41: 23 | G41: frozen from [4] 240614 Suppliers Subbies Price Comparison (Jun-2024 cache) - link severed 26/07/26; Phase 5 re-source pending
A42: 6*3m Demantable Office - COMPLETE | B42: Day | D42: 23 | F42: COMPLETED don’t edit | G42: frozen from [4] 240614 Suppliers Subbies Price Comparison (Jun-2024 cache) - link severed 26/07/26; Phase 5 re-source pending
A43: 20Ft Shipping Container | B43: Day
A44: Quick Cut Demo Saw | B44: Day
...

Sheet Misc Subbie Rates_Master
A4: DENIS - Cells highlighted GREEN are complete (By Me). | H4: Source
A8: PLANT HIRE - WET | D8: TCS PROJECT USE | G8: COMPLETED don’t edit
A9: DESCRIPTION | B9: Unit | D9: Hr Rate | E9: Total
A10: 1.8T Excavator | B10: Hr | D10: 100 | H10: frozen from [4] 240614 Suppliers Subbies Price Comparison (Jun-2024 cache) - link severed 26/07/26; Phase 5 re-source pending
A11: 3-5 ton Excavator | B11: Hr | D11: 115 | H11: frozen from [4] 240614 Suppliers Subbies Price Comparison (Jun-2024 cache) - link severed 26/07/26; Phase 5 re-source pending
A12: 3-5T Combo | B12: Hr | D12: 154 | H12: frozen from [4] 240614 Suppliers Subbies Price Comparison (Jun-2024 cache) - link severed 26/07/26; Phase 5 re-source pending
A13: Hammer attachment 3.5-4T | B13: Hr | D13: 21 | G13: COMPLETED don’t edit | H13: frozen from [4] 240614 Suppliers Subbies Price Comparison (Jun-2024 cache) - link severed 26/07/26; Phase 5 re-source pending
A14: Ripper 3.5-4T | B14: Hr | D14: 10 | H14: frozen from [4] 240614 Suppliers Subbies Price Comparison (Jun-2024 cache) - link severed 26/07/26; Phase 5 re-source pending
A15: 5t Excavator | B15: Hr | D15: 150 | H15: frozen from [4] 240614 Suppliers Subbies Price Comparison (Jun-2024 cache) - link severed 26/07/26; Phase 5 re-source pending
A16: Hammer attachment 5T | B16: Hr | D16: 50 | H16: frozen from [4] 240614 Suppliers Subbies Price Comparison (Jun-2024 cache) - link severed 26/07/26; Phase 5 re-source pending
A17: Skid steer | B17: Hr | D17: 140 | H17: frozen from [4] 240614 Suppliers Subbies Price Comparison (Jun-2024 cache) - link severed 26/07/26; Phase 5 re-source pending
A18: 8T Excavator | B18: Hr | D18: 128 | G18: COMPLETED don’t edit | H18: frozen from [4] 240614 Suppliers Subbies Price Comparison (Jun-2024 cache) - link severed 26/07/26; Phase 5 re-source pending
A19: Hammer attachment 8T | B19: Hr | D19: 26 | H19: frozen from [4] 240614 Suppliers Subbies Price Comparison (Jun-2024 cache) - link severed 26/07/26; Phase 5 re-source pending
A20: Ripper 8T | B20: Hr | D20: 10 | H20: frozen from [4] 240614 Suppliers Subbies Price Comparison (Jun-2024 cache) - link severed 26/07/26; Phase 5 re-source pending
A21: 13-15T Excavator | B21: Hr | D21: 153 | H21: frozen from [4] 240614 Suppliers Subbies Price Comparison (Jun-2024 cache) - link severed 26/07/26; Phase 5 re-source pending
A22: Hammer attachment 14T | B22: Hr | D22: 36 | H22: frozen from [4] 240614 Suppliers Subbies Price Comparison (Jun-2024 cache) - link severed 26/07/26; Phase 5 re-source pending
A23: Ripper 14T | B23: Hr | D23: 10 | G23: COMPLETED don’t edit | H23: frozen from [4] 240614 Suppliers Subbies Price Comparison (Jun-2024 cache) - link severed 26/07/26; Phase 5 re-source pending
A24: 3000L Hydro Excavation Truck | B24: Hr | D24: 190 | H24: frozen from [4] 240614 Suppliers Subbies Price Comparison (Jun-2024 cache) - link severed 26/07/26; Phase 5 re-source pending
A25: 4500L Hydro Excavation Truck | B25: Hr | D25: 220 | H25: frozen from [4] 240614 Suppliers Subbies Price Comparison (Jun-2024 cache) - link severed 26/07/26; Phase 5 re-source pending
A26: 6300L Hydro Excavation Truck | B26: Hr | D26: 250 | H26: frozen from [4] 240614 Suppliers Subbies Price Comparison (Jun-2024 cache) - link severed 26/07/26; Phase 5 re-source pending
A27: Water Truck allow for water at cost | B27: Hr | D27: 110 | H27: frozen from [4] 240614 Suppliers Subbies Price Comparison (Jun-2024 cache) - link severed 26/07/26; Phase 5 re-source pending
A28: 12t Body Truck Tipper | B28: Hr | D28: 110 | G28: COMPLETED don’t edit | H28: frozen from [4] 240614 Suppliers Subbies Price Comparison (Jun-2024 cache) - link severed 26/07/26; Phase 5 re-source pending
A33: SURVEYOR | D33: TCS PROJECT USE | G33: COMPLETED don’t edit
A34: DESCRIPTION | B34: QTY | D34: Hr Rate? | E34: Total
A35: Site Field Surveyor for all works preformed | B35: 0 | D35: 180 | E35: =B35*D35 -> 0 | H35: frozen from [4] 240614 Suppliers Subbies Price Comparison (Jun-2024 cache) - link severed 26/07/26; Phase 5 re-source pending
B36: 0 | D36: 0 | E36: =B36*D36 -> 0
B37: 0 | D37: 0 | E37: =B37*D37 -> 0
A40: SERVICES LOCATOR | D40: TCS PROJECT USE | G40: COMPLETED don’t edit
A41: DESCRIPTION | B41: QTY | D41: Hr Rate? | E41: Total
A42: Standard Rate (includes wand, GPR) | B42: 0 | D42: 130 | E42: =B42*D42 -> 0 | H42: frozen from [4] 240614 Suppliers Subbies Price Comparison (Jun-2024 cache) - link severed 26/07/26; Phase 5 re-source pending
B43: 0 | D43: 0 | E43: =B43*D43 -> 0
B44: 0 | D44: 0 | E44: =B44*D44 -> 0
A47: CONCRETE CUTTER | D47: TCS PROJECT USE | G47: COMPLETED don’t edit
A48: DESCRIPTION | B48: QTY | D48: Lm Rate | E48: Total
A49: Asphalt Cutting | B49: 0 | D49: 13.5 | E49: =B49*D49 -> 0 | H49: frozen from [4] 240614 Suppliers Subbies Price Comparison (Jun-2024 cache) - link severed 26/07/26; Phase 5 re-source pending
A50: Concrete Cutting | B50: 0 | D50: 16 | E50: =B50*D50 -> 0 | H50: frozen from [4] 240614 Suppliers Subbies Price Comparison (Jun-2024 cache) - link severed 26/07/26; Phase 5 re-source pending
A51: Site Establishment Fee (2 per stage) | B51: 0 | D51: 80 | E51: =B51*D51 -> 0 | H51: frozen from [4] 240614 Suppliers Subbies Price Comparison (Jun-2024 cache) - link severed 26/07/26; Phase 5 re-source pending
A54: CONCRETING SERVICES | D54: TCS PROJECT USE | G54: COMPLETED don’t edit
A55: DESCRIPTION | B55: QTY | D55: Rate | E55: Total
A56: Road/Drveway Reinstate; 1mW x 150 Thck, N25/20/80, Incl Reinforcement | B56: 0 | D56: 145 | E56: =B56*D56 -> 0 | H56: frozen from [4] 240614 Suppliers Subbies Price Comparison (Jun-2024 cache) - link severed 26/07/26; Phase 5 re-source pending
...

Sheet Accomodation_Master
B3: INCLUDING GST (UNLESS NOTED OTHERWISE)
B5: TCS Accomodation Rates & Costs
B6: Hotel / Motel | C6: Sngl Night | D6: Week | E6: Month | F6: Qtr
B7: 1 x Unit, 1 x Room | C7: Motel Unit | D7: Private Unit
A8: Hidden | B8: No. of persons stayng; | C8: 1
B9: Furnished | C9: YES
B10: *Serviced | C10: YES
B11: Individual/Private BATHROOM | C11: YES
B12: Individual/Private KITCHEN (Cooking) Faciliities Available - Microwave min. | C12: YES
B13: Individual/Private LAUNDRY Facilities Available | C13: YES
B14: Individual/Private LOUNGE ROOM Facilities Available | C14: YES
C16: Sngl Night | D16: Week | E16: Month | F16: Qtr
B17: Total Booking Cost | C17: =D17/7 -> 112.85714 | D17: 790 | E17: =D17*4 -> 3160 | F17: =E17*3 -> 9480
B19: TCS Housing Consumables; ….. | C19: =D19/7 -> 0 | D19: 0 | E19: =D19*4 -> 0 | F19: =E19*3 -> 0
B20: TCS Laundry Allowance..? | C20: =D20/7 -> 0 | D20: 0 | E20: =D20*4 -> 0 | F20: =E20*3 -> 0
B21: TCS Additional Meals Allowance (If no cooking Facilities?) | C21: =D21/7 -> 0 | D21: 0 | E21: =D21*4 -> 0 | F21: =E21*3 -> 0
B22: TCS Furnishings? | C22: =D22/7 -> 0 | D22: 0 | E22: =D22*4 -> 0 | F22: =E22*3 -> 0
B23: TCS Cleaning/Servincing Allowance? | C23: =D23/7 -> 0 | D23: 0 | E23: =D23*4 -> 0 | F23: =E23*3 -> 0
B25: Total TCS Cost | C25: =SUM(C17:C24) -> 112.85714 | D25: =SUM(D17:D24) -> 790 | E25: =SUM(E17:E24) -> 3160 | F25: =SUM(F17:F24) -> 9480
B26: Total Cost Per Person | C26: =D26/7 -> 112.85714 | D26: =D17/C8 -> 790 | E26: =D26*4 -> 3160 | F26: =E26*3 -> 9480
B28: 1 x Unit, 1 x Room | C28: Motel Unit | D28: Share Rooms
A29: Hidden | B29: No. of persons stayng; | C29: 2
B31: Furnished | C31: YES
B32: *Serviced | C32: YES
B33: Individual/Private BATHROOM | C33: NO | D33: Share with Unit
B34: Individual/Private KITCHEN (Cooking) Faciliities Available - Microwave min. | C34: NO | D34: Share with Unit
B35: Individual/Private LAUNDRY Facilities Available | C35: YES
B36: Individual/Private LOUNGE ROOM Facilities Available | C36: YES
C38: Sngl Night | D38: Week | E38: Month | F38: Qtr
B39: Total Booking Cost | C39: =D39/7 -> 101.42857 | D39: 710 | E39: =D39*4 -> 2840 | F39: =E39*3 -> 8520
B41: TCS Housing Consumables; ….. | C41: =D41/7 -> 0 | D41: 0 | E41: =D41*4 -> 0 | F41: =E41*3 -> 0
B42: TCS Laundry Allowance..? | C42: =D42/7 -> 0 | D42: 0 | E42: =D42*4 -> 0 | F42: =E42*3 -> 0
B43: TCS Additional Meals Allowance (If no cooking Facilities?) | C43: =D43/7 -> 0 | D43: 0 | E43: =D43*4 -> 0 | F43: =E43*3 -> 0
B44: TCS Furnishings? | C44: =D44/7 -> 0 | D44: 0 | E44: =D44*4 -> 0 | F44: =E44*3 -> 0
B45: TCS Cleaning/Servincing Allowance? | C45: =D45/7 -> 0 | D45: 0 | E45: =D45*4 -> 0 | F45: =E45*3 -> 0
B47: Total TCS Cost | C47: =SUM(C39:C46) -> 101.42857 | D47: =SUM(D39:D46) -> 710 | E47: =SUM(E39:E46) -> 2840 | F47: =SUM(F39:F46) -> 8520
B48: Total Cost Per Person | C48: =D48/7 -> 50.714286 | D48: =D39/C29 -> 355 | E48: =D48*4 -> 1420 | F48: =E48*3 -> 4260
B50: 1 x Unit, 1 x Room | C50: Motel Unit | D50: Share Rooms
A51: Hidden | B51: No. of persons stayng; | C51: 3
B53: Furnished | C53: YES
...

Sheet EBC_Alternates
B1: TPS - EBC REGISTER & ALTERNATES - TEN16699 (all ex GST)
B2: NOTHING on this sheet feeds the base roll-up on 'TCS $ Sched'. Every figure is either an EXCLUDED-BUT-COSTED add-price held ready for reinstatement, or a labelled ALTERNATE to a base-offer item. The markup factor is referenced live from 'TCS $ Sched' Q51 (41.5% = 5.5% prelims + 18% O/H + 18% profit, each applied to total cost per SS5.4).
B4: SECTION A - EXCLUDED-BUT-COSTED (EBC) add-prices - formula-ready for reinstatement
B6: EBC-1 Sewer rising main O100/DN110, pumpwell to discharge - 110 m (SCOPE_MATRIX 2.1-x2; NewItems #1; RFI CL C4 discharge undefined)
B7: PE100 DN110 PN16 pressure pipe - benchmark (Reece Q-459014437 PE100 125 @ $31.1083/m x (110/125)^2 weight ratio x 1.38 escalation) | C7: m | D7: 110 | E7: =31.1083*(110/125)^2*1.38 -> 33.244569 | F7: =E7*D7 -> 3656.9026
B8: EF couplers / fittings allowance (15% of pipe value) | C8: item | D8: 1 | E8: =F7*0.15 -> 548.53539 | F8: =E8*D8 -> 548.53539
B9: Labour - Crew 1 in-ground, 2 crew-days (Phase 7 T1-06) | C9: day | D9: 2 | E9: ='LabourProject Rates_Master'!E37 -> 2862.4261 | F9: =E9*D9 -> 5724.8522
B10: Plant - 5T excavator 2 d + butt welder 2 d @ $350/d allowance | C10: item | D10: 1 | E10: =2*'Equip&HIRE_Master'!D10+2*350 -> 1177.3333 | F10: =E10*D10 -> 1177.3333
B11: EBC-1 cost subtotal | F11: =SUM(F7:F10) -> 11107.624
B12: EBC-1 ADD-PRICE (cost x 1.415) | F12: =F11*(1+'TCS $ Sched'!Q51) -> 15717.287
B13: Wording control: the exclusion must be worded so the builder cannot deem the rising main included inside 2.1-b gravity sewer. Ownership is ambiguous once Council installs the station (interface L6) - the reinstatement price is HELD, not offered.
B15: EBC-2 Trade waste application (grease arrestor) - excluded per locked SS5.3 / cross-cutting X3; add-price held (CL A2)
B16: Trade waste application / consultant fee allowance | C16: item | D16: 1 | E16: 1500 | F16: =E16*D16 -> 1500
B17: Attendance + documentation - 0.5 crew-day | C17: day | D17: 0.5 | E17: ='LabourProject Rates_Master'!E37 -> 2862.4261 | F17: =E17*D17 -> 1431.213
B18: EBC-2 cost subtotal | F18: =SUM(F16:F17) -> 2931.213
B19: EBC-2 ADD-PRICE (cost x 1.415) | F19: =F18*(1+'TCS $ Sched'!Q51) -> 4147.6665
B20: H002 n.25 makes the trade waste application TPS's; VOL 21 never mentions trade waste despite the canteen. Excluded per locked decision + RFI. The arrestor HARDWARE is priced in the NBC base (1500 L Viking GIT; size conflict 1500/2000/550-5000 L per CL B6).
B22: EBC-3 Fire extinguisher SUPPLY - NBC x8 + PAM x1 (drawn with no trade allocation - CL B8; matrix 4.11-d / 3.11-d)
B23: FE 2.5 kg ABE + bracket + location sign | C23: ea | D23: 9 | E23: 120 | F23: =E23*D23 -> 1080
B24: Install / mount labour - 0.25 crew-day | C24: day | D24: 0.25 | E24: ='LabourProject Rates_Master'!E37 -> 2862.4261 | F24: =E24*D24 -> 715.60652
B25: EBC-3 cost subtotal | F25: =SUM(F23:F24) -> 1795.6065
B26: EBC-3 ADD-PRICE (cost x 1.415) | F26: =F25*(1+'TCS $ Sched'!Q51) -> 2540.7832
B27: VOL38 s14.1 says the plumber prices extinguishers; the drawing note says the builder generally provides them. Carried EBC + RFI so the position is stated either way. AS1851 12-month maintenance of the fire services IS priced in the NBC base (r309).
B29: EBC-4 Sewer pump station - EXCLUDED, NO PRICE CARRIED (Addendum 2, 10 Jul 2026: 'Sewage Pump Station will be getting installed by Council')
B30: Interface per ledger L6: TPS carries the gravity sewer to and terminating at the station's inlet DICL pipe piece ('LIMIT OF Q-MAX WORKS'). Station supply, installation, excavation and slab by Council/others; electrical supply, controls and commissioning cabling by the electrical trade; the rising main is EBC-1 above. TPS states this interface list verbatim in its submission so 'pump station excluded' cannot be read as excluding the connecting works.
B31: Add-price EVIDENCE held (not offered): APS Quote 14065 as-specified QMax Fortis 3200 O x 6700 deep = $468,000 supply + install + commissioning - the basis to quote from if an add-price is requested (no validity stated - flag). Cross-references for the same station: Tradelink 1066334 pack ~$416,000 (incl. $115,000 M&E install labour) and Reece Q-459014431 $523,170.73 S+I. Spread of $107k across the three offers.
B32: REMOVED FROM THE MODEL 26/07/26: the prior workbook carried an orphaned block W37 $468,000 -> W43 = 468,000 x 1.15 + $2,500 freight + $5,000 install = $545,700 'sell'. That block fed NO roll-up cell - it was never inside the old $273,056.54 sub-total, so its deletion moves no headline number. D6 FLAG: any prior quote circulated off the old N68 grand total never included the pump station.
B34: SECTION B - ALTERNATES (clearly labelled; EXCLUDED from the base roll-up)
B36: ALT-1 O200 buried main - COPPER Type B alternate. BASE OFFER = HDPE PE100 SDR11 DN250 (locked SS5.5: no buried copper alternate is OFFERED)
B37: Kembla copper Type B DN200 - Tradelink 6595064, $2,015 per 6 m length (Jul-26; escalation not embedded) | C37: m | D37: 134.63 | E37: =2015/6 -> 335.83333 | F37: =E37*D37 -> 45213.242
B38: Base HDPE line as carried in the model ('Siteworks ' F349) | F38: ='Siteworks '!F349 -> 23118.388
B39: Material delta if copper were adopted (alternate less base) | F39: =F37-F38 -> 22094.854
B40: Sell delta if adopted (delta x 1.18 site contingency x 1.415 markup) | F40: =F39*1.18*(1+'TCS $ Sched'!Q51) -> 36891.777
B41: The copper build-up is retained here as a cost record only. The base offer sits inside the spec's own equivalence table (VOL38 s10.1, Cromford PN16 250 = O200 ID) so it is a CONFORMING offer, not a departure. The copper tapping-cluster FITTINGS (tees, bends, full-faced stubs, gasket kits, sluice valves) remain in the base at adopted counts - only the 134.63 m pipe run changes material.
B43: ALT-2 Building water >DN22 - COPPER alternate. BASE = 316 SS press-fit per WS2 (priced both ways per locked SS5.5 / CL C9)
B44: NBC copper Type B 32 mm (CQU 1057751 curve basis) | C44: m | D44: 17.86 | E44: 32 | F44: =E44*D44 -> 571.52
B45: NBC copper Type B 25 mm | C45: m | D45: 112.72 | E45: =129/6 -> 21.5 | F45: =E45*D45 -> 2423.48
B46: PAM copper Type B 32 mm | C46: m | D46: 9.56 | E46: =119.88/6 -> 19.98 | F46: =E46*D46 -> 191.0088
B47: PAM copper Type B 25 mm | C47: m | D47: 26.9 | E47: 17.52 | F47: =E47*D47 -> 471.288
B48: Copper pipe alternate - total | F48: =SUM(F44:F47) -> 3657.2968
...

Sheet Sched3_Extract
A1: TPS (Hydraulic) - Paynters Schedule 3 price extract - TEN16699 - ALL EX GST
A2: Maps the TPS cost model to the exact Schedule 3 line structure (schedule3_transcript.md / 01_SCOPE_MATRIX). Physical lump-sum lines are carried inside the stage lump sums; PC Sums, provisional fees and schedule-of-rates lines are separately identified as the schedule requires. Every Schedule 3 line allocated to TPS appears exactly once.
A4: Stage | B4: Sch ref | C4: Schedule 3 line | D4: TPS treatment | E4: Amount ex GST | F4: Basis / qualification
