Workbook

Sheet Cover_Control
B2: ROK SPORTS PRECINCT — STAGE 1 | TCS COST MODEL V2
B4: Entity | C4: TriCore Civil Services Pty Ltd (TCS) — civil stormwater
B5: ABN | C5: 89 195 291 365
B6: Tender | C6: TEN16699 — Rockhampton Sports Precinct Stage 1A ('A Home for Netball') & Stage 1B ('Recreational Park and Public Amenities')
B7: Site | C7: 554-700 Yaamba Rd, Norman Gardens QLD
B8: Quote reference | C8: TCS #2372-V2
B9: Date | C9: 26-07-2026
B10: GST | C10: ALL SUMS EX-GST throughout this workbook
B11: Architecture | C11: CQU/Hyd pattern per COST_MODEL_REBUILD_DECISION.md: Cover_Control / TCS $ Sched / work-area sheets / 5 masters / Prelim_OH / EBC / Sched3_Extract
B13: KEY TOTALS (live)
B14: Stage 1A lump sum (excl PC) | D14: ='TCS $ Sched'!D24 -> 2761815
B15: Stage 1A WSUD PC sum | D15: ='TCS $ Sched'!D31 -> 111787.74
B16: Stage 1A total incl PC | D16: ='TCS $ Sched'!D32 -> 2873602.7
B17: Stage 1B lump sum | D17: ='TCS $ Sched'!D44 -> 113131.26
B18: TCS GRAND TOTAL ex GST | D18: ='TCS $ Sched'!D46 -> 2986734
B19: Old Civil workbook total (materials-only, superseded) | D19: 890849.95
B21: REVISION / CHANGE LOG
B22: V1 | C22: 16-07-2026 — MasterCostSheet_Civ.V1 — original TCS Quote #2372. Part A $890,849.95 ex GST = materials/subbies-only marked up: labour $0, plant $0, no accommodation, GT drains excluded (orphaned $164,860 column), Prelim_OH check empty, profit compounded on (cost+prelims+OH) = 45.73% effective vs 41.5% label, external link to unrelated Loganlea 2018-era file.
B23: V2 | C23: 26-07-2026 — FULL REBUILD on CQU/Hyd architecture (this workbook). Adopted quantities (Phase 4), re-sourced rates (Phase 5), FIFO labour x1.08 + crew-days/plant-days/accommodation (Phase 7), markup re-based to directed 41.5% each-on-cost (old effective 45.73% — both shown), GST removed, all external links severed (values frozen from dumps then re-sourced), GT reinstated, WSUD re-based to Reece PC line, kerb chutes carried both ways (D6-F1), basin/spillway $0 allocation-RFI flag. LH supervision priced as DIRECT LABOUR per TriCore methodology (correction recorded at change-log S9). See TCS_CHANGE_LOG.md + MIGRATION_RECONCILIATION.xlsx.
B25: ASSUMPTIONS & BASIS
B26: 1. | C26: Quantities: ADOPTED column of QUANTITY_RECONCILIATION.xlsx (TCS_Civil + NewItems) is the sole pricing basis; Denis's figures retained there — variances reasoned in MIGRATION_RECONCILIATION.xlsx.
B27: 2. | C27: Labour: FIFO Roster Example #3 (6-day week, 10-hr days, 21 work-days / 210 hrs per month); ROK monthly bases x1.08 -> LH $132.9634/hr, Trades $101.6458/hr, T/A $82.9510/hr; crews of 3 (2 Trades + 1 T/A) = $2,862.43/crew-day.
B28: 3. | C28: Crew-days and plant-days: PROGRAMME_LABOUR_PLANT.xlsx TCS_Activities/TCS_Programme (233 base cd = 222 1A + 11 1B; B-07 spillway 10 cd held at $0 pending allocation RFI; B-09 kerb chutes 9 cd EBC).
B29: 4. | C29: Leading Hand supervision (120 days) is DIRECT LABOUR in the Stage 1A/1B labour blocks (row A-14 each), allocated pro-rata to crew-days — per TriCore's existing methodology, which prices TRADESMAN_LEADING HAND as a Day line inside the work-area labour block (old Civ 'SW Zone Sumry' B13/C13/E13 feeding H11; the Hyd master follows the same pattern). It is NOT a preliminary. Establishment non-labour, temp services incl. temp water cartage, EDQ remob and ADAC/CCTV/as-cons are funded from the 5.5% prelims allowance; Prelim_OH builds those bottom-up and carries the variance cross-check (LH row retained there at $0 for traceability).
B30: 5. | C30: Markup: Prelims 5.5% + OH 18% + Profit 18% EACH ON TOTAL COST (= 41.5%); cost = escalated-contingent materials + labour + plant + subbies + accommodation. Corrects old compounding (45.73% effective).
B31: 6. | C31: Material contingency x1.18 on materials only (incl freight); never on labour/plant/PC/provisional; no quote on file embeds contingency (Register S3).
B32: 7. | C32: Escalation to 2027 commencement applied ONCE via factors x1.38 PE/PVC (incl PP Stormpro + Hauraton Recyfix PE-PP), x1.15 subbies, x1.20 delivery — only where KeyRates safe-to-multiply flag is Y; concrete/precast/quarry carry no directed factor (escalation risk inside x1.18 + re-quote condition). Per-rate decision recorded on Materials_Master.
B33: 8. | C33: Supplier selection: cheaper compliant rate per item — Humes (RCP, RCBC, BCC headwalls, twin 375), Reece (winged 375 headwall, PP Stormpro, Hauraton, 100 PVC), Tradelink (225/150 PVC, 600 pits), Jaybro (small headwalls + freight adder). RCP375 take-off discrepancy (Humes 299 vs Reece 262 lengths) noted — adopted 714.9 m governs.
B34: 9. | C34: PP lines priced as PP (StormPRO o.e.) per drawings — Atlan HDPE cheaper but day-of-issue validity and spec acceptance unconfirmed (Opens #5).
B35: 10. | C35: WSUD: supply+delivery PC Sum $97,206.73 + 15% (Reece Q-459014431; Ocean Protect direct re-quote required — MUSIC model); installation in base lump sum (locked 5.3).
B36: 11. | C36: Trench drains REINSTATED (Hauraton package $162,349 quote basis; old model's $164,860 orphan superseded) incl excavation & quarry; GT6 grate substitution verify (Gap #7); Reece $198/m Fibretec anomaly to confirm (delta $19,217).
B37: 12. | C37: Kerb chutes: base EXCLUDED per Denis 24-Jul; add-price 9 chutes + rock/mat on EBC — 'Director decision D6-F1', both positions carried.
... B45: 20. | C45: Validity cliff: every quote expires Aug-2026 vs 2027 start — escalation carried once as above; re-quote at award (Register S5).

Sheet TCS $ Sched
B1: TCS $ SCHED — SUMMARY
B2: TriCore Civil Services Pty Ltd — ABN 89 195 291 365
B3: TEN16699 ROK Sports Precinct Stage 1A & 1B — Civil Stormwater | 554-700 Yaamba Rd, Norman Gardens QLD
B4: TCS Quote #: 2372-V2 | Date: 26-07-2026 | Rev: V2 (rebuild on CQU/Hyd architecture)
B5: ALL SUMS EX-GST
B7: MARKUP BASIS (Directive 5.4): Prelims + OH + Profit EACH calculated ON TOTAL COST — NOT compounded.
B8: Prelims % | C8: 0.055 | H8: CHANGE LOG: old model compounded profit on (cost+prelims+OH) giving 45.73% effective while labelled 41.5%; this model applies the directed 41.5% (each % on cost). Movement recorded in TCS_CHANGE_LOG.md.
B9: Overheads % | C9: 0.18
B10: Profit % | C10: 0.18
B11: Total effective markup on cost | C11: =C8+C9+C10 -> 0.415
B14: STAGE 1A — 'A HOME FOR NETBALL' (Sch 3 items 2.3-a drainage component / 2.5 Drainage / 3.5 Grated trench drains)
B15: Materials (escalated + x1.18 contingency) | D15: =Stage1A_Drainage!$F$74 -> 880272.95
B16: Labour incl. LH supervision (crew-days x FIFO rates) | D16: =Stage1A_Drainage!$F$105 -> 758545.61
B17: Plant | D17: =Stage1A_Drainage!$F$123 -> 165146.73
B18: Subbies & services | D18: =Stage1A_Drainage!$F$131 -> 41975
B19: Accommodation & FIFO travel share | D19: =Stage1A_Drainage!$F$134 -> 105872.42
B20: STAGE 1A TOTAL COST | D20: =SUM(D15:D19) -> 1951812.7
B21: Prelims (5.5% on cost) | D21: =D20*$C$8 -> 107349.7
B22: Overheads (18% on cost) | D22: =D20*$C$9 -> 351326.29
B23: Profit (18% on cost) | D23: =D20*$C$10 -> 351326.29
B24: STAGE 1A LUMP SUM (EX-GST, excl PC sums) | D24: =D20+D21+D22+D23 -> 2761815
B26: STAGE 1A — PC SUMS (SEPARATED; not in lump sum above)
B27: WSUD StormFilter — 22x Tall (690) PSorb cartridges in DN3300 manhole — SUPPLY + DELIVERY | D27: 90064.63 | H27: Reece Q-459014431 line (only project-specific price; verify vs direct Ocean Protect quote — Register Gap #1 / Opens #10). Superseded Atlan $88,838 basis removed.
B28: Freight — StormFilter manhole | D28: 7142.1
B29: PC base (supply + delivery) | D29: =D27+D28 -> 97206.73
B30: PC markup % | C30: 0.15
B31: WSUD PC SUM TOTAL (supply + delivery + 15%) | D31: =D29*(1+C30) -> 111787.74 | H31: INSTALLATION (excavation, bedding, cranage, placement, connection, backfill — Phase 7 activity C-05) is priced in the BASE lump sum, not in this PC (locked 5.3).
B32: STAGE 1A TOTAL INCL PC SUMS (EX-GST) | D32: =D24+D31 -> 2873602.7
B34: STAGE 1B — 'RECREATIONAL PARK AND PUBLIC AMENITIES' (Sch 3 item 2.3 Drainage)
B35: Materials (escalated + x1.18 contingency) | D35: =Stage1B_Drainage!$F$16 -> 29185.193
B36: Labour incl. LH supervision | D36: =Stage1B_Drainage!$F$25 -> 39331.529
B37: Plant | D37: =Stage1B_Drainage!$F$31 -> 2942.12
B38: Subbies & services | D38: =Stage1B_Drainage!$F$37 -> 2999.2
B39: Accommodation & FIFO travel share | D39: =Stage1B_Drainage!$F$40 -> 5493.3803
B40: STAGE 1B TOTAL COST | D40: =SUM(D35:D39) -> 79951.422
B41: Prelims (5.5% on cost) | D41: =D40*$C$8 -> 4397.3282
B42: Overheads (18% on cost) | D42: =D40*$C$9 -> 14391.256
B43: Profit (18% on cost) | D43: =D40*$C$10 -> 14391.256
B44: STAGE 1B LUMP SUM (EX-GST; no PC sums in 1B) | D44: =D40+D41+D42+D43 -> 113131.26 | H44: Sch 1B 2.3-b 'Retention basin': no separate 1B basin is documented — carried unpriced with qualification + RFI (CL A4). The single detention basin outlet works are in 1A.
B46: TCS GRAND TOTAL — STAGE 1A + 1B INCL PC SUMS (EX-GST) | D46: =D32+D44 -> 2986734
...

Sheet Stage1A_Drainage
B1: STAGE 1A — CIVIL STORMWATER WORK AREA (TCS)
B2: Quantities = ADOPTED per QUANTITY_RECONCILIATION.xlsx TCS_Civil (pricing basis). Rates ref Materials_Master adopted (escalated) rates. ALL SUMS EX-GST.
A4: ID | B4: Description | C4: Qty | D4: Unit | E4: Rate | F4: Total | G4: Source / note
B5: A — MATERIALS (adopted qty x source-tagged escalated rate)
A6: P1 | B6: RCP 375 CL3+CL4 mainline incl C09 twin barrels (adopted 702.9 m CL3 + 12.0 m CL4) | C6: 714.9 | D6: m | E6: =Materials_Master!$H$11 -> 105 | F6: =C6*E6 -> 75064.5 | G6: Adopted 714.9 m governs (Humes 299-len vs Reece 262-len take-off discrepancy noted). CL4 12.0 m re-split per Opens #2.
A7: P2 | B7: 375 rubber rings (1 per 2.44 m length) | C7: =ROUNDUP(C6/2.44,0) -> 293 | D7: ea | E7: =Materials_Master!$H$12 -> 4.8 | F7: =C7*E7 -> 1406.4 | G7: Qty = lengths of P1.
A8: P3 | B8: RCP 600 CL3 (line 26 stub, 1:500 grade) | C8: 3.31 | D8: m | E8: =Materials_Master!$H$13 -> 183.56557 | F8: =C8*E8 -> 607.60205
A9: P4 | B9: 600 rubber rings (allowance) | C9: 2 | D9: ea | E9: =Materials_Master!$H$14 -> 24 | F9: =C9*E9 -> 48
A10: P5 | B10: 225 PP collector (lines 26-29) | C10: 137.67 | D10: m | E10: =Materials_Master!$H$15 -> 49.785977 | F10: =C10*E10 -> 6854.0354
A11: P6 | B11: 300 PP (tank line 25 — deepest pipework 1.57-1.67 m) | C11: 58.56 | D11: m | E11: =Materials_Master!$H$16 -> 82.8 | F11: =C11*E11 -> 4848.768
A12: P7 | B12: 375 PP collectors (17 m court bays) | C12: 210.43 | D12: m | E12: =Materials_Master!$H$17 -> 126.97396 | F12: =C12*E12 -> 26719.131
A13: P8 | B13: 450 PP (line 26) | C13: 41.47 | D13: m | E13: =Materials_Master!$H$18 -> 186.3 | F13: =C13*E13 -> 7725.861
A14: P9 | B14: 600 PP (line 26) | C14: 38.47 | D14: m | E14: =Materials_Master!$H$19 -> 311.92718 | F14: =C14*E14 -> 11999.839
A15: P10 | B15: Jointing lubricant | C15: 10 | D15: ea | E15: =Materials_Master!$H$31 -> 17 | F15: =C15*E15 -> 170
A16: P11 | B16: 225 PVC DWV SN8 — building drainage collector line 81 (adopted printed chainage 115.45 m; Denis 180.93 m over-measure removed) | C16: 115.45 | D16: m | E16: =Materials_Master!$H$20 -> 178.595 | F16: =C16*E16 -> 20618.793 | G16: Rule 2 — printed design data governs (Opens #1).
A17: P12 | B17: 150 PVC DWV SN8 — trash box laterals lines 30-53/87 (1A share; 29.6 m to 1B) | C17: 33.25 | D17: m | E17: =Materials_Master!$H$21 -> 50.623 | F17: =C17*E17 -> 1683.2147
A18: P13 | B18: 100 PVC DWV — subsoil outlets / building DP laterals | C18: 283.71 | D18: m | E18: =Materials_Master!$H$22 -> 9.9061 | F18: =C18*E18 -> 2810.4596 | G18: Subsoil SYSTEM excluded by others; outlets/connections at TCS pits only (matrix 2.3-x2/2.5-x3).
A19: F1 | B19: 100 PVC 90 deg bends | C19: 17 | D19: ea | E19: =Materials_Master!$H$23 -> 4.83 | F19: =C19*E19 -> 82.11
A20: F2 | B20: 100 PVC 45 deg bends | C20: 9 | D20: ea | E20: =Materials_Master!$H$24 -> 4.83 | F20: =C20*E20 -> 43.47
A21: F3 | B21: 225 PVC 90 deg bend | C21: 1 | D21: ea | E21: =Materials_Master!$H$25 -> 32.43 | F21: =C21*E21 -> 32.43
A22: F4 | B22: 100 PVC 45 deg junctions | C22: 26 | D22: ea | E22: =Materials_Master!$H$26 -> 13.8 | F22: =C22*E22 -> 358.8
A23: F5 | B23: 225 PVC 45 deg junction | C23: 1 | D23: ea | E23: =Materials_Master!$H$27 -> 82.938 | F23: =C23*E23 -> 82.938
A24: F6 | B24: 225x100 PVC 45 deg junctions | C24: 11 | D24: ea | E24: =Materials_Master!$H$28 -> 53.199 | F24: =C24*E24 -> 585.189
A25: F7 | B25: Inspection openings c/w galv cover flush | C25: 3 | D25: ea | E25: =Materials_Master!$H$29 -> 207 | F25: =C25*E25 -> 621
A26: F8 | B26: Pipe-to-pipe / pipe-to-culvert connections (20 P2P per F1310) | C26: 20 | D26: ea | E26: =Materials_Master!$H$30 -> 310 | F26: =C26*E26 -> 6200
A27: C1 | B27: RCBC 600x300 crowns (C05-C08, 33.39 m @ 2.4 m/unit) | C27: =ROUNDUP(33.39/2.4,0) -> 14 | D27: ea | E27: =Materials_Master!$H$32 -> 1095 | F27: =C27*E27 -> 15330 | G27: Zero/negative cover at headwalls — extra-over excav/bedding at Q2 (NewItems #2).
A28: C2 | B28: RCBC 750x300 crowns (WSUD high-flow bypass, 5.17 m) | C28: =ROUNDUP(5.17/2.4,0) -> 3 | D28: ea | E28: =Materials_Master!$H$33 -> 1171.2 | F28: =C28*E28 -> 3513.6
A29: C3 | B29: RCBC 900x450 crowns (C01/C02, 27.86 m) | C29: =ROUNDUP(27.86/2.4,0) -> 12 | D29: ea | E29: =Materials_Master!$H$34 -> 1404.8 | F29: =C29*E29 -> 16857.6
A30: C4 | B30: RCBC 1200x600 crowns (C03, 17.77 m) | C30: =ROUNDUP(17.77/2.4,0) -> 8 | D30: ea | E30: =Materials_Master!$H$35 -> 1718.4 | F30: =C30*E30 -> 13747.2
A31: C5 | B31: LBC 1500x600 crowns (C04, 29.04 m) | C31: =ROUNDUP(29.04/2.4,0) -> 13 | D31: ea | E31: =Materials_Master!$H$36 -> 3065.72 | F31: =C31*E31 -> 39854.36
A32: C6 | B32: LBC 2700x1200 crowns (C10 basin outlet, 17.53 m — heavy lift) | C32: =ROUNDUP(17.53/2.4,0) -> 8 | D32: ea | E32: =Materials_Master!$H$37 -> 5891.95 | F32: =C32*E32 -> 47135.6
A33: H1 | B33: Headwalls to suit 375 RCP | C33: 5 | D33: ea | E33: =Materials_Master!$H$38 -> 317.05 | F33: =C33*E33 -> 1585.25
A34: H2 | B34: Headwalls to suit 2x375 RCP (C09A/B — details missing, RFI Opens #8) | C34: 2 | D34: ea | E34: =Materials_Master!$H$39 -> 588.8 | F34: =C34*E34 -> 1177.6
A35: H3 | B35: Headwall to suit 150 PVC (87-01) | C35: 1 | D35: ea | E35: =Materials_Master!$H$40 -> 158 | F35: =C35*E35 -> 158
A36: H4 | B36: Headwall to suit 225 PVC (81-01; adopted 1 vs Denis 2 per F1310) | C36: 1 | D36: ea | E36: =Materials_Master!$H$41 -> 280 | F36: =C36*E36 -> 280
A37: H5 | B37: Headwall to suit 300 PP (25-01) | C37: 1 | D37: ea | E37: =Materials_Master!$H$42 -> 352 | F37: =C37*E37 -> 352
A38: H6 | B38: BCC headwalls 600x300 (C05A/B-C08A/B) | C38: 8 | D38: ea | E38: =Materials_Master!$H$43 -> 1800.63 | F38: =C38*E38 -> 14405.04
A39: H7 | B39: BCC headwall 750x300 (26-01) | C39: 1 | D39: ea | E39: =Materials_Master!$H$44 -> 2162.6 | F39: =C39*E39 -> 2162.6
A40: H8 | B40: BCC headwalls 900x450 (C01A/B, C02A/B) | C40: 4 | D40: ea | E40: =Materials_Master!$H$45 -> 2425.63 | F40: =C40*E40 -> 9702.52
A41: H9 | B41: BCC headwalls 1200x600 (C03A/B) | C41: 2 | D41: ea | E41: =Materials_Master!$H$46 -> 3322.45 | F41: =C41*E41 -> 6644.9
...

Sheet Stage1B_Drainage
B1: STAGE 1B — CIVIL STORMWATER WORK AREA (TCS)
B2: Stage 1B per adopted stage-split basis (VOL 20 SE_12306_SKT_CMP Rev B hatch; RFI to confirm): GT5 + GT6 + lines 60/61/83. 1B priced standalone-viable per Directive 5.2. ALL SUMS EX-GST.
A4: ID | B4: Description | C4: Qty | D4: Unit | E4: Rate | F4: Total | G4: Source / note
B5: A — MATERIALS (adopted qty x source-tagged escalated rate)
A6: P1 | B6: 150 PVC DWV SN8 — lines 60/61/83 (district park / PAM) | C6: 29.6 | D6: m | E6: =Materials_Master!$H$21 -> 50.623 | F6: =C6*E6 -> 1498.4408
A7: G1 | B7: Grated trench GT5 Recyfix PRO100 SS heelguard — multi-use court (Sch 1B 4.2-a interface) | C7: 15.2 | D7: m | E7: =Materials_Master!$H$59 -> 508.1712 | F7: =C7*E7 -> 7724.2022 | G7: Stage split per VOL 20 hatch (RFI).
A8: G2 | B8: Grated trench GT6 Recyfix PRO200 G-tec D400 ductile — amenities bldg (Class D outlier) | C8: 31.4 | D8: m | E8: =Materials_Master!$H$60 -> 387.6282 | F8: =C8*E8 -> 12171.525 | G8: GT6 spec is PRO100 D400 code 47245; Reece offered PRO200 G-tec — substitution verify (Register Gap #7).
A9: G3 | B9: Hauraton trash boxes TB100 (60-01, 60-03, 61-01, 83-01) | C9: 4 | D9: ea | E9: =Materials_Master!$H$62 -> 295.4856 | F9: =C9*E9 -> 1181.9424
A10: G4 | B10: End caps PRO100 | C10: 4 | D10: ea | E10: =Materials_Master!$H$64 -> 12.9858 | F10: =C10*E10 -> 51.9432
A11: Q1 | B11: Bedding stone 5-7 mm (0.203 T/m) | C11: =ROUND(0.203*C6,1) -> 6 | D11: T | E11: =Materials_Master!$H$72 -> 62 | F11: =C11*E11 -> 372
A12: D1 | B12: Freight — Reece (GT5/GT6/TB100), est loads | C12: 1 | D12: load | E12: =Materials_Master!$H$66 -> 1133.16 | F12: =C12*E12 -> 1133.16
A13: D2 | B13: Freight — 1B misc deliveries | C13: 1 | D13: lot | E13: =Materials_Master!$H$71 -> 600 | F13: =C13*E13 -> 600
B14: Materials subtotal (escalated rates) | F14: =SUM(F6:F13) -> 24733.214
B15: x1.18 material contingency (Directive 5.4 — materials only) | F15: =F14*(Materials_Master!$D$8-1) -> 4451.9785
B16: A — MATERIALS TOTAL (escalated + contingent) | F16: =F14+F15 -> 29185.193
B18: B — LABOUR (crew-days from Phase 7)
A19: A-12 | B19: Stage 1B establishment / remobilisation (standalone per 5.2) | C19: 2 | D19: crew-day | E19: =LabourRates_Master!$G$15 -> 2862.4261 | F19: =C19*E19 -> 5724.8522
A20: A-13 | B20: 1B testing / CCTV attendance / ADAC share | C20: 2 | D20: crew-day | E20: =LabourRates_Master!$G$15 -> 2862.4261 | F20: =C20*E20 -> 5724.8522
A21: C-08 | B21: GT5 + GT6 trench drains 46.6 m | C21: 3 | D21: crew-day | E21: =LabourRates_Master!$G$15 -> 2862.4261 | F21: =C21*E21 -> 8587.2783
A22: C-09 | B22: 1B lines 60/61/83 + TB100 x4 + connections | C22: 4 | D22: crew-day | E22: =LabourRates_Master!$G$15 -> 2862.4261 | F22: =C22*E22 -> 11449.704
B23: B1 — Crew labour subtotal (crew-days / $) | C23: =SUM(C19:C22) -> 11 | F23: =SUM(F19:F22) -> 31486.687
A24: A-14 | B24: Leading Hand supervision — 1B share (DIRECT LABOUR per TriCore methodology: old Civ 'SW Zone Sumry' B13). 120 LH-days allocated pro-rata to crew-days. | C24: =ROUND(120*C23/(Stage1A_Drainage!$C$103+C23),1) -> 5.9 | D24: LH-day | E24: =LabourRates_Master!$G$11 -> 1329.6343 | F24: =C24*E24 -> 7844.8423
B25: B — LABOUR TOTAL (crew labour + LH supervision) | F25: =F23+F24 -> 39331.529
B27: C — PLANT
B28: 3-5T excavator | C28: 7 | D28: day | E28: =Equip_Master!$D$8 -> 238.67 | F28: =C28*E28 -> 1670.69
B29: <6T tipper truck | C29: 1 | D29: day | E29: =Equip_Master!$D$12 -> 171.43 | F29: =C29*E29 -> 171.43
B30: Water truck (test/flush cartage) | C30: 1 | D30: day | E30: =Equip_Master!$D$15 -> 1100 | F30: =C30*E30 -> 1100
B31: C — PLANT TOTAL | F31: =SUM(F28:F30) -> 2942.12
B33: D — SUBBIES & SERVICES (x1.15 via Materials_Master)
B34: Surveyor — 1B set-out / as-con | C34: 1 | D34: day | E34: =Materials_Master!$H$83 -> 2070 | F34: =C34*E34 -> 2070
B35: Compaction testing | C35: 4 | D35: test | E35: =Materials_Master!$H$85 -> 140.3 | F35: =C35*E35 -> 561.2
B36: Spoil haulage & dump | C36: =ROUND(0.21*C6+2,0) -> 8 | D36: m3 | E36: =Materials_Master!$H$87 -> 46 | F36: =C36*E36 -> 368
B37: D — SUBBIES TOTAL | F37: =SUM(F34:F36) -> 2999.2
B39: E — ACCOMMODATION & FIFO TRAVEL share (pro-rata CREW-days, excl. LH supervision days)
B40: Accommodation + flights share — Stage 1B | F40: =Accommodation!$E$27*C23/(Stage1A_Drainage!$C$103+C23) -> 5493.3803
B42: STAGE 1B — TOTAL COST (materials + labour + plant + subbies + accommodation) | F42: =F16+F25+F31+F37+F40 -> 79951.422

Sheet LabourRates_Master
B1: LABOUR RATES MASTER — FIFO ROSTER (TCS)
B2: Work ROSTER Example #3 - 6-Day Week, 10Hr Days, Stay @ Rocky for W/E, Return Every 2nd W/E. (FLY)
B3: Source: MasterCostSheet_Hyd.V1 'LabourProject Rates_Master' (monthly bases frozen from severed external link [2] CQU ROK_Staff Costing.V1_Steph.xlsx) x 1.08 ROK uplift per Directive 5.4. All ex GST.
B5: Working Days / Month | C5: 21
B6: Avrg Hours / Day | C6: 10
B7: Avrg Hours / Month | C7: =C5*C6 -> 210
B8: ROK uplift factor (Directive 5.4) | C8: 1.08
B10: Classification | C10: Unit basis | D10: Monthly base ($) | E10: Uplifted monthly ($) | F10: Hourly ($/hr) | G10: Day ($/10-hr day) | H10: Week ($/wk) | I10: Source / check
B11: TRADESMAN_LEADING HAND | C11: per month | D11: 25854 | E11: =D11*$C$8 -> 27922.32 | F11: =E11/$C$7 -> 132.96343 | G11: =E11/$C$5 -> 1329.6343 | H11: =E11/4 -> 6980.58 | I11: Hyd master E17 (was $123.1143/hr) -> x1.08 target $132.9634/hr
B12: TRADESMAN_PLUMBER_OPERATOR (Trades) | C12: per month | D12: 19764.459 | E12: =D12*$C$8 -> 21345.616 | F12: =E12/$C$7 -> 101.64579 | G12: =E12/$C$5 -> 1016.4579 | H12: =E12/4 -> 5336.404 | I12: Hyd master E24 (was $94.1165/hr) -> x1.08 target $101.6458/hr
B13: T/A & APPRENTICE | C13: per month | D13: 16129.367 | E13: =D13*$C$8 -> 17419.716 | F13: =E13/$C$7 -> 82.951029 | G13: =E13/$C$5 -> 829.51029 | H13: =E13/4 -> 4354.929 | I13: Hyd master E31 (was $76.8065/hr) -> x1.08 target $82.9510/hr
B15: CIVIL CREW (2 x Trades + 1 x T/A) — Phase 7 crew convention | C15: per 10-hr day | F15: =2*F12+F13 -> 286.24261 | G15: =2*G12+G13 -> 2862.4261 | H15: =2*H12+H13 -> 15027.737 | I15: Crew day rate check vs Phase 7 indicative $2,862.43/crew-day
B17: Uplifted hourly rates carried: LH $132.9634 / Trades $101.6458 / T/A $82.9510 (Directive 5.4). Cascade is fully formula-driven: month -> x1.08 -> hour(/210) / day(/21) / week(/4).

Sheet Materials_Master
B1: MATERIALS MASTER — TCS (adopted rates, ex GST)
B2: Every rate carries its source and a per-rate escalation decision. Escalation factors are the CQU-architecture 'april 2026 direct impact Increase % (not contingency)' set, applied ONLY where MATERIAL_QUOTE_REGISTER KeyRates safe-to-multiply flag confirms the rate is not already loaded. All quotes on file are current-price offers with no embedded escalation (Register S3).
B4: Escalation factors (Directive / CQU block J14:M19):
B5: PE / PVC pipe & fittings | D5: 1.38
B6: Subby rates | D6: 1.15
B7: Delivery / freight | D7: 1.2
B8: Material contingency (Directive 5.4 — materials only, applied on work-area subtotals; never on labour/plant/PC/provisional) | D8: 1.18
A10: Code | B10: Item | C10: Unit | D10: Base rate | E10: Source | F10: Factor | H10: Adopted rate | I10: Escalation decision / note
A11: M01 | B11: RCP 375 CL3/CL4 RRJ (priced at Humes Class 4 rate; no CL3 quote on file — conservative) | C11: m | D11: =256.2/2.44 -> 105 | E11: Humes Q21642316 REV2 ($256.20/2.44 m eff.) | F11: 1 | H11: =D11*F11 -> 105 | I11: Concrete/precast: no directed category factor (not PE/PVC/subbie/delivery); 2027 escalation risk carried inside x1.18 material contingency + re-quote condition at award. Humes 299 vs Reece 262 take-off discrepancy noted — our adopted 714.9 m governs.
A12: M02 | B12: 375 rubber ring | C12: ea | D12: 4.8 | E12: Humes Q21642316 REV2 | F12: 1 | H12: =D12*F12 -> 4.8 | I12: Concrete/precast: no directed category factor (not PE/PVC/subbie/delivery); 2027 escalation risk carried inside x1.18 material contingency + re-quote condition at award.
A13: M03 | B13: RCP 600 CL3 RRJ | C13: m | D13: =447.9/2.44 -> 183.56557 | E13: Humes Q21642316 REV2 ($447.90/2.44 m) | F13: 1 | H13: =D13*F13 -> 183.56557 | I13: Concrete/precast: no directed category factor (not PE/PVC/subbie/delivery); 2027 escalation risk carried inside x1.18 material contingency + re-quote condition at award.
A14: M04 | B14: 600 rubber ring (allowance) | C14: ea | D14: 24 | E14: Old Civ workbook rate (benchmark) | F14: 1 | H14: =D14*F14 -> 24 | I14: Benchmark-derived; minor value.
A15: M05 | B15: 225 PP Stormpro SN8 (or equal) | C15: m | D15: =216.1/5.99 -> 36.076795 | E15: Reece Q-459014445 ($216.10/5.99 m) | F15: =$D$5 -> 1.38 | H15: =D15*F15 -> 49.785977 | I15: PP priced (drawings label PP; 'HDPE PN100' not a real class — Opens #5). Atlan HDPE cheaper but day-of-issue validity + spec acceptance unconfirmed — NOT adopted. KeyRates safe-flag Y -> x1.38 PE family.
A16: M06 | B16: 300 PP Stormpro SN8 | C16: m | D16: 60 | E16: DERIVED — interpolated Reece Stormpro curve (225=$36.08/m, 375=$92.01/m) | F16: =$D$5 -> 1.38 | H16: =D16*F16 -> 82.8 | I16: Benchmark-derived (no 300 rate quoted); re-quote at award. x1.38 PE family.
A17: M07 | B17: 375 PP Stormpro SN8 | C17: m | D17: =545.62/5.93 -> 92.010118 | E17: Reece Q-459014445 ($545.62/5.93 m) | F17: =$D$5 -> 1.38 | H17: =D17*F17 -> 126.97396 | I17: KeyRates safe-flag Y -> x1.38 PE family.
A18: M08 | B18: 450 PP Stormpro SN8 | C18: m | D18: 135 | E18: DERIVED — interpolated Reece Stormpro curve (375=$92.01/m, 600=$226.03/m) | F18: =$D$5 -> 1.38 | H18: =D18*F18 -> 186.3 | I18: Benchmark-derived (no 450 rate quoted); re-quote at award. x1.38 PE family.
A19: M09 | B19: 600 PP Stormpro SN8 | C19: m | D19: =1322.3/5.85 -> 226.03419 | E19: Reece Q-459014445 ($1,322.30/5.85 m) | F19: =$D$5 -> 1.38 | H19: =D19*F19 -> 311.92718 | I19: KeyRates safe-flag Y -> x1.38 PE family.
A20: M10 | B20: 225 PVC DWV SN8 SWJ | C20: m | D20: =776.5/6 -> 129.41667 | E20: Tradelink 1065005 R1 ($776.50/6 m) | F20: =$D$5 -> 1.38 | H20: =D20*F20 -> 178.595 | I20: KeyRates safe-flag Y -> x1.38 PVC. Tradelink freight is a separate lot line (M56) — rate not freight-loaded.
A21: M11 | B21: 150 PVC DWV SN8 SWJ | C21: m | D21: =220.1/6 -> 36.683333 | E21: Tradelink 1065005 R1 ($220.10/6 m) | F21: =$D$5 -> 1.38 | H21: =D21*F21 -> 50.623 | I21: As M10.
A22: M12 | B22: 100 PVC DWV SN6 SWJ | C22: m | D22: =43.07/6 -> 7.1783333 | E22: Reece Q-459014445 ($43.07/6 m) | F22: =$D$5 -> 1.38 | H22: =D22*F22 -> 9.9061 | I22: KeyRates safe-flag Y -> x1.38 PVC.
A23: M13 | B23: 100 PVC 90 deg bend | C23: ea | D23: 3.5 | E23: Old Civ workbook rate (benchmark — no current quote) | F23: =$D$5 -> 1.38 | H23: =D23*F23 -> 4.83 | I23: Benchmark-derived; x1.38 PVC; re-quote at award.
A24: M14 | B24: 100 PVC 45 deg bend | C24: ea | D24: 3.5 | E24: Old Civ workbook rate (benchmark) | F24: =$D$5 -> 1.38 | H24: =D24*F24 -> 4.83 | I24: As M13.
A25: M15 | B25: 225 PVC 90 deg bend | C25: ea | D25: 23.5 | E25: Old Civ workbook rate (benchmark) | F25: =$D$5 -> 1.38 | H25: =D25*F25 -> 32.43 | I25: As M13.
A26: M16 | B26: 100 PVC 45 deg junction | C26: ea | D26: 10 | E26: Old Civ workbook rate (benchmark) | F26: =$D$5 -> 1.38 | H26: =D26*F26 -> 13.8 | I26: As M13.
A27: M17 | B27: 225 PVC 45 deg junction | C27: ea | D27: 60.1 | E27: Old Civ workbook rate (benchmark) | F27: =$D$5 -> 1.38 | H27: =D27*F27 -> 82.938 | I27: As M13.
A28: M18 | B28: 225x100 PVC 45 deg junction | C28: ea | D28: 38.55 | E28: Old Civ workbook rate (benchmark) | F28: =$D$5 -> 1.38 | H28: =D28*F28 -> 53.199 | I28: As M13.
A29: M19 | B29: Inspection opening c/w galvanised cover flush with surface | C29: ea | D29: 150 | E29: Old Civ workbook rate (benchmark) | F29: =$D$5 -> 1.38 | H29: =D29*F29 -> 207 | I29: PVC assembly — x1.38; re-quote at award.
A30: M20 | B30: Pipe-to-pipe / pipe-to-culvert connection materials (couplers, epoxy, mortar) | C30: ea | D30: 310 | E30: Old Civ workbook rates $150-600 (benchmark allowance) | F30: 1 | H30: =D30*F30 -> 310 | I30: Connection allowance, not a supplier rate — factor 1.00; escalation risk inside x1.18 contingency.
A31: M21 | B31: Jointing lubricant 1L | C31: ea | D31: 17 | E31: Old Civ workbook rate (benchmark) | F31: 1 | H31: =D31*F31 -> 17 | I31: Minor consumable.
A32: M22 | B32: RCBC 600x300 crown unit (2.4 m) | C32: ea | D32: 1095 | E32: Humes Q21642316 REV2 (vs Reece $1,136.36 — Humes adopted) | F32: 1 | H32: =D32*F32 -> 1095 | I32: Concrete/precast: no directed category factor (not PE/PVC/subbie/delivery); 2027 escalation risk carried inside x1.18 material contingency + re-quote condition at award.
A33: M23 | B33: RCBC 750x300 crown unit (2.4 m) | C33: ea | D33: 1171.2 | E33: Humes Q21642316 REV2 (vs Reece $1,330.91) | F33: 1 | H33: =D33*F33 -> 1171.2 | I33: Concrete/precast: no directed category factor (not PE/PVC/subbie/delivery); 2027 escalation risk carried inside x1.18 material contingency + re-quote condition at award.
A34: M24 | B34: RCBC 900x450 crown unit (2.4 m) | C34: ea | D34: 1404.8 | E34: Humes Q21642316 REV2 (vs Reece $1,599.77) | F34: 1 | H34: =D34*F34 -> 1404.8 | I34: Concrete/precast: no directed category factor (not PE/PVC/subbie/delivery); 2027 escalation risk carried inside x1.18 material contingency + re-quote condition at award.
A35: M25 | B35: RCBC 1200x600 crown unit (2.4 m) | C35: ea | D35: 1718.4 | E35: Humes Q21642316 REV2 | F35: 1 | H35: =D35*F35 -> 1718.4 | I35: Concrete/precast: no directed category factor (not PE/PVC/subbie/delivery); 2027 escalation risk carried inside x1.18 material contingency + re-quote condition at award.
A36: M26 | B36: Large box culvert 1500x600 (2.4 m) AS1597.2 | C36: ea | D36: 3065.72 | E36: Humes Q21642316 REV2 (vs Reece $3,483.77; Humes qty 13 vs Reece 8 — our 29.04 m governs) | F36: 1 | H36: =D36*F36 -> 3065.72 | I36: Concrete/precast: no directed category factor (not PE/PVC/subbie/delivery); 2027 escalation risk carried inside x1.18 material contingency + re-quote condition at award.
A37: M27 | B37: Large box culvert 2700x1200 (2.4 m) AS1597.2 | C37: ea | D37: 5891.95 | E37: Humes Q21642316 REV2 (vs Reece $6,797.67) | F37: 1 | H37: =D37*F37 -> 5891.95 | I37: Concrete/precast: no directed category factor (not PE/PVC/subbie/delivery); 2027 escalation risk carried inside x1.18 material contingency + re-quote condition at award.
A38: M28 | B38: Headwall to suit 375 RCP (winged) | C38: ea | D38: 317.05 | E38: Reece Q-459014445 (vs Humes $380.80 / Jaybro $372+freight — Reece adopted) | F38: 1 | H38: =D38*F38 -> 317.05 | I38: Concrete/precast: no directed category factor (not PE/PVC/subbie/delivery); 2027 escalation risk carried inside x1.18 material contingency + re-quote condition at award.
A39: M29 | B39: Headwall to suit 2x375 RCP twin cell | C39: ea | D39: 588.8 | E39: Humes Q21642316 REV2 (vs Jaybro $1,670 — Humes adopted) | F39: 1 | H39: =D39*F39 -> 588.8 | I39: Concrete/precast: no directed category factor (not PE/PVC/subbie/delivery); 2027 escalation risk carried inside x1.18 material contingency + re-quote condition at award.
A40: M30 | B40: Headwall to suit 150 PVC | C40: ea | D40: 158 | E40: Jaybro email 16/07/26 (freight excluded — carried at M57) | F40: 1 | H40: =D40*F40 -> 158 | I40: Concrete/precast: no directed category factor (not PE/PVC/subbie/delivery); 2027 escalation risk carried inside x1.18 material contingency + re-quote condition at award.
A41: M31 | B41: Headwall to suit 225 PVC | C41: ea | D41: 280 | E41: Jaybro email 16/07/26 (freight excluded — M57) | F41: 1 | H41: =D41*F41 -> 280 | I41: Concrete/precast: no directed category factor (not PE/PVC/subbie/delivery); 2027 escalation risk carried inside x1.18 material contingency + re-quote condition at award.
... A57: M47 | B57: 600x600 Class D grate & frame (HD) | C57: ea | D57: 365.2 | E57: Tradelink 1065005 R1 (re-sourced from old $195) | F57: 1 | H57: =D57*F57 -> 365.2 | I57: Concrete/precast: no directed category factor (not PE/PVC/subbie/delivery); 2027 escalation risk carried inside x1.18 material contingency + re-quote condition at award.
...

Sheet Equip_Master
B1: EQUIPMENT / HIRE MASTER — TCS
B2: Adopted plant day rates (dry hire unless noted). Source register header says WEEKLY (5-day) but unit column says Day — treated as $/day (conservative), flagged for confirmation (Phase 7 flag carried).
B4: Item | C4: Unit | D4: Rate ex GST | E4: Source | F4: In hire register? | G4: Note
B5: 13-16T excavator | C5: day | D5: 317.2 | E5: Hyd Equip&HIRE_Master | F5: Y | G5: Mainline / PP / DWV trenching
B6: 8T excavator | C6: day | D6: 261.17 | E6: Hyd Equip&HIRE_Master | F6: Y | G6: Crew B pits / structures
B7: 20-24T excavator | C7: day | D7: 314.29 | E7: Hyd Equip&HIRE_Master | F7: Y | G7: Culverts, WSUD, rock band
B8: 3-5T excavator | C8: day | D8: 238.67 | E8: Hyd Equip&HIRE_Master | F8: Y | G8: GT drains, trash boxes, laterals, rock pads
B9: Hydraulic breaker 13-15T | C9: day | D9: 203 | E9: Hyd Equip&HIRE_Master | F9: Y | G9: Rock extra-over band only
B10: Trench roller dbl drum remote | C10: day | D10: 165 | E10: Hyd Equip&HIRE_Master | F10: Y
B11: Upright rammer / wacker | C11: day | D11: 34.29 | E11: Hyd Equip&HIRE_Master | F11: Y
B12: <6T tipper truck | C12: day | D12: 171.43 | E12: Hyd Equip&HIRE_Master | F12: Y
B13: Vacuum excavator (TPZ/services) | C13: day | D13: 295.77 | E13: Hyd Equip&HIRE_Master | F13: Y | G13: VFMP water excavation in NRZs (arborist supervised)
B14: Sump pumps / dewatering set | C14: day | D14: 57 | E14: Hyd Equip&HIRE_Master (flexdrive set) | F14: Y | G14: Wet-season seepage per geotech S4.2
B15: Water truck (test/flush cartage) | C15: day | D15: 1100 | E15: Misc Subbie Rates $110/hr wet x 10 hr | F15: Y | G15: No site water — ITT S17.3
B16: 50t mobile crane (wet) | C16: day | D16: 3800 | E16: ALLOWANCE — quote at award | F16: N — FLAG: NOT IN HIRE REGISTERS | G16: C10 RCBC 2700x1200 + WSUD DN3300 sets
B17: Franna / pick-and-carry (wet) | C17: day | D17: 2200 | E17: ALLOWANCE — quote at award | F17: N — FLAG: NOT IN HIRE REGISTERS | G17: Culvert crown units
B18: Trench shields | C18: day | D18: 120 | E18: ALLOWANCE — quote at award | F18: N — FLAG: NOT IN HIRE REGISTERS | G18: WSUD + C10 + entered runs >1.5 m per geotech 5.3.3
B19: Quick-cut / demo saw | C19: day | D19: 100 | E19: Benchmark (Civ register $100/wk Coates line — treated /day) | F19: Y (weekly basis) | G19: GT drain cutting
B20: PE butt/electrofusion welder | C20: day | D20: 0 | E20: NOT REQUIRED — TCS scope has no PE pressure welding (rising main = TPS) | F20: N — FLAG: ABSENT FROM ALL REGISTERS | G20: Flagged per rebuild direction; if scope changes, quote at award
B22: REFERENCE — MIGRATED FROM MasterCostSheet_Civ.V1 'Equip&HIRE' (weekly 5-day rates, all qty=0 in old model; retained for comparison only — NOT used in pricing)
B23: Description | D23: TCS wkly | E23: CAT (ROK) wkly | F23: COATES wkly | G23: ONSITE wkly
B24: Skid Steer Loader_Tracked | D24: 0 | E24: 0 | F24: 0 | G24: 262
B25: Skid Steer Loader_Wheeled | D25: 300 | E25: 250 | F25: 192 | G25: 0
B26: 4.5-6Ton_Excavator | D26: 200 | E26: 0 | F26: 0 | G26: 0
B27: 8Ton_Excavator | D27: 250 | E27: 0 | F27: 0 | G27: 0
B28: 10-12Ton_Excavator | D28: 310 | E28: 310 | F28: 301 | G28: 300
B29: 14-16Ton_Excavator | D29: 440 | E29: 370 | F29: 375 | G29: 295
B30: 20-24Ton_Excavator | D30: 450 | E30: 480 | F30: 417 | G30: 444
B31: Ripper_10-12T | D31: 26 | E31: 0 | F31: 25.7 | G31: 0
B32: Ripper_14-16T | D32: 26 | E32: 0 | F32: 25.7 | G32: 21
B33: Ripper_20-24T | D33: 30 | E33: 0 | F33: 30.1 | G33: 23
B34: Auger Drive_10-12T | D34: 115 | E34: 0 | F34: 0 | G34: 0
B35: 300Dia Auger Drill | D35: 50 | E35: 0 | F35: 0 | G35: 0
... B58: TRANSPORT_Ex ROK - Return (22T) | D58: 0 | E58: 0 | F58: 480 | G58: 0

Sheet Accommodation
B1: ACCOMMODATION & FIFO TRAVEL — TCS
B2: Basis: Roster Example #3 — 6-day week, 10-hr days, stay Rockhampton weekends, fly home every 2nd weekend. 21 work-days / 210 hrs per month. Rates ex GST from Accomodation_Master (Hyd). No shared accommodation between entities (Directive 5.2).
B4: Full apartment/townhouse via agent (houses crew of 3), per month | C4: 4606.06 | D4: Accomodation_Master E308 ex GST
B5: Individual private unit, nightly | C5: 103.2468 | D5: Accomodation_Master F364 ex GST
B6: Nights per person-month (approx 5 nights home / month on 2nd-weekend fly-back) | C6: 25
B7: Flight one-way (Qantas, no checked luggage) ex GST | C7: 200 | D7: Misc Subbie Rates_Master: $220 incl GST -> $200 ex GST
B8: Return flights per person-month (fly home every 2nd weekend) | C8: 2
B10: Month | C10: Persons on site (incl LH) | D10: Apartments (3/apt) | E10: Apartment cost | F10: Individual nights | G10: Individual cost
B11: M1 (A+B+C+LH) | C11: 10 | D11: =ROUNDUP((C11-1)/3,0) -> 3 | E11: =D11*$C$4 -> 13818.18 | F11: =C11*$C$6 -> 250 | G11: =F11*$C$5 -> 25811.7
B12: M2 (A+B+C+LH) | C12: 10 | D12: =ROUNDUP((C12-1)/3,0) -> 3 | E12: =D12*$C$4 -> 13818.18 | F12: =C12*$C$6 -> 250 | G12: =F12*$C$5 -> 25811.7
B13: M3 (B+C+LH) | C13: 7 | D13: =ROUNDUP((C13-1)/3,0) -> 2 | E13: =D13*$C$4 -> 9212.12 | F13: =C13*$C$6 -> 175 | G13: =F13*$C$5 -> 18068.19
B14: M4 (B+LH) | C14: 4 | D14: =ROUNDUP((C14-1)/3,0) -> 1 | E14: =D14*$C$4 -> 4606.06 | F14: =C14*$C$6 -> 100 | G14: =F14*$C$5 -> 10324.68
B15: M5 (B+C+LH) | C15: 7 | D15: =ROUNDUP((C15-1)/3,0) -> 2 | E15: =D15*$C$4 -> 9212.12 | F15: =C15*$C$6 -> 175 | G15: =F15*$C$5 -> 18068.19
B16: M6 (A+C+LH) | C16: 7 | D16: =ROUNDUP((C16-1)/3,0) -> 2 | E16: =D16*$C$4 -> 9212.12 | F16: =C16*$C$6 -> 175 | G16: =F16*$C$5 -> 18068.19
B17: TOTAL (6 months) | C17: =SUM(C11:C16) -> 45 | D17: =SUM(D11:D16) -> 13 | E17: =SUM(E11:E16) -> 59878.78 | F17: =SUM(F11:F16) -> 1125 | G17: =SUM(G11:G16) -> 116152.65
B19: LH individual nights (Option A: LH on nightly individual, 6 months x 25 nights) | C19: =6*$C$6 -> 150 | E19: =C19*$C$5 -> 15487.02
B21: OPTION A — apartments (crews) + LH individual [ADOPTED] | E21: =E17+E19 -> 75365.8
B22: OPTION B — all individual nightly (shown for comparison; NOT adopted) | E22: =G17 -> 116152.65
B23: Option B premium vs Option A | E23: =E22-E21 -> 40786.85
B25: FIFO return flights (person-months x returns/month x 2 legs x one-way rate) | E25: =C17*$C$8*2*$C$7 -> 36000
B27: TOTAL ACCOMMODATION + FIFO TRAVEL (Option A, adopted) — carried to work-area cost pro-rata crew-days | E27: =E21+E25 -> 111365.8

Sheet Prelim_OH
B1: PRELIMINARIES & OVERHEAD — BOTTOM-UP CROSS-CHECK (TCS)
B2: The sell carries Prelims 5.5% + OH 18% + Profit 18%, EACH calculated ON TOTAL COST per Directive 5.4 (no compounding). This sheet builds TRUE PRELIMINARIES bottom-up and cross-checks the 5.5% allowance. Items here are NOT added to the sell — they are funded from the 5.5% pool. Leading Hand supervision is NOT a preliminary: per TriCore methodology it is DIRECT LABOUR and is priced in the Stage 1A/1B labour blocks (row retained below at $0 for traceability). All ex GST.
B4: Item | C4: Qty | D4: Unit | E4: Rate | F4: Total | G4: Basis / note
B5: LH SUPERVISION
B6: Leading Hand supervision (site-wide, both stages) — REALLOCATED TO DIRECT LABOUR | C6: 0 | D6: day | E6: =LabourRates_Master!$G$11 -> 1329.6343 | F6: =C6*E6 -> 0 | G6: REALLOCATED to direct labour per TriCore methodology (old Civ 'SW Zone Sumry' B13 prices TRADESMAN_LEADING HAND as a Day line inside the work-area labour block) — see TCS_CHANGE_LOG.md S9. Row retained at ZERO for traceability; the 120 LH-days are priced at Stage1A_Drainage A-14 and Stage1B_Drainage A-14. Rate shown for reference.
B7: ESTABLISHMENT (non-labour; establishment crew-days are in Stage1A/1B labour A-01/A-12)
B8: Compound set-up: fencing, gates, signage, rumble grid/washdown (VFMP) | C8: 1 | D8: lot | E8: 4500 | F8: =C8*E8 -> 4500 | G8: Estimator allowance — VFMP washdown compliance.
B9: 20 ft container / site storage | C9: 6 | D9: month | E9: 150 | F9: =C9*E9 -> 900 | G9: Benchmark (register weekly rates implausibly low — flagged).
B10: Site admin, stationery, Greenstar admin | C10: 6 | D10: month | E10: 1600 | F10: =C10*E10 -> 9600 | G10: Old Civ Prelim rate $1,600/mo.
B11: Site PPE | C11: 6 | D11: month | E11: 400 | F11: =C11*E11 -> 2400 | G11: Old Civ Prelim rate.
B12: Site consumables — paint, tapes etc | C12: 6 | D12: month | E12: 180 | F12: =C12*E12 -> 1080 | G12: Old Civ Prelim rate.
B13: Site management — bollards, pickets, barrier mesh | C13: 6 | D13: month | E13: 400 | F13: =C13*E13 -> 2400 | G13: Old Civ Prelim rate.
B14: Dual cab ute | C14: 6 | D14: month | E14: 541 | F14: =C14*E14 -> 3246 | G14: Civ Equip&HIRE $125/wk x 4.33.
B15: 10 m3 skip bin + waste | C15: 6 | D15: month | E15: 600 | F15: =C15*E15 -> 3600 | G15: Benchmark incl exchanges (spoil stays on site per Add 2 — general waste only).
B16: TEMPORARY SERVICES — TCS OWN SHARE (locked Split; nothing shared, ITT S17.3: no site power or water)
B17: Portable toilets + wash station (2 no.) | C17: 26 | D17: week | E17: 120 | F17: =C17*E17 -> 3120 | G17: Benchmark 2 x $60/wk.
B18: 6 KVA genset + fuel | C18: 26 | D18: week | E18: 130 | F18: =C18*E18 -> 3380 | G18: Civ register $50/wk + fuel allowance.
B19: Temporary potable water storage + CARTAGE (no site water) | C19: 1 | D19: lot | E19: 6000 | F19: =C19*E19 -> 6000 | G19: Estimator allowance — ITT S17.3; incl temp water cartage for amenities/testing top-up.
B20: Temporary power boards / leads | C20: 26 | D20: week | E20: 25 | F20: =C20*E20 -> 650 | G20: Civ register rate.
B21: EDQ GATE
B22: EDQ-gate remobilisation — plant float 2 loads | C22: 2 | D22: load | E22: 800 | F22: =C22*E22 -> 1600 | G22: RPT006_B S3.1 Conditions 16/17; $200/hr x 4 hr/load. Crew remobilisation 4 crew-days carried in Stage1A labour A-11 (not here — no double count).
B23: QA DELIVERABLES — ADAC / CCTV / AS-CONSTRUCTED
B24: CCTV of all TCS in-ground drainage (independent approved firm, Superintendent present) | C24: =ROUND(Stage1A_Drainage!C6+Stage1A_Drainage!C8+Stage1A_Drainage!C10+Stage1A_Drainage!C11+Stage1A_Drainage!C12+Stage1A_Drainage!C13+Stage1A_Drainage!C14+Stage1A_Drainage!C16+Stage1A_Drainage!C17+Stage1A_Drainage!C18+Stage1B_Drainage!C6,0) -> 1667 | D24: m | E24: =Materials_Master!$H$82 -> 5.75 | F24: =C24*E24 -> 9585.25 | G24: VOL38 3.56; qty = 1A + 1B pipe metres (formula); rate x1.15 subbie.
B25: ADAC XML preparation + validation (TCS stormwater assets) | C25: 1 | D25: lot | E25: 4500 | F25: =C25*E25 -> 4500 | G25: ITT S19 / CMDG ADAC deliverable — estimator allowance.
B26: RPEQ certification + as-constructed drawing preparation | C26: 1 | D26: lot | E26: 3500 | F26: =C26*E26 -> 3500 | G26: Estimator allowance; surveyor pickup attendance already in Stage subbies.
B27: Drainage clean / pre-PC de-silt (S24) | C27: 1 | D27: lot | E27: 2500 | F27: =C27*E27 -> 2500 | G27: Estimator allowance.
B29: BOTTOM-UP PRELIMS TOTAL | F29: =SUM(F5:F27) -> 62561.25
B31: 5.5% PRELIMS ALLOWANCE (as carried in the sell = 5.5% x total cost 1A+1B) | F31: =0.055*(Stage1A_Drainage!$F$136+Stage1B_Drainage!$F$42) -> 111747.03
B32: CROSS-CHECK — variance (allowance less bottom-up; negative = allowance shortfall) | F32: =F31-F29 -> 49185.777
B33: Variance % (bottom-up vs allowance) | F33: =F29/F31-1 -> -0.44015289
B35: OVERHEAD CROSS-CHECK
B36: OH 18% x total cost (as carried in the sell) | F36: =0.18*(Stage1A_Drainage!$F$136+Stage1B_Drainage!$F$42) -> 365717.54
B37: TriCore overheads benchmark — $20,000/month x 6 months (old Civ Prelim_OH-Check rate) | C37: 6 | D37: month | E37: 20000 | F37: =C37*E37 -> 120000
B38: OH margin vs benchmark | F38: =F36-F37 -> 245717.54

Sheet EBC
B1: EBC — EXCLUDED-BUT-COSTED / DIRECTOR-PENDING REGISTER (TCS)
B2: Add-prices computed at the same commercial basis as the base model (escalated rates, x1.18 on materials, 41.5% on cost). Reinstatement cell references given per item. ALL EX-GST.
B4: Item | C4: Qty | D4: Unit | E4: Rate | F4: Total | G4: Note
B5: E1 — KERB CHUTES x9 — 'Director decision D6-F1' (BOTH POSITIONS CARRIED — do not close either way)
B6: Position 1 (BASE, as modelled): kerb chutes EXCLUDED entirely per Denis 24-Jul email — base lump sums carry $0.
B7: Position 2 (ADD-PRICE): 9 chutes (03-02, 03-03, 04-02, 13-02 to 18-02 per F1310/F1325) + rock + erosion matting:
B8: Kerb chute structure materials (concrete invert, kerb returns, R1000) | C8: 9 | D8: ea | E8: =Materials_Master!$H$79 -> 850 | F8: =C8*E8 -> 7650
B9: Kerb chute rock DIA 100 x 180 thick (55.67 m2 x 0.18) | C9: =55.67*0.18 -> 10.0206 | D9: m3 | E9: =Materials_Master!$H$81 -> 150 | F9: =C9*E9 -> 1503.09
B10: Erosion control matting | C10: 56 | D10: m2 | E10: =Materials_Master!$H$80 -> 7 | F10: =C10*E10 -> 392
B11: Materials subtotal x1.18 contingency | F11: =SUM(F8:F10)*Materials_Master!$D$8 -> 11263.206
B12: Labour B-09 — 9 crew-days (Phase 7 EBC) | C12: 9 | D12: crew-day | E12: =LabourRates_Master!$G$15 -> 2862.4261 | F12: =C12*E12 -> 25761.835
B13: Plant — 3-5T excavator 9 days | C13: 9 | D13: day | E13: =Equip_Master!$D$8 -> 238.67 | F13: =C13*E13 -> 2148.03
B14: KERB CHUTES ADD-PRICE (cost x 1.415) | F14: =(F11+F12+F13)*(1+'TCS $ Sched'!$C$8+'TCS $ Sched'!$C$9+'TCS $ Sched'!$C$10) -> 55429.896 | G14: Reinstatement: add labour row B-09 (9 crew-days) to Stage1A_Drainage labour block; add the three material rows above to the Stage 1A materials block; add 9 plant-days to the 3-5T excavator line.
B16: E2 — DETENTION BASIN EARTHWORKS + CONCRETE SPILLWAY — ALLOCATION RFI PENDING (Opens #26; Director)
B17: Base carries $0 (Stage1A_Drainage row X1 and labour B-07 held at 0). Spillway build-up below for reinstatement if allocated to TCS; basin bulk earthworks NOT QUANTIFIED anywhere (F1305 annotation only) — cannot be priced, RFI.
B18: Spillway concrete 25 MPa, 125 thk x 50 m weir + 1.5 m aprons (F1323 build-up) | C18: =ROUND(50*1.65*0.125,1) -> 10.3 | D18: m3 | E18: =Materials_Master!$H$75 -> 400 | F18: =C18*E18 -> 4120
B19: SL72 mesh central | C19: 12 | D19: sheet | E19: =Materials_Master!$H$76 -> 85 | F19: =C19*E19 -> 1020
B20: Type 2.3 sub-base 75 mm | C20: 13 | D20: T | E20: =Materials_Master!$H$77 -> 48 | F20: =C20*E20 -> 624
B21: Materials subtotal x1.18 contingency | F21: =SUM(F18:F20)*Materials_Master!$D$8 -> 6801.52
B22: Labour B-07 — 10 crew-days (5 m/day, L-confidence) | C22: 10 | D22: crew-day | E22: =LabourRates_Master!$G$15 -> 2862.4261 | F22: =C22*E22 -> 28624.261
B23: Plant — 3-5T excavator 5 days + concrete gear allowance | C23: 5 | D23: day | E23: =Equip_Master!$D$8+100 -> 338.67 | F23: =C23*E23 -> 1693.35
B24: SPILLWAY ADD-PRICE IF ALLOCATED TO TCS (cost x 1.415) | F24: =(F21+F22+F23)*(1+'TCS $ Sched'!$C$8+'TCS $ Sched'!$C$9+'TCS $ Sched'!$C$10) -> 52523.57 | G24: Reinstatement: set Stage1A_Drainage labour B-07 = 10 cd; enter spillway material rows at X1; add 5 plant-days 3-5T.
B26: E3 — RECORDS (excluded / relocated items — nothing lost silently)
B27: Grated trench drains (GT1-9, trash boxes, excavation & quarry) — REINSTATED into base (1A 3.5 / 1B 2.3-a). Old workbook computed $164,860.30 in an orphaned column (K258) that never reached the old total. | F27: REINSTATED — in base
B28: 100 mm subsoil / type 2 strip-filter drainage, 2,172.4 m — EXCLUDED 'by others' (locked 5.3; matrix 2.3-x2/2.5-x3). Old workbook carried $10,865 in orphaned cells J269 (never in total). Interface: strip-filter connections at TCS collector pits only. | F28: EXCLUDED — E+Q
B29: Sewer rising main Ø100/DN110 (110 m allowance) — TPS scope (matrix 2.1-x2 EBC in TPS model), NOT in TCS. | F29: NOT TCS
B30: Sewer pump station QMax Fortis — EXCLUDED per Addendum 2 (Council installs); TPS interface ledger item, NOT TCS. | F30: NOT TCS
B31: $20,000 provisional connection fees (Sch 1A 5.0 / 1B 4.6) — TPS side, carried as directed in TPS model, NOT in TCS. | F31: NOT TCS
B32: WSUD supply basis — old Atlan $88,838 'high level estimate' (day-of-issue validity) SUPERSEDED by Reece Q-459014431 line $90,064.63 + $7,142.10 freight as PC Sum +15% (RPT006_B 7.4 nomination). | F32: SUPERSEDED — PC

Sheet Sched3_Extract
B1: SCHED3_EXTRACT — PAYNTERS TENDER SCHEDULE 3 LINE STRUCTURE WITH TCS PRICES (D5)
B2: Exact Schedule 3 1A/1B structure (schedule3_transcript.md rows cited) for direct transfer. Only TCS lines carry prices; other-trade lines shown as headers only. ALL EX-GST.
A4: 1A | B4: R5 | C4: 1.0 | D4: Preliminaries & Documentation (1.1-1.7) | H4: TCS's own establishment/TC/ESC/plans/set-out/QA-ADAC/PM are inside the lump sum rates below (Split per matrix 1.1-1.7); enter at section level only if Paynters direct.
A5: 1A | B5: R15 | C5: 2.0 | D5: Site Works
A6: 1A | B6: R33 | C6: 2.3 | D6: Road and Carpark — Drainage, retaining structures and protective treatments | H6: TCS prices the DRAINAGE COMPONENT ONLY; mapped into 2.5 Stormwater drainage below under the single-pricing control (each F13xx line ID priced once — matrix 2.3-a). Retaining/protective treatments NOT TCS.
A7: 1A | B7: R49 | C7: 2.5 | D7: Drainage
A8: 1A | B8: R50 | D8: Stormwater drainage | E8: Item | F8: 1 | G8: ='TCS $ Sched'!D24-F67 -> 2204088.5 | H8: 1A lump sum less GT component (GT carried at 3.5). Includes 2.3-a drainage component, culverts, headwalls, pits, WSUD INSTALLATION, rock protection.
A9: 1A | B9: R51 | D9: Retention Basin | H9: Outlet structures (C10, spillway interface, rock pads) included in Stormwater drainage line. Detention basin bulk earthworks + concrete spillway NOT PRICED — allocation RFI pending (Opens #26; drawings say DETENTION basin).
A10: 1A | B10: R52 | D10: WSUD Basin? (question mark in document) | E10: Item | F10: 1 | G10: ='TCS $ Sched'!D31 -> 111787.74 | H10: PC SUM — supply + delivery of 22x Ocean Protect Tall (690) PSorb StormFilter cartridges O.A.E. in DN3300 manhole + 15% (locked 5.3). Installation in the Stormwater drainage lump sum. RFI CL A4.
A11: 1A | B11: R59 | C11: 3.0 | D11: Netball Courts
A12: 1A | B12: R81-82 | C12: 3.5 | D12: Hydraulic — Grated trench drains and pits | E12: Item | F12: 1 | G12: =F67 -> 557726.5 | H12: TCS despite 'Hydraulic' heading (locked 5.1; drawn on civil sheets). GT1-GT4 + GT7-GT9 = 561.9 m Hauraton Recyfix + trash boxes + connection pits incl excavation & quarry — REINSTATED in full. GT5/GT6 in Stage 1B.
A13: 1A | B13: R138 | D13: LUMP SUM TOTAL (EXC. GST) — TCS lines | G13: ='TCS $ Sched'!D24+'TCS $ Sched'!D31 -> 2873602.7 | H13: Sum of: Stormwater drainage + 3.5 GT + WSUD PC.
A14: 1A | B14: R140 | C14: 7.0 | D14: Schedule of Rates - Provisions
A15: 1A | B15: R141 | D15: Rock — removal of rock as defined in tender specification — SOFT ROCK, TRENCHES | E15: m3 | G15: ='TCS $ Sched'!F51 -> 239.11491 | H15: 4 rates per H002 n.24 (soft/hard x trench/pit); TCS rates apply to stormwater excavations only.
A16: 1A | B16: R141 | D16: Rock — HARD ROCK, TRENCHES | E16: m3 | G16: ='TCS $ Sched'!F52 -> 478.22983
A17: 1A | B17: R141 | D17: Rock — SOFT ROCK, PITS | E17: m3 | G17: ='TCS $ Sched'!F53 -> 318.81989
A18: 1A | B18: R141 | D18: Rock — HARD ROCK, PITS | E18: m3 | G18: ='TCS $ Sched'!F54 -> 597.78729
A19: 1A | B19: R142 | D19: Unsuitable ground — removal and reinstatement | E19: m3 | G19: ='TCS $ Sched'!F55 -> 390.38511 | H19: Superintendent written direction only (ITT S18.1).
A21: 1B | B21: R15 | C21: 2.0 | D21: Site Works
A22: 1B | B22: R28 | C22: 2.3 | D22: Drainage
A23: 1B | B23: R29 | D23: Stormwater drainage | E23: Item | F23: 1 | G23: ='TCS $ Sched'!D44 -> 113131.26 | H23: 1B lump sum: GT5 + GT6 (46.6 m) + lines 60/61/83 + TB100 x4, standalone-viable (5.2).
A24: 1B | B24: R30 | D24: Retention Basin | H24: NO separate 1B basin documented anywhere in the civil set — carried UNPRICED with qualification + RFI (CL A4); the single detention basin sits in the 1A hatch.
A25: 1B | B25: R113 | D25: LUMP SUM TOTAL (EXC. GST) — TCS lines | G25: ='TCS $ Sched'!D44 -> 113131.26
A26: 1B | B26: R115 | C26: 5.0 | D26: Schedule of Rates - Provisions
A27: 1B | B27: R116 | D27: Rock — SOFT ROCK, TRENCHES | E27: m3 | G27: ='TCS $ Sched'!F51 -> 239.11491 | H27: Same tendered rates as 1A (each stage's own excavations).
A28: 1B | B28: R116 | D28: Rock — HARD ROCK, TRENCHES | E28: m3 | G28: ='TCS $ Sched'!F52 -> 478.22983
A29: 1B | B29: R116 | D29: Rock — SOFT ROCK, PITS | E29: m3 | G29: ='TCS $ Sched'!F53 -> 318.81989
A30: 1B | B30: R116 | D30: Rock — HARD ROCK, PITS | E30: m3 | G30: ='TCS $ Sched'!F54 -> 597.78729
A31: 1B | B31: R117 | D31: Unsuitable ground — removal and reinstatement | E31: m3 | G31: ='TCS $ Sched'!F55 -> 390.38511
B60: HELPER — GT (grated trench) component build-out for Sch 1A 3.5 split
D61: GT materials (G1-G5) escalated + x1.18 | F61: =(Stage1A_Drainage!F54+Stage1A_Drainage!F55+Stage1A_Drainage!F56+Stage1A_Drainage!F57+Stage1A_Drainage!F58)*Materials_Master!$D$8 -> 238277.27
D62: GT labour C-06 + C-07 | F62: =Stage1A_Drainage!F101+Stage1A_Drainage!F102 -> 103047.34
D63: GT plant (36 d 3-5T + quick-cut 5 d) | F63: =36*Equip_Master!$D$8+5*Equip_Master!$D$19 -> 9092.12
D64: GT accommodation share (36 cd pro-rata) | F64: =Accommodation!$E$27*36/(Stage1A_Drainage!C103+Stage1B_Drainage!C23) -> 17978.335
D65: GT LH supervision share (36 cd pro-rata) | F65: =(Stage1A_Drainage!F104+Stage1B_Drainage!F24)*36/(Stage1A_Drainage!C103+Stage1B_Drainage!C23) -> 25757.938
D66: GT component cost | F66: =SUM(F61:F65) -> 394153
D67: GT component SELL (x 1.415 on cost) | F67: =F66*(1+'TCS $ Sched'!$C$8+'TCS $ Sched'!$C$9+'TCS $ Sched'!$C$10) -> 557726.5
