Workbook
Name aa: #REF!
Name aa: #REF!
Name aa: #REF!
Name aa: #REF!
Name aa: 'MISC & SITEWIDE'!#REF!
Name aa: #REF!
Name aa: #REF!
Name aa: #REF!
Name aa: #REF!
Name aa: #REF!
Name aa: #REF!
Name aa: #REF!
Name aa: #REF!
Name aa: #REF!
Name aa: #REF!
Name bh: #REF!
Name Civil4: #REF!
Name Civil4: #REF!
Name Civil4: #REF!
Name Civil4: #REF!
Name Civil4: 'MISC & SITEWIDE'!#REF!
Name Civil4: #REF!
Name Civil4: #REF!
Name Civil4: #REF!
Name Civil4: #REF!
Name Civil4: #REF!
Name Civil4: #REF!
Name Civil4: #REF!
Name Civil4: #REF!
Name Civil4: #REF!
Name Civil4: #REF!
Name d: #REF!
Name d: #REF!
Name d: #REF!
Name d: #REF!
Name d: 'MISC & SITEWIDE'!#REF!
Name d: #REF!
Name d: #REF!
Name d: #REF!
Name d: #REF!
Name d: #REF!
Name d: #REF!
Name d: #REF!
Name d: #REF!
Name d: #REF!
Name d: #REF!
Name date: #REF!
Name date: #REF!
Name date: #REF!
Name date: #REF!
Name date: 'MISC & SITEWIDE'!#REF!
Name date: #REF!
Name date: #REF!
Name date: #REF!
Name date: #REF!
Name date: #REF!
Name date: #REF!
Name date: #REF!
Name date: #REF!
Name date: #REF!

Sheet TCS $ Sched
B6: SUMMARY | V6: BIG TICKET ITEMS
B8: JOB DESCRIPTION: | N8: DATE: | V8: ROK 092
B9: SITE ADDRESS: | I9: CQU ROK | N9: TCS Quote #: **
R10: Cost | S10: (Cost + O/H) + Profit | V10: TRADE WASTE HOLDING TANK HOL(1) | Y10: ROK 092 - Sanitary Drainage Pump Station SDPS | AB10: ROK 092 - OIL/WATER SEPARATOR (OWS 2)
N11: TOTALS | V11: Purchase Cost Total | W11: 18000 | Y11: Purchase Cost Total | Z11: 35563 | AB11: Purchase Cost Total | AC11: 15932
V13: TPS Markup | W13: 1.15 | Y13: TPS Markup | Z13: 1.15 | AB13: TPS Markup | AC13: 1.15
B14: ROK092 | V14: Qty | W14: 1 | Y14: Qty | Z14: 1 | AB14: Qty | AC14: 1
V15: Freight | W15: 121 | Y15: Freight | Z15: 8965 | AB15: Freight | AC15: 2000
B16: A | C16: . | D16: 1 | I16: ROK 092 _ Hydraulic & Fire Services Complete | N16: =S16+Z17+W17+AC17+AC27+Z27+W26+W54+AC36+AC44+Z44+W44 -> 1103268.3 | R16: ='ROK092'!F908 -> 651013.36 | S16: =((R16/$R$64)*($R$74-$R$64))+R16 -> 967108.98 | V16: Installation_MH | W16: 1850 | Y16: Installation_MH | Z16: 1250 | AB16: Installation_MH | AC16: 2500
B17: A | C17: . | D17: 1 | E17: . | F17: 1 | J17: Ground Floor - InGround Services (Drainage, Water, Fire) | M17: 0 | V17: TOTAL | W17: =W11*W13*W14+W15+W16 -> 22671 | Y17: TOTAL | Z17: =Z11*Z13*Z14+Z15+Z16 -> 51112.45 | AB17: TOTAL | AC17: =AC11*AC13*AC14+AC15+AC16 -> 22821.8
B18: A | C18: . | D18: 1 | E18: . | F18: 2 | J18: Temps_ Plumbing Services and Connections for 'Typical' Construction temps | M18: 8620
B19: A | C19: . | D19: 1 | E19: . | F19: 3 | J19: Supply Hydraulic Fixtures | M19: 0 | V19: ROK 092 - Rainwater Pump 1(Dave KRB4 )
V20: Purchase Cost Total | W20: 2092 | Y20: ROK 092 - Rainwater Harvesting Filters - RWF (1) | AB20: RAIN WATER HARVESTING TANK RWHT (1)
B21: ROK021A | Y21: Purchase Cost Total | Z21: 4135 | AB21: Purchase Cost Total | AC21: 13200
V22: TPS Markup | W22: 1.15
B23: B | C23: . | D23: 1 | I23: ROK021A_ Hydraulic & Fire Services Complete | N23: =S23+W65 -> 81951.779 | R23: =ROK21A!F853 -> 54039.91 | S23: =((R23/$R$64)*($R$74-$R$64))+R23 -> 80278.664 | V23: Qty | W23: 1 | Y23: TPS Markup | Z23: 1.15 | AB23: TPS Markup | AC23: 1.15
B24: B | C24: . | D24: 1 | E24: . | F24: 1 | J24: Temps_ Plumbing Services and Connections for 'Typical' Construction temps | M24: 500 | V24: Freight | W24: 121 | Y24: Qty | Z24: 1 | AB24: Qty | AC24: 1
B25: B | C25: . | D25: 1 | E25: . | F25: 2 | J25: Supply Hydraulic Fixtures | M25: 0 | V25: Installation_MH | W25: 1000 | Y25: Freight | Z25: 121 | AB25: Freight
V26: TOTAL | W26: =W20*W22*W23+W24+W25 -> 3526.8 | Y26: Installation_MH | Z26: 1000 | AB26: Installation_MH | AC26: 1000
B27: ROK019 | Y27: TOTAL | Z27: =Z21*Z23*Z24+Z25+Z26 -> 5876.25 | AB27: TOTAL | AC27: =AC21*AC23*AC24+AC25+AC26 -> 16180
B29: C | C29: . | D29: 1 | I29: ROK019_ Hydraulic & Fire Services Complete | N29: =S29+W77+Z77 -> 210148.67 | R29: ='ROK019'!F854 -> 137986.01 | S29: =((R29/$R$64)*($R$74-$R$64))+R29 -> 204984.29
B30: C | C30: . | D30: 1 | E30: . | F30: 1 | J30: Temps_ Plumbing Services and Connections for 'Typical' Construction temps | M30: 3840 | V30: ROK 092 - Boiling/ Chilled /Hot Water Unit BCHWU (1) | Y30: ROK 092 - Boiling Chilled water unit BCWU (1) | AB30: ROK 092 - HWU 4 DHE27
B31: C | C31: . | D31: 1 | E31: . | F31: 2 | J31: Supply Hydraulic Fixtures | M31: 0 | V31: Purchase Cost Total | W31: 6930.1 | Y31: Purchase Cost Total | Z31: 4056.3 | AB31: Purchase Cost Total | AC31: 1432.3
Y32: FONT KID | Z32: 415.3
B33: ROK033 | V33: TPS Markup | W33: 1.15 | Y33: TPS Markup | Z33: 1.15 | AB33: TPS Markup | AC33: 1.15
V34: Qty | W34: 1 | Y34: Qty | Z34: 1 | AB34: Qty | AC34: 1
B35: D | C35: . | D35: 1 | I35: ROK033_ Hydraulic & Fire Services Complete | N35: =S35+W88+Z88+AC88 -> 405932.81 | R35: ='ROK033'!F860 -> 264906.62 | S35: =((R35/$R$64)*($R$74-$R$64))+R35 -> 393530.44 | V35: Installation_MH | Y35: Installation_MH | AB35: Installation_MH | AC35: 500
B36: D | C36: . | D36: 1 | E36: . | F36: 1 | J36: Temps_ Plumbing Services and Connections for 'Typical' Construction temps | M36: 3840 | V36: TOTAL | W36: =W31*W33*W34+W35 -> 7969.615 | Y36: TOTAL | Z36: =Z31*Z33*Z34+Z32+Z35 -> 5080.045 | AB36: TOTAL | AC36: =AC31*AC33*AC34+AC35 -> 2147.145
B37: D | C37: . | D37: 1 | E37: . | F37: 2 | J37: Supply Hydraulic Fixtures | M37: 0
V38: ROK 092 - HWU 5 DEL 27 PLUS | Y38: ROK 092 - HWU 6 DEL 18 | AB38: ROK 092 - HWU 7 DHB-E 13 LCD
B39: ROK034 | V39: Purchase Cost Total | W39: 1302.1 | Y39: Purchase Cost Total | Z39: 1240.1 | AB39: Purchase Cost Total | AC39: 1020.1
B41: E | C41: . | D41: 1 | I41: ROK034_ Hydraulic & Fire Services Complete | N41: =S41 -> 71587.708 | R41: ='ROK034'!F852 -> 48189.558 | S41: =((R41/$R$64)*($R$74-$R$64))+R41 -> 71587.708 | V41: TPS Markup | W41: 1.15 | Y41: TPS Markup | Z41: 1.15 | AB41: TPS Markup | AC41: 1.15
B42: E | C42: . | D42: 1 | E42: . | F42: 1 | J42: Temps_ Plumbing Services and Connections for 'Typical' Construction temps | M42: 500 | V42: Qty | W42: 1 | Y42: Qty | Z42: 3 | AB42: Qty | AC42: 1
B43: E | C43: . | D43: 1 | E43: . | F43: 2 | J43: Supply Hydraulic Fixtures | M43: 0 | V43: Installation_MH | W43: 500 | Y43: Installation_MH | Z43: 500 | AB43: Installation_MH | AC43: 500
V44: TOTAL | W44: =W39*W41*W42+W43 -> 1997.415 | Y44: TOTAL | Z44: =Z39*Z41*Z42+Z43 -> 4778.345 | AB44: TOTAL | AC44: =AC39*AC41*AC42+AC43 -> 1673.115
B45: ROK036
B47: F | C47: . | D47: 1 | I47: ROK036_ Hydraulic & Fire Services Complete | N47: =S47+W110+AC110+Z120+W120 -> 1094184.6 | R47: ='ROK036'!F938 -> 717701.26 | S47: =((R47/$R$64)*($R$74-$R$64))+R47 -> 1066176.8
B48: F | C48: . | D48: 1 | E48: . | F48: 1 | J48: Temps_ Plumbing Services and Connections for 'Typical' Construction temps | M48: 3840 | V48: ROK 092 - Lift Pump Sump
B49: F | C49: . | D49: 1 | E49: . | F49: 2 | J49: Supply Hydraulic Fixtures | M49: 0 | V49: Purchase Cost Total | W49: 2500
B51: ROK076 | V51: TPS Markup | W51: 1.15
...

Sheet 00_ TCS Prelim & OH
B1: Project:
B2: Tricore -
B3: Stage 1 Version 1
A4: Item
A7: A | B7: PRELIMINARIES
B8: SUMMARY (Not added in prelim$)
C9: =[1]Program_MASTER!$B$102 -> TOTAL Days Mobilized On Site
C10: =[1]Program_MASTER!B103 -> Months Mobilized
C11: =[1]Program_MASTER!B104 -> Work Weeks' Mobilized On Site
C12: =[1]Program_MASTER!B105 -> Work Days
C13: Breakdown as per program
B14: ='LabourProject Rates_Master'!$B$14 -> TRADESMAN_LEADING HAND | C14: Day | E14: =E36 -> 1231.1429 | F14: =D14*E14 -> 0
B15: ='LabourProject Rates_Master'!$B$23 -> TRADESMAN_PLUMBER_OPERATOR | C15: Day | E15: =E37 -> 941.16473 | F15: =D15*E15 -> 0
B16: ='LabourProject Rates_Master'!$B$30 -> T/A & Apprentice | C16: Day | E16: =E38 -> 768.06508 | F16: =D16*E16 -> 0
B17: ='LabourProject Rates_Master'!$B$36 -> Crew #1 - InGround Drainage | C17: Day | E17: =E39 -> 2650.3945 | F17: =D17*E17 -> 0
B18: ='LabourProject Rates_Master'!$B$43 -> Crew #2 - InGround Water/Fire | C18: Day | E18: =E40 -> 2650.3945 | F18: =D18*E18 -> 0
E19: Total Labour | F19: =SUM(F14:F18) -> 0
C20: Total as per stage boq
E21: Total Part A Labour | F21: 0
E22: Total Stage 1 Labour | F22: 0
E23: Total Stage 2 Labour | F23: 0
E24: Total Stage 3 Labour | F24: 0
E25: Total Stage 4 Labour | F25: 0
F26: =SUM(F21:F25) -> 0
E27: Difference | F27: =F26-F19 -> 0
C29: Unit | D29: REQ | E29: Cost ex GST | F29: Total ex GST
B30: Labour
B33: Contingencies; Wet Weather ?
B35: Superviser; Return Trip, 2 day stay - Inclusive | C35: item | D35: 4 | E35: 2423.831 | F35: =D35*E35 -> 9695.324
B36: ='LabourProject Rates_Master'!$B$14 -> TRADESMAN_LEADING HAND | C36: Day | D36: 14 | E36: ='LabourProject Rates_Master'!$E$15 -> 1231.1429 | F36: =E36*D36 -> 17236
B37: ='LabourProject Rates_Master'!$B$23 -> TRADESMAN_PLUMBER_OPERATOR | C37: Day | D37: 14 | E37: ='LabourProject Rates_Master'!$E$22 -> 941.16473 | F37: =E37*D37 -> 13176.306
B38: ='LabourProject Rates_Master'!$B$30 -> T/A & Apprentice | C38: Day | D38: 7 | E38: ='LabourProject Rates_Master'!$E$29 -> 768.06508 | F38: =E38*D38 -> 5376.4556
B39: ='LabourProject Rates_Master'!$B$36 -> Crew #1 - InGround Drainage | C39: Day | D39: 5 | E39: ='LabourProject Rates_Master'!$E$37 -> 2650.3945 | F39: =E39*D39 -> 13251.973
B40: ='LabourProject Rates_Master'!$B$43 -> Crew #2 - InGround Water/Fire | C40: Day | D40: 0 | E40: ='LabourProject Rates_Master'!$E$44 -> 2650.3945 | F40: =E40*D40 -> 0
B42: Management Labour
B44: ='LabourProject Rates_Master'!$B$14 -> TRADESMAN_LEADING HAND | C44: Day | D44: 5 | E44: ='LabourProject Rates_Master'!$E$15 -> 1231.1429 | F44: =E44*D44 -> 6155.7143 | G44: Included within stages?
B45: MH / DQ | C45: Day | D45: =[1]Program_MASTER!$C$144 -> 44 | E45: 120 | F45: =E45*D45 -> 5280 | G45: Refer Program for approx attendance on site. Technically covered in overheads. E/O for meals etc?
B46: MH / DQ - FLIGHTS | C46: ea | D46: 20 | E46: 200 | F46: =E46*D46 -> 4000
B51: ACCOMODATION (Refer Program)
B52: Per Month - Full Project (6 Persons)
...

Sheet MISC & SITEWIDE
B1: Project:
B2: Tricore -
B3: Stage 1 Version 1
A4: Item
A9: 1 | B9: Complete -
B12: Labour
B14: DAY | J14: april 2026 direct impact Increase % (not contigency)
B15: ='LabourProject Rates_Master'!$B$14 -> TRADESMAN_LEADING HAND | C15: Day | E15: ='LabourProject Rates_Master'!$E$15 -> 1231.1429 | F15: =E15*D15 -> 0
B16: ='LabourProject Rates_Master'!$B$23 -> TRADESMAN_PLUMBER_OPERATOR | C16: Day | E16: ='LabourProject Rates_Master'!$E$22 -> 941.16473 | F16: =E16*D16 -> 0 | K16: PE Pipe & Fitting | L16: 0.38 | M16: 1.38
B17: ='LabourProject Rates_Master'!$B$30 -> T/A & Apprentice | C17: Day | E17: ='LabourProject Rates_Master'!$E$29 -> 768.06508 | F17: =E17*D17 -> 0 | K17: PVC Pipe & Fittings | L17: 0.38 | M17: 1.38
B18: ='LabourProject Rates_Master'!$B$36 -> Crew #1 - InGround Drainage | C18: Day | E18: ='LabourProject Rates_Master'!$E$37 -> 2650.3945 | F18: =E18*D18 -> 0 | K18: Subby Rates | L18: 0.15 | M18: 1.15
B19: ='LabourProject Rates_Master'!$B$43 -> Crew #2 - InGround Water/Fire | C19: Day | E19: ='LabourProject Rates_Master'!$E$44 -> 2650.3945 | F19: =E19*D19 -> 0 | K19: Delivey Rate | L19: 0.2 | M19: 1.2
B21: HOUR
B22: ='LabourProject Rates_Master'!$B$14 -> TRADESMAN_LEADING HAND | C22: HR | D22: 0 | E22: ='LabourProject Rates_Master'!$E$14 -> 123.11429 | F22: =E22*D22 -> 0
B23: ='LabourProject Rates_Master'!$B$23 -> TRADESMAN_PLUMBER_OPERATOR | C23: HR | D23: 0 | E23: ='LabourProject Rates_Master'!$E$21 -> 94.116473 | F23: =E23*D23 -> 0
B24: ='LabourProject Rates_Master'!$B$30 -> T/A & Apprentice | C24: HR | D24: 0 | E24: ='LabourProject Rates_Master'!$E$28 -> 76.806508 | F24: =E24*D24 -> 0
B25: ='LabourProject Rates_Master'!$B$36 -> Crew #1 - InGround Drainage | C25: HR | D25: 0 | E25: ='LabourProject Rates_Master'!$E$36 -> 265.03945 | F25: =E25*D25 -> 0
B26: ='LabourProject Rates_Master'!$B$43 -> Crew #2 - InGround Water/Fire | C26: HR | D26: 0 | E26: ='LabourProject Rates_Master'!$E$43 -> 265.03945 | F26: =E26*D26 -> 0
B29: Demolition & Reinstatement
B30: DEMO
B31: ='Misc Subbie Rates_Master'!A49 -> Asphalt Cutting | C31: m | E31: ='Misc Subbie Rates_Master'!D49+('Misc Subbie Rates_Master'!D49*$L$18) -> 15.525 | F31: =E31*D31 -> 0
B32: ='Misc Subbie Rates_Master'!A50 -> Concrete Cutting | C32: m | E32: ='Misc Subbie Rates_Master'!D50+('Misc Subbie Rates_Master'!D50*$L$18) -> 18.4 | F32: =E32*D32 -> 0
B33: Con Cut Establishemnt Fee | C33: ea | E33: ='Misc Subbie Rates_Master'!D51+('Misc Subbie Rates_Master'!D51*$L$18) -> 92 | F33: =E33*D33 -> 0
B34: REINSTATE - CONCRETE
B35: ='Misc Subbie Rates_Master'!A56 -> Road/Drveway Reinstate; 1mW x 150 Thck, N25/20/80, Incl Reinforcement | C35: m | E35: ='Misc Subbie Rates_Master'!D56 -> 145 | F35: =E35*D35 -> 0
B36: ='Misc Subbie Rates_Master'!A57 -> Kerb & Channel - 1m Wide | C36: ea | E36: ='Misc Subbie Rates_Master'!D57 -> 155 | F36: =E36*D36 -> 0
B37: ='Misc Subbie Rates_Master'!A58 -> Footpath - 1.5mW, N25/20/80, Incl Reinforcement | C37: lm | E37: ='Misc Subbie Rates_Master'!D58 -> 180 | F37: =E37*D37 -> 0
B38: ='Misc Subbie Rates_Master'!A59 -> Footpath - 1.5mW, EXPOSED AGG, N25/20/80, Incl Reinforcement | C38: lm | E38: ='Misc Subbie Rates_Master'!D59 -> 185 | F38: =E38*D38 -> 0
B39: REINSTATE - ASPHALT
B40: ='Misc Subbie Rates_Master'!A64 -> 50mm Thck - Trench Reinstatement Through Road/Driveway | C40: m2 | E40: ='Misc Subbie Rates_Master'!D64 -> 97 | F40: =E40*D40 -> 0
B41: ='Misc Subbie Rates_Master'!A65 -> 50mm Thck - 1.5-2m Wide Footpath reinstatements | C41: m2 | E41: ='Misc Subbie Rates_Master'!D65 -> 97 | F41: =E41*D41 -> 0
B42: ='Misc Subbie Rates_Master'!A66 -> Establishment Fee (1 per stage) | C42: Ea | E42: ='Misc Subbie Rates_Master'!D66 -> 5500 | F42: =E42*D42 -> 0
B44: Equipment & Hire - INCL WET PLANT HIRE
B46: PLANT HIRE - WET
B47: 1.8T Excavator | C47: Hr | E47: ='Misc Subbie Rates_Master'!D10 -> 100 | F47: =E47*D47 -> 0
B48: 3-5 ton Excavator | C48: Hr | E48: ='Misc Subbie Rates_Master'!D11 -> 115 | F48: =E48*D48 -> 0
B49: 3-5T Combo | C49: Hr | E49: ='Misc Subbie Rates_Master'!D12 -> 154 | F49: =E49*D49 -> 0
B50: Hammer attachment 3.5-4T | C50: Hr | E50: ='Misc Subbie Rates_Master'!D13 -> 21 | F50: =E50*D50 -> 0
B51: Ripper 3.5-4T | C51: Hr | E51: ='Misc Subbie Rates_Master'!D14 -> 10 | F51: =E51*D51 -> 0
B52: 5t Excavator | C52: Hr | E52: ='Misc Subbie Rates_Master'!D15 -> 150 | F52: =E52*D52 -> 0
...

Sheet ROK092
B1: Project:
B2: Tricore -
B3: Stage 1 Version 1
A4: Item
A9: 1 | B9: Complete -
B12: Labour
B14: DAY | J14: april 2026 direct impact Increase % (not contigency)
B15: ='LabourProject Rates_Master'!$B$14 -> TRADESMAN_LEADING HAND | C15: Day | E15: ='LabourProject Rates_Master'!$E$15 -> 1231.1429 | F15: =E15*D15 -> 0
B16: ='LabourProject Rates_Master'!$B$23 -> TRADESMAN_PLUMBER_OPERATOR | C16: Day | E16: ='LabourProject Rates_Master'!$E$22 -> 941.16473 | F16: =E16*D16 -> 0 | K16: PE Pipe & Fitting | L16: 0.38 | M16: 1.38
B17: ='LabourProject Rates_Master'!$B$30 -> T/A & Apprentice | C17: Day | E17: ='LabourProject Rates_Master'!$E$29 -> 768.06508 | F17: =E17*D17 -> 0 | K17: PVC Pipe & Fittings | L17: 0.38 | M17: 1.38
B18: ='LabourProject Rates_Master'!$B$36 -> Crew #1 - InGround Drainage | C18: Day | D18: 47 | E18: ='LabourProject Rates_Master'!$E$37 -> 2650.3945 | F18: =E18*D18 -> 124568.54 | K18: Subby Rates | L18: 0.15 | M18: 1.15
B19: ='LabourProject Rates_Master'!$B$43 -> Crew #2 - InGround Water/Fire | C19: Day | D19: 20 | E19: ='LabourProject Rates_Master'!$E$44 -> 2650.3945 | F19: =E19*D19 -> 53007.891 | K19: Delivey Rate | L19: 0.2 | M19: 1.2
B20: ='LabourProject Rates_Master'!B51 -> Crew #3 - Above Ground Drainage | C20: Day | D20: 17 | E20: ='LabourProject Rates_Master'!E52 -> 2650.3945 | F20: =E20*D20 -> 45056.707
B21: ='LabourProject Rates_Master'!B59 -> Crew #4 - Above Ground WATER/FIRE | C21: Day | D21: 49 | E21: ='LabourProject Rates_Master'!E60 -> 2650.3945 | F21: =E21*D21 -> 129869.33
B22: ='LabourProject Rates_Master'!B67 -> Crew #5 - Above Ground FitOff / Misc | C22: Day | D22: 15 | E22: ='LabourProject Rates_Master'!E68 -> 2650.3945 | F22: =E22*D22 -> 39755.918
B23: ='LabourProject Rates_Master'!B75 -> Crew #6 - DEMO | C23: Day | E23: ='LabourProject Rates_Master'!E76 -> 1709.2298 | F23: =E23*D23 -> 0
B27: HOUR
B28: ='LabourProject Rates_Master'!$B$14 -> TRADESMAN_LEADING HAND | C28: HR | D28: 0 | E28: ='LabourProject Rates_Master'!$E$14 -> 123.11429 | F28: =E28*D28 -> 0
B29: ='LabourProject Rates_Master'!$B$23 -> TRADESMAN_PLUMBER_OPERATOR | C29: HR | D29: 0 | E29: ='LabourProject Rates_Master'!$E$21 -> 94.116473 | F29: =E29*D29 -> 0
B30: ='LabourProject Rates_Master'!$B$30 -> T/A & Apprentice | C30: HR | D30: 0 | E30: ='LabourProject Rates_Master'!$E$28 -> 76.806508 | F30: =E30*D30 -> 0
B31: ='LabourProject Rates_Master'!$B$36 -> Crew #1 - InGround Drainage | C31: HR | D31: 0 | E31: ='LabourProject Rates_Master'!$E$36 -> 265.03945 | F31: =E31*D31 -> 0
B32: ='LabourProject Rates_Master'!$B$43 -> Crew #2 - InGround Water/Fire | C32: HR | D32: 0 | E32: ='LabourProject Rates_Master'!$E$43 -> 265.03945 | F32: =E32*D32 -> 0
B35: Demolition & Reinstatement
B36: DEMO
B37: ='Misc Subbie Rates_Master'!A49 -> Asphalt Cutting | C37: m | E37: ='Misc Subbie Rates_Master'!D49+('Misc Subbie Rates_Master'!D49*$L$18) -> 15.525 | F37: =E37*D37 -> 0
B38: ='Misc Subbie Rates_Master'!A50 -> Concrete Cutting | C38: m | E38: ='Misc Subbie Rates_Master'!D50+('Misc Subbie Rates_Master'!D50*$L$18) -> 18.4 | F38: =E38*D38 -> 0
B39: Con Cut Establishemnt Fee | C39: ea | E39: ='Misc Subbie Rates_Master'!D51+('Misc Subbie Rates_Master'!D51*$L$18) -> 92 | F39: =E39*D39 -> 0
B40: REINSTATE - CONCRETE
B41: ='Misc Subbie Rates_Master'!A56 -> Road/Drveway Reinstate; 1mW x 150 Thck, N25/20/80, Incl Reinforcement | C41: m | E41: ='Misc Subbie Rates_Master'!D56 -> 145 | F41: =E41*D41 -> 0
B42: ='Misc Subbie Rates_Master'!A57 -> Kerb & Channel - 1m Wide | C42: ea | E42: ='Misc Subbie Rates_Master'!D57 -> 155 | F42: =E42*D42 -> 0
B43: ='Misc Subbie Rates_Master'!A58 -> Footpath - 1.5mW, N25/20/80, Incl Reinforcement | C43: lm | E43: ='Misc Subbie Rates_Master'!D58 -> 180 | F43: =E43*D43 -> 0
B44: ='Misc Subbie Rates_Master'!A59 -> Footpath - 1.5mW, EXPOSED AGG, N25/20/80, Incl Reinforcement | C44: lm | E44: ='Misc Subbie Rates_Master'!D59 -> 185 | F44: =E44*D44 -> 0
B45: REINSTATE - ASPHALT
B46: ='Misc Subbie Rates_Master'!A64 -> 50mm Thck - Trench Reinstatement Through Road/Driveway | C46: m2 | E46: ='Misc Subbie Rates_Master'!D64 -> 97 | F46: =E46*D46 -> 0
B47: ='Misc Subbie Rates_Master'!A65 -> 50mm Thck - 1.5-2m Wide Footpath reinstatements | C47: m2 | E47: ='Misc Subbie Rates_Master'!D65 -> 97 | F47: =E47*D47 -> 0
B48: ='Misc Subbie Rates_Master'!A66 -> Establishment Fee (1 per stage) | C48: Ea | E48: ='Misc Subbie Rates_Master'!D66 -> 5500 | F48: =E48*D48 -> 0
B50: Equipment & Hire - INCL WET PLANT HIRE
A52: HIDDEN | B52: PLANT HIRE - WET
B53: 1.8T Excavator | C53: Hr | E53: ='Misc Subbie Rates_Master'!D10 -> 100 | F53: =E53*D53 -> 0
B54: 3-5 ton Excavator | C54: Hr | E54: ='Misc Subbie Rates_Master'!D11 -> 115 | F54: =E54*D54 -> 0
...

Sheet ROK21A
B1: Project:
B2: Tricore -
B3: Stage 1 Version 1
A4: Item
A9: 1 | B9: Complete -
B12: Labour
B14: DAY | J14: april 2026 direct impact Increase % (not contigency)
B15: ='LabourProject Rates_Master'!$B$14 -> TRADESMAN_LEADING HAND | C15: Day | E15: ='LabourProject Rates_Master'!$E$15 -> 1231.1429 | F15: =E15*D15 -> 0
B16: ='LabourProject Rates_Master'!$B$23 -> TRADESMAN_PLUMBER_OPERATOR | C16: Day | E16: ='LabourProject Rates_Master'!$E$22 -> 941.16473 | F16: =E16*D16 -> 0 | K16: PE Pipe & Fitting | L16: 0.38 | M16: 1.38
B17: ='LabourProject Rates_Master'!$B$30 -> T/A & Apprentice | C17: Day | E17: ='LabourProject Rates_Master'!$E$29 -> 768.06508 | F17: =E17*D17 -> 0 | K17: PVC Pipe & Fittings | L17: 0.38 | M17: 1.38
B18: ='LabourProject Rates_Master'!$B$36 -> Crew #1 - InGround Drainage | C18: Day | D18: 3 | E18: ='LabourProject Rates_Master'!$E$37 -> 2650.3945 | F18: =E18*D18 -> 7951.1836 | K18: Subby Rates | L18: 0.15 | M18: 1.15
B19: ='LabourProject Rates_Master'!$B$43 -> Crew #2 - InGround Water/Fire | C19: Day | D19: 3 | E19: ='LabourProject Rates_Master'!$E$44 -> 2650.3945 | F19: =E19*D19 -> 7951.1836 | K19: Delivey Rate | L19: 0.2 | M19: 1.2
B20: ='LabourProject Rates_Master'!B51 -> Crew #3 - Above Ground Drainage | C20: Day | D20: 2 | E20: ='LabourProject Rates_Master'!E52 -> 2650.3945 | F20: =E20*D20 -> 5300.7891
B21: ='LabourProject Rates_Master'!B59 -> Crew #4 - Above Ground WATER/FIRE | C21: Day | D21: 2 | E21: ='LabourProject Rates_Master'!E60 -> 2650.3945 | F21: =E21*D21 -> 5300.7891
B22: ='LabourProject Rates_Master'!B67 -> Crew #5 - Above Ground FitOff / Misc | C22: Day | D22: 2 | E22: ='LabourProject Rates_Master'!E68 -> 2650.3945 | F22: =E22*D22 -> 5300.7891
B23: ='LabourProject Rates_Master'!B75 -> Crew #6 - DEMO | C23: Day | D23: 2 | E23: ='LabourProject Rates_Master'!E76 -> 1709.2298 | F23: =E23*D23 -> 3418.4596
B25: HOUR
B26: ='LabourProject Rates_Master'!$B$14 -> TRADESMAN_LEADING HAND | C26: HR | D26: 0 | E26: ='LabourProject Rates_Master'!$E$14 -> 123.11429 | F26: =E26*D26 -> 0
B27: ='LabourProject Rates_Master'!$B$23 -> TRADESMAN_PLUMBER_OPERATOR | C27: HR | D27: 0 | E27: ='LabourProject Rates_Master'!$E$21 -> 94.116473 | F27: =E27*D27 -> 0
B28: ='LabourProject Rates_Master'!$B$30 -> T/A & Apprentice | C28: HR | D28: 0 | E28: ='LabourProject Rates_Master'!$E$28 -> 76.806508 | F28: =E28*D28 -> 0
B29: ='LabourProject Rates_Master'!$B$36 -> Crew #1 - InGround Drainage | C29: HR | D29: 0 | E29: ='LabourProject Rates_Master'!$E$36 -> 265.03945 | F29: =E29*D29 -> 0
B30: ='LabourProject Rates_Master'!$B$43 -> Crew #2 - InGround Water/Fire | C30: HR | D30: 0 | E30: ='LabourProject Rates_Master'!$E$43 -> 265.03945 | F30: =E30*D30 -> 0
B33: Demolition & Reinstatement
B34: DEMO
B35: ='Misc Subbie Rates_Master'!A49 -> Asphalt Cutting | C35: m | E35: ='Misc Subbie Rates_Master'!D49+('Misc Subbie Rates_Master'!D49*$L$18) -> 15.525 | F35: =E35*D35 -> 0
B36: ='Misc Subbie Rates_Master'!A50 -> Concrete Cutting | C36: m | E36: ='Misc Subbie Rates_Master'!D50+('Misc Subbie Rates_Master'!D50*$L$18) -> 18.4 | F36: =E36*D36 -> 0
B37: Con Cut Establishemnt Fee | C37: ea | E37: ='Misc Subbie Rates_Master'!D51+('Misc Subbie Rates_Master'!D51*$L$18) -> 92 | F37: =E37*D37 -> 0
B38: REINSTATE - CONCRETE
B39: ='Misc Subbie Rates_Master'!A56 -> Road/Drveway Reinstate; 1mW x 150 Thck, N25/20/80, Incl Reinforcement | C39: m | E39: ='Misc Subbie Rates_Master'!D56 -> 145 | F39: =E39*D39 -> 0
B40: ='Misc Subbie Rates_Master'!A57 -> Kerb & Channel - 1m Wide | C40: ea | E40: ='Misc Subbie Rates_Master'!D57 -> 155 | F40: =E40*D40 -> 0
B41: ='Misc Subbie Rates_Master'!A58 -> Footpath - 1.5mW, N25/20/80, Incl Reinforcement | C41: lm | E41: ='Misc Subbie Rates_Master'!D58 -> 180 | F41: =E41*D41 -> 0
B42: ='Misc Subbie Rates_Master'!A59 -> Footpath - 1.5mW, EXPOSED AGG, N25/20/80, Incl Reinforcement | C42: lm | E42: ='Misc Subbie Rates_Master'!D59 -> 185 | F42: =E42*D42 -> 0
B43: REINSTATE - ASPHALT
B44: ='Misc Subbie Rates_Master'!A64 -> 50mm Thck - Trench Reinstatement Through Road/Driveway | C44: m2 | E44: ='Misc Subbie Rates_Master'!D64 -> 97 | F44: =E44*D44 -> 0
B45: ='Misc Subbie Rates_Master'!A65 -> 50mm Thck - 1.5-2m Wide Footpath reinstatements | C45: m2 | E45: ='Misc Subbie Rates_Master'!D65 -> 97 | F45: =E45*D45 -> 0
B46: ='Misc Subbie Rates_Master'!A66 -> Establishment Fee (1 per stage) | C46: Ea | E46: ='Misc Subbie Rates_Master'!D66 -> 5500 | F46: =E46*D46 -> 0
B48: Equipment & Hire - INCL WET PLANT HIRE
B50: PLANT HIRE - WET
B51: 1.8T Excavator | C51: Hr | E51: ='Misc Subbie Rates_Master'!D10 -> 100 | F51: =E51*D51 -> 0
B52: 3-5 ton Excavator | C52: Hr | E52: ='Misc Subbie Rates_Master'!D11 -> 115 | F52: =E52*D52 -> 0
...

Sheet ROK019
B1: Project:
B2: Tricore -
B3: Stage 1 Version 1
A4: Item
A9: 1 | B9: Complete -
B12: Labour
B14: DAY | J14: april 2026 direct impact Increase % (not contigency)
B15: ='LabourProject Rates_Master'!$B$14 -> TRADESMAN_LEADING HAND | C15: Day | E15: ='LabourProject Rates_Master'!$E$15 -> 1231.1429 | F15: =E15*D15 -> 0
B16: ='LabourProject Rates_Master'!$B$23 -> TRADESMAN_PLUMBER_OPERATOR | C16: Day | E16: ='LabourProject Rates_Master'!$E$22 -> 941.16473 | F16: =E16*D16 -> 0 | K16: PE Pipe & Fitting | L16: 0.38 | M16: 1.38
B17: ='LabourProject Rates_Master'!$B$30 -> T/A & Apprentice | C17: Day | E17: ='LabourProject Rates_Master'!$E$29 -> 768.06508 | F17: =E17*D17 -> 0 | K17: PVC Pipe & Fittings | L17: 0.38 | M17: 1.38
B18: ='LabourProject Rates_Master'!$B$36 -> Crew #1 - InGround Drainage | C18: Day | E18: ='LabourProject Rates_Master'!$E$37 -> 2650.3945 | F18: =E18*D18 -> 0 | K18: Subby Rates | L18: 0.15 | M18: 1.15
B19: ='LabourProject Rates_Master'!$B$43 -> Crew #2 - InGround Water/Fire | C19: Day | E19: ='LabourProject Rates_Master'!$E$44 -> 2650.3945 | F19: =E19*D19 -> 0 | K19: Delivey Rate | L19: 0.2 | M19: 1.2
B20: ='LabourProject Rates_Master'!B51 -> Crew #3 - Above Ground Drainage | C20: Day | D20: 9 | E20: ='LabourProject Rates_Master'!E52 -> 2650.3945 | F20: =E20*D20 -> 23853.551
B21: ='LabourProject Rates_Master'!B59 -> Crew #4 - Above Ground WATER/FIRE | C21: Day | D21: 13 | E21: ='LabourProject Rates_Master'!E60 -> 2650.3945 | F21: =E21*D21 -> 34455.129
B22: ='LabourProject Rates_Master'!B67 -> Crew #5 - Above Ground FitOff / Misc | C22: Day | D22: 8 | E22: ='LabourProject Rates_Master'!E68 -> 2650.3945 | F22: =E22*D22 -> 21203.156
B23: ='LabourProject Rates_Master'!B75 -> Crew #6 - DEMO | C23: Day | D23: 9 | E23: ='LabourProject Rates_Master'!E76 -> 1709.2298 | F23: =E23*D23 -> 15383.068
B25: HOUR
B26: ='LabourProject Rates_Master'!$B$14 -> TRADESMAN_LEADING HAND | C26: HR | D26: 0 | E26: ='LabourProject Rates_Master'!$E$14 -> 123.11429 | F26: =E26*D26 -> 0
B27: ='LabourProject Rates_Master'!$B$23 -> TRADESMAN_PLUMBER_OPERATOR | C27: HR | D27: 0 | E27: ='LabourProject Rates_Master'!$E$21 -> 94.116473 | F27: =E27*D27 -> 0
B28: ='LabourProject Rates_Master'!$B$30 -> T/A & Apprentice | C28: HR | D28: 0 | E28: ='LabourProject Rates_Master'!$E$28 -> 76.806508 | F28: =E28*D28 -> 0
B29: ='LabourProject Rates_Master'!$B$36 -> Crew #1 - InGround Drainage | C29: HR | D29: 0 | E29: ='LabourProject Rates_Master'!$E$36 -> 265.03945 | F29: =E29*D29 -> 0
B30: ='LabourProject Rates_Master'!$B$43 -> Crew #2 - InGround Water/Fire | C30: HR | D30: 0 | E30: ='LabourProject Rates_Master'!$E$43 -> 265.03945 | F30: =E30*D30 -> 0
B33: Demolition & Reinstatement
B34: DEMO
B35: ='Misc Subbie Rates_Master'!A49 -> Asphalt Cutting | C35: m | E35: ='Misc Subbie Rates_Master'!D49+('Misc Subbie Rates_Master'!D49*$L$18) -> 15.525 | F35: =E35*D35 -> 0
B36: ='Misc Subbie Rates_Master'!A50 -> Concrete Cutting | C36: m | E36: ='Misc Subbie Rates_Master'!D50+('Misc Subbie Rates_Master'!D50*$L$18) -> 18.4 | F36: =E36*D36 -> 0
B37: Con Cut Establishemnt Fee | C37: ea | E37: ='Misc Subbie Rates_Master'!D51+('Misc Subbie Rates_Master'!D51*$L$18) -> 92 | F37: =E37*D37 -> 0
B38: REINSTATE - CONCRETE
B39: ='Misc Subbie Rates_Master'!A56 -> Road/Drveway Reinstate; 1mW x 150 Thck, N25/20/80, Incl Reinforcement | C39: m | E39: ='Misc Subbie Rates_Master'!D56 -> 145 | F39: =E39*D39 -> 0
B40: ='Misc Subbie Rates_Master'!A57 -> Kerb & Channel - 1m Wide | C40: ea | E40: ='Misc Subbie Rates_Master'!D57 -> 155 | F40: =E40*D40 -> 0
B41: ='Misc Subbie Rates_Master'!A58 -> Footpath - 1.5mW, N25/20/80, Incl Reinforcement | C41: lm | E41: ='Misc Subbie Rates_Master'!D58 -> 180 | F41: =E41*D41 -> 0
B42: ='Misc Subbie Rates_Master'!A59 -> Footpath - 1.5mW, EXPOSED AGG, N25/20/80, Incl Reinforcement | C42: lm | E42: ='Misc Subbie Rates_Master'!D59 -> 185 | F42: =E42*D42 -> 0
B43: REINSTATE - ASPHALT
B44: ='Misc Subbie Rates_Master'!A64 -> 50mm Thck - Trench Reinstatement Through Road/Driveway | C44: m2 | E44: ='Misc Subbie Rates_Master'!D64 -> 97 | F44: =E44*D44 -> 0
B45: ='Misc Subbie Rates_Master'!A65 -> 50mm Thck - 1.5-2m Wide Footpath reinstatements | C45: m2 | E45: ='Misc Subbie Rates_Master'!D65 -> 97 | F45: =E45*D45 -> 0
B46: ='Misc Subbie Rates_Master'!A66 -> Establishment Fee (1 per stage) | C46: Ea | E46: ='Misc Subbie Rates_Master'!D66 -> 5500 | F46: =E46*D46 -> 0
B48: Equipment & Hire - INCL WET PLANT HIRE
B50: PLANT HIRE - WET
B51: 1.8T Excavator | C51: Hr | E51: ='Misc Subbie Rates_Master'!D10 -> 100 | F51: =E51*D51 -> 0
B52: 3-5 ton Excavator | C52: Hr | E52: ='Misc Subbie Rates_Master'!D11 -> 115 | F52: =E52*D52 -> 0
...

Sheet ROK033
B1: Project:
B2: Tricore -
B3: Stage 1 Version 1
A4: Item
A9: 1 | B9: Complete -
B12: Labour
B14: DAY | J14: april 2026 direct impact Increase % (not contigency)
B15: ='LabourProject Rates_Master'!$B$14 -> TRADESMAN_LEADING HAND | C15: Day | E15: ='LabourProject Rates_Master'!$E$15 -> 1231.1429 | F15: =E15*D15 -> 0
B16: ='LabourProject Rates_Master'!$B$23 -> TRADESMAN_PLUMBER_OPERATOR | C16: Day | E16: ='LabourProject Rates_Master'!$E$22 -> 941.16473 | F16: =E16*D16 -> 0 | K16: PE Pipe & Fitting | L16: 0.38 | M16: 1.38
B17: ='LabourProject Rates_Master'!$B$30 -> T/A & Apprentice | C17: Day | E17: ='LabourProject Rates_Master'!$E$29 -> 768.06508 | F17: =E17*D17 -> 0 | K17: PVC Pipe & Fittings | L17: 0.38 | M17: 1.38
B18: ='LabourProject Rates_Master'!$B$36 -> Crew #1 - InGround Drainage | C18: Day | E18: ='LabourProject Rates_Master'!$E$37 -> 2650.3945 | F18: =E18*D18 -> 0 | K18: Subby Rates | L18: 0.15 | M18: 1.15
B19: ='LabourProject Rates_Master'!$B$43 -> Crew #2 - InGround Water/Fire | C19: Day | D19: 8 | E19: ='LabourProject Rates_Master'!$E$44 -> 2650.3945 | F19: =E19*D19 -> 21203.156 | K19: Delivey Rate | L19: 0.2 | M19: 1.2
B20: ='LabourProject Rates_Master'!B51 -> Crew #3 - Above Ground Drainage | C20: Day | D20: 0 | E20: ='LabourProject Rates_Master'!E52 -> 2650.3945 | F20: =E20*D20 -> 0
B21: ='LabourProject Rates_Master'!B59 -> Crew #4 - Above Ground WATER/FIRE | C21: Day | D21: 30 | E21: ='LabourProject Rates_Master'!E60 -> 2650.3945 | F21: =E21*D21 -> 79511.836
B22: ='LabourProject Rates_Master'!B67 -> Crew #5 - Above Ground FitOff / Misc | C22: Day | D22: 21 | E22: ='LabourProject Rates_Master'!E68 -> 2650.3945 | F22: =E22*D22 -> 55658.285
B23: ='LabourProject Rates_Master'!B75 -> Crew #6 - DEMO | C23: Day | D23: 16 | E23: ='LabourProject Rates_Master'!E76 -> 1709.2298 | F23: =E23*D23 -> 27347.677
B25: HOUR
B26: ='LabourProject Rates_Master'!$B$14 -> TRADESMAN_LEADING HAND | C26: HR | D26: 0 | E26: ='LabourProject Rates_Master'!$E$14 -> 123.11429 | F26: =E26*D26 -> 0
B27: ='LabourProject Rates_Master'!$B$23 -> TRADESMAN_PLUMBER_OPERATOR | C27: HR | D27: 0 | E27: ='LabourProject Rates_Master'!$E$21 -> 94.116473 | F27: =E27*D27 -> 0
B28: ='LabourProject Rates_Master'!$B$30 -> T/A & Apprentice | C28: HR | D28: 0 | E28: ='LabourProject Rates_Master'!$E$28 -> 76.806508 | F28: =E28*D28 -> 0
B29: ='LabourProject Rates_Master'!$B$36 -> Crew #1 - InGround Drainage | C29: HR | D29: 0 | E29: ='LabourProject Rates_Master'!$E$36 -> 265.03945 | F29: =E29*D29 -> 0
B30: ='LabourProject Rates_Master'!$B$43 -> Crew #2 - InGround Water/Fire | C30: HR | D30: 0 | E30: ='LabourProject Rates_Master'!$E$43 -> 265.03945 | F30: =E30*D30 -> 0
B33: Demolition & Reinstatement
B34: DEMO
B35: ='Misc Subbie Rates_Master'!A49 -> Asphalt Cutting | C35: m | E35: ='Misc Subbie Rates_Master'!D49+('Misc Subbie Rates_Master'!D49*$L$18) -> 15.525 | F35: =E35*D35 -> 0
B36: ='Misc Subbie Rates_Master'!A50 -> Concrete Cutting | C36: m | E36: ='Misc Subbie Rates_Master'!D50+('Misc Subbie Rates_Master'!D50*$L$18) -> 18.4 | F36: =E36*D36 -> 0
B37: Con Cut Establishemnt Fee | C37: ea | E37: ='Misc Subbie Rates_Master'!D51+('Misc Subbie Rates_Master'!D51*$L$18) -> 92 | F37: =E37*D37 -> 0
B38: REINSTATE - CONCRETE
B39: ='Misc Subbie Rates_Master'!A56 -> Road/Drveway Reinstate; 1mW x 150 Thck, N25/20/80, Incl Reinforcement | C39: m | E39: ='Misc Subbie Rates_Master'!D56 -> 145 | F39: =E39*D39 -> 0
B40: ='Misc Subbie Rates_Master'!A57 -> Kerb & Channel - 1m Wide | C40: ea | E40: ='Misc Subbie Rates_Master'!D57 -> 155 | F40: =E40*D40 -> 0
B41: ='Misc Subbie Rates_Master'!A58 -> Footpath - 1.5mW, N25/20/80, Incl Reinforcement | C41: lm | E41: ='Misc Subbie Rates_Master'!D58 -> 180 | F41: =E41*D41 -> 0
B42: ='Misc Subbie Rates_Master'!A59 -> Footpath - 1.5mW, EXPOSED AGG, N25/20/80, Incl Reinforcement | C42: lm | E42: ='Misc Subbie Rates_Master'!D59 -> 185 | F42: =E42*D42 -> 0
B43: REINSTATE - ASPHALT
B44: ='Misc Subbie Rates_Master'!A64 -> 50mm Thck - Trench Reinstatement Through Road/Driveway | C44: m2 | E44: ='Misc Subbie Rates_Master'!D64 -> 97 | F44: =E44*D44 -> 0
B45: ='Misc Subbie Rates_Master'!A65 -> 50mm Thck - 1.5-2m Wide Footpath reinstatements | C45: m2 | E45: ='Misc Subbie Rates_Master'!D65 -> 97 | F45: =E45*D45 -> 0
B46: ='Misc Subbie Rates_Master'!A66 -> Establishment Fee (1 per stage) | C46: Ea | E46: ='Misc Subbie Rates_Master'!D66 -> 5500 | F46: =E46*D46 -> 0
B48: Equipment & Hire - INCL WET PLANT HIRE
B50: PLANT HIRE - WET
B51: 1.8T Excavator | C51: Hr | E51: ='Misc Subbie Rates_Master'!D10 -> 100 | F51: =E51*D51 -> 0
B52: 3-5 ton Excavator | C52: Hr | E52: ='Misc Subbie Rates_Master'!D11 -> 115 | F52: =E52*D52 -> 0
...

Sheet ROK034
B1: Project:
B2: Tricore -
B3: Stage 1 Version 1
A4: Item
A9: 1 | B9: Complete -
B12: Labour
B14: DAY | J14: april 2026 direct impact Increase % (not contigency)
B15: ='LabourProject Rates_Master'!$B$14 -> TRADESMAN_LEADING HAND | C15: Day | E15: ='LabourProject Rates_Master'!$E$15 -> 1231.1429 | F15: =E15*D15 -> 0
B16: ='LabourProject Rates_Master'!$B$23 -> TRADESMAN_PLUMBER_OPERATOR | C16: Day | E16: ='LabourProject Rates_Master'!$E$22 -> 941.16473 | F16: =E16*D16 -> 0 | K16: PE Pipe & Fitting | L16: 0.38 | M16: 1.38
B17: ='LabourProject Rates_Master'!$B$30 -> T/A & Apprentice | C17: Day | E17: ='LabourProject Rates_Master'!$E$29 -> 768.06508 | F17: =E17*D17 -> 0 | K17: PVC Pipe & Fittings | L17: 0.38 | M17: 1.38
B18: ='LabourProject Rates_Master'!$B$36 -> Crew #1 - InGround Drainage | C18: Day | E18: ='LabourProject Rates_Master'!$E$37 -> 2650.3945 | F18: =E18*D18 -> 0 | K18: Subby Rates | L18: 0.15 | M18: 1.15
B19: ='LabourProject Rates_Master'!$B$43 -> Crew #2 - InGround Water/Fire | C19: Day | D19: 2 | E19: ='LabourProject Rates_Master'!$E$44 -> 2650.3945 | F19: =E19*D19 -> 5300.7891 | K19: Delivey Rate | L19: 0.2 | M19: 1.2
B20: ='LabourProject Rates_Master'!B51 -> Crew #3 - Above Ground Drainage | C20: Day | D20: 2 | E20: ='LabourProject Rates_Master'!E52 -> 2650.3945 | F20: =E20*D20 -> 5300.7891
B21: ='LabourProject Rates_Master'!B59 -> Crew #4 - Above Ground WATER/FIRE | C21: Day | D21: 4 | E21: ='LabourProject Rates_Master'!E60 -> 2650.3945 | F21: =E21*D21 -> 10601.578
B22: ='LabourProject Rates_Master'!B67 -> Crew #5 - Above Ground FitOff / Misc | C22: Day | D22: 5 | E22: ='LabourProject Rates_Master'!E68 -> 2650.3945 | F22: =E22*D22 -> 13251.973
B23: ='LabourProject Rates_Master'!B75 -> Crew #6 - DEMO | C23: Day | E23: ='LabourProject Rates_Master'!E76 -> 1709.2298 | F23: =E23*D23 -> 0
B25: HOUR
B26: ='LabourProject Rates_Master'!$B$14 -> TRADESMAN_LEADING HAND | C26: HR | D26: 0 | E26: ='LabourProject Rates_Master'!$E$14 -> 123.11429 | F26: =E26*D26 -> 0
B27: ='LabourProject Rates_Master'!$B$23 -> TRADESMAN_PLUMBER_OPERATOR | C27: HR | D27: 0 | E27: ='LabourProject Rates_Master'!$E$21 -> 94.116473 | F27: =E27*D27 -> 0
B28: ='LabourProject Rates_Master'!$B$30 -> T/A & Apprentice | C28: HR | D28: 0 | E28: ='LabourProject Rates_Master'!$E$28 -> 76.806508 | F28: =E28*D28 -> 0
B29: ='LabourProject Rates_Master'!$B$36 -> Crew #1 - InGround Drainage | C29: HR | D29: 0 | E29: ='LabourProject Rates_Master'!$E$36 -> 265.03945 | F29: =E29*D29 -> 0
B30: ='LabourProject Rates_Master'!$B$43 -> Crew #2 - InGround Water/Fire | C30: HR | D30: 0 | E30: ='LabourProject Rates_Master'!$E$43 -> 265.03945 | F30: =E30*D30 -> 0
B33: Demolition & Reinstatement
B34: DEMO
B35: ='Misc Subbie Rates_Master'!A49 -> Asphalt Cutting | C35: m | E35: ='Misc Subbie Rates_Master'!D49+('Misc Subbie Rates_Master'!D49*$L$18) -> 15.525 | F35: =E35*D35 -> 0
B36: ='Misc Subbie Rates_Master'!A50 -> Concrete Cutting | C36: m | E36: ='Misc Subbie Rates_Master'!D50+('Misc Subbie Rates_Master'!D50*$L$18) -> 18.4 | F36: =E36*D36 -> 0
B37: Con Cut Establishemnt Fee | C37: ea | E37: ='Misc Subbie Rates_Master'!D51+('Misc Subbie Rates_Master'!D51*$L$18) -> 92 | F37: =E37*D37 -> 0
B38: REINSTATE - CONCRETE
B39: ='Misc Subbie Rates_Master'!A56 -> Road/Drveway Reinstate; 1mW x 150 Thck, N25/20/80, Incl Reinforcement | C39: m | E39: ='Misc Subbie Rates_Master'!D56 -> 145 | F39: =E39*D39 -> 0
B40: ='Misc Subbie Rates_Master'!A57 -> Kerb & Channel - 1m Wide | C40: ea | E40: ='Misc Subbie Rates_Master'!D57 -> 155 | F40: =E40*D40 -> 0
B41: ='Misc Subbie Rates_Master'!A58 -> Footpath - 1.5mW, N25/20/80, Incl Reinforcement | C41: lm | E41: ='Misc Subbie Rates_Master'!D58 -> 180 | F41: =E41*D41 -> 0
B42: ='Misc Subbie Rates_Master'!A59 -> Footpath - 1.5mW, EXPOSED AGG, N25/20/80, Incl Reinforcement | C42: lm | E42: ='Misc Subbie Rates_Master'!D59 -> 185 | F42: =E42*D42 -> 0
B43: REINSTATE - ASPHALT
B44: ='Misc Subbie Rates_Master'!A64 -> 50mm Thck - Trench Reinstatement Through Road/Driveway | C44: m2 | E44: ='Misc Subbie Rates_Master'!D64 -> 97 | F44: =E44*D44 -> 0
B45: ='Misc Subbie Rates_Master'!A65 -> 50mm Thck - 1.5-2m Wide Footpath reinstatements | C45: m2 | E45: ='Misc Subbie Rates_Master'!D65 -> 97 | F45: =E45*D45 -> 0
B46: ='Misc Subbie Rates_Master'!A66 -> Establishment Fee (1 per stage) | C46: Ea | E46: ='Misc Subbie Rates_Master'!D66 -> 5500 | F46: =E46*D46 -> 0
B48: Equipment & Hire - INCL WET PLANT HIRE
B50: PLANT HIRE - WET
B51: 1.8T Excavator | C51: Hr | E51: ='Misc Subbie Rates_Master'!D10 -> 100 | F51: =E51*D51 -> 0
B52: 3-5 ton Excavator | C52: Hr | E52: ='Misc Subbie Rates_Master'!D11 -> 115 | F52: =E52*D52 -> 0
...

Sheet ROK036
B1: Project:
B2: Tricore -
B3: Stage 1 Version 1
A4: Item
A9: 1 | B9: Complete -
B12: Labour
B14: DAY | J14: april 2026 direct impact Increase % (not contigency)
B15: ='LabourProject Rates_Master'!$B$14 -> TRADESMAN_LEADING HAND | C15: Day | E15: ='LabourProject Rates_Master'!$E$15 -> 1231.1429 | F15: =E15*D15 -> 0
B16: ='LabourProject Rates_Master'!$B$23 -> TRADESMAN_PLUMBER_OPERATOR | C16: Day | E16: ='LabourProject Rates_Master'!$E$22 -> 941.16473 | F16: =E16*D16 -> 0 | K16: PE Pipe & Fitting | L16: 0.38 | M16: 1.38
B17: ='LabourProject Rates_Master'!$B$30 -> T/A & Apprentice | C17: Day | E17: ='LabourProject Rates_Master'!$E$29 -> 768.06508 | F17: =E17*D17 -> 0 | K17: PVC Pipe & Fittings | L17: 0.38 | M17: 1.38
B18: ='LabourProject Rates_Master'!$B$36 -> Crew #1 - InGround Drainage | C18: Day | D18: 30 | E18: ='LabourProject Rates_Master'!$E$37 -> 2650.3945 | F18: =E18*D18 -> 79511.836 | K18: Subby Rates | L18: 0.15 | M18: 1.15
B19: ='LabourProject Rates_Master'!$B$43 -> Crew #2 - InGround Water/Fire | C19: Day | D19: 6 | E19: ='LabourProject Rates_Master'!$E$44 -> 2650.3945 | F19: =E19*D19 -> 15902.367 | K19: Delivey Rate | L19: 0.2 | M19: 1.2
B20: ='LabourProject Rates_Master'!B51 -> Crew #3 - Above Ground Drainage | C20: Day | D20: 31 | E20: ='LabourProject Rates_Master'!E52 -> 2650.3945 | F20: =E20*D20 -> 82162.231
B21: ='LabourProject Rates_Master'!B59 -> Crew #4 - Above Ground WATER/FIRE | C21: Day | D21: 63 | E21: ='LabourProject Rates_Master'!E60 -> 2650.3945 | F21: =E21*D21 -> 166974.86
B22: ='LabourProject Rates_Master'!B67 -> Crew #5 - Above Ground FitOff / Misc | C22: Day | D22: 50 | E22: ='LabourProject Rates_Master'!E68 -> 2650.3945 | F22: =E22*D22 -> 132519.73
B23: ='LabourProject Rates_Master'!B75 -> Crew #6 - DEMO | C23: Day | D23: 13 | E23: ='LabourProject Rates_Master'!E76 -> 1709.2298 | F23: =E23*D23 -> 22219.988
B25: HOUR
B26: ='LabourProject Rates_Master'!$B$14 -> TRADESMAN_LEADING HAND | C26: HR | D26: 0 | E26: ='LabourProject Rates_Master'!$E$14 -> 123.11429 | F26: =E26*D26 -> 0
B27: ='LabourProject Rates_Master'!$B$23 -> TRADESMAN_PLUMBER_OPERATOR | C27: HR | D27: 0 | E27: ='LabourProject Rates_Master'!$E$21 -> 94.116473 | F27: =E27*D27 -> 0
B28: ='LabourProject Rates_Master'!$B$30 -> T/A & Apprentice | C28: HR | D28: 0 | E28: ='LabourProject Rates_Master'!$E$28 -> 76.806508 | F28: =E28*D28 -> 0
B29: ='LabourProject Rates_Master'!$B$36 -> Crew #1 - InGround Drainage | C29: HR | D29: 0 | E29: ='LabourProject Rates_Master'!$E$36 -> 265.03945 | F29: =E29*D29 -> 0
B30: ='LabourProject Rates_Master'!$B$43 -> Crew #2 - InGround Water/Fire | C30: HR | D30: 0 | E30: ='LabourProject Rates_Master'!$E$43 -> 265.03945 | F30: =E30*D30 -> 0
B33: Demolition & Reinstatement
B34: DEMO
B35: ='Misc Subbie Rates_Master'!A49 -> Asphalt Cutting | C35: m | E35: ='Misc Subbie Rates_Master'!D49+('Misc Subbie Rates_Master'!D49*$L$18) -> 15.525 | F35: =E35*D35 -> 0
B36: ='Misc Subbie Rates_Master'!A50 -> Concrete Cutting | C36: m | E36: ='Misc Subbie Rates_Master'!D50+('Misc Subbie Rates_Master'!D50*$L$18) -> 18.4 | F36: =E36*D36 -> 0
B37: Con Cut Establishemnt Fee | C37: ea | E37: ='Misc Subbie Rates_Master'!D51+('Misc Subbie Rates_Master'!D51*$L$18) -> 92 | F37: =E37*D37 -> 0
B38: REINSTATE - CONCRETE
B39: ='Misc Subbie Rates_Master'!A56 -> Road/Drveway Reinstate; 1mW x 150 Thck, N25/20/80, Incl Reinforcement | C39: m | E39: ='Misc Subbie Rates_Master'!D56 -> 145 | F39: =E39*D39 -> 0
B40: ='Misc Subbie Rates_Master'!A57 -> Kerb & Channel - 1m Wide | C40: ea | E40: ='Misc Subbie Rates_Master'!D57 -> 155 | F40: =E40*D40 -> 0
B41: ='Misc Subbie Rates_Master'!A58 -> Footpath - 1.5mW, N25/20/80, Incl Reinforcement | C41: lm | E41: ='Misc Subbie Rates_Master'!D58 -> 180 | F41: =E41*D41 -> 0
B42: ='Misc Subbie Rates_Master'!A59 -> Footpath - 1.5mW, EXPOSED AGG, N25/20/80, Incl Reinforcement | C42: lm | E42: ='Misc Subbie Rates_Master'!D59 -> 185 | F42: =E42*D42 -> 0
B43: REINSTATE - ASPHALT
B44: ='Misc Subbie Rates_Master'!A64 -> 50mm Thck - Trench Reinstatement Through Road/Driveway | C44: m2 | E44: ='Misc Subbie Rates_Master'!D64 -> 97 | F44: =E44*D44 -> 0
B45: ='Misc Subbie Rates_Master'!A65 -> 50mm Thck - 1.5-2m Wide Footpath reinstatements | C45: m2 | E45: ='Misc Subbie Rates_Master'!D65 -> 97 | F45: =E45*D45 -> 0
B46: ='Misc Subbie Rates_Master'!A66 -> Establishment Fee (1 per stage) | C46: Ea | E46: ='Misc Subbie Rates_Master'!D66 -> 5500 | F46: =E46*D46 -> 0
B48: Equipment & Hire - INCL WET PLANT HIRE
B50: PLANT HIRE - WET
B51: 1.8T Excavator | C51: Hr | E51: ='Misc Subbie Rates_Master'!D10 -> 100 | F51: =E51*D51 -> 0
B52: 3-5 ton Excavator | C52: Hr | E52: ='Misc Subbie Rates_Master'!D11 -> 115 | F52: =E52*D52 -> 0
...

Sheet ROK076
B1: Project:
B2: Tricore -
B3: Stage 1 Version 1
A4: Item
A9: 1 | B9: Complete -
B12: Labour
B14: DAY | J14: april 2026 direct impact Increase % (not contigency)
B15: ='LabourProject Rates_Master'!$B$14 -> TRADESMAN_LEADING HAND | C15: Day | E15: ='LabourProject Rates_Master'!$E$15 -> 1231.1429 | F15: =E15*D15 -> 0
B16: ='LabourProject Rates_Master'!$B$23 -> TRADESMAN_PLUMBER_OPERATOR | C16: Day | E16: ='LabourProject Rates_Master'!$E$22 -> 941.16473 | F16: =E16*D16 -> 0 | K16: PE Pipe & Fitting | L16: 0.38 | M16: 1.38
B17: ='LabourProject Rates_Master'!$B$30 -> T/A & Apprentice | C17: Day | E17: ='LabourProject Rates_Master'!$E$29 -> 768.06508 | F17: =E17*D17 -> 0 | K17: PVC Pipe & Fittings | L17: 0.38 | M17: 1.38
B18: ='LabourProject Rates_Master'!$B$36 -> Crew #1 - InGround Drainage | C18: Day | D18: 7 | E18: ='LabourProject Rates_Master'!$E$37 -> 2650.3945 | F18: =E18*D18 -> 18552.762 | K18: Subby Rates | L18: 0.15 | M18: 1.15
B19: ='LabourProject Rates_Master'!$B$43 -> Crew #2 - InGround Water/Fire | C19: Day | D19: 4 | E19: ='LabourProject Rates_Master'!$E$44 -> 2650.3945 | F19: =E19*D19 -> 10601.578 | K19: Delivey Rate | L19: 0.2 | M19: 1.2
B20: ='LabourProject Rates_Master'!B51 -> Crew #3 - Above Ground Drainage | C20: Day | D20: 3 | E20: ='LabourProject Rates_Master'!E52 -> 2650.3945 | F20: =E20*D20 -> 7951.1836
B21: ='LabourProject Rates_Master'!B59 -> Crew #4 - Above Ground WATER/FIRE | C21: Day | D21: 14 | E21: ='LabourProject Rates_Master'!E60 -> 2650.3945 | F21: =E21*D21 -> 37105.524
B22: ='LabourProject Rates_Master'!B67 -> Crew #5 - Above Ground FitOff / Misc | C22: Day | D22: 4 | E22: ='LabourProject Rates_Master'!E68 -> 2650.3945 | F22: =E22*D22 -> 10601.578
B23: ='LabourProject Rates_Master'!B75 -> Crew #6 - DEMO | C23: Day | D23: 2 | E23: ='LabourProject Rates_Master'!E76 -> 1709.2298 | F23: =E23*D23 -> 3418.4596
B25: HOUR
B26: ='LabourProject Rates_Master'!$B$14 -> TRADESMAN_LEADING HAND | C26: HR | D26: 0 | E26: ='LabourProject Rates_Master'!$E$14 -> 123.11429 | F26: =E26*D26 -> 0
B27: ='LabourProject Rates_Master'!$B$23 -> TRADESMAN_PLUMBER_OPERATOR | C27: HR | D27: 0 | E27: ='LabourProject Rates_Master'!$E$21 -> 94.116473 | F27: =E27*D27 -> 0
B28: ='LabourProject Rates_Master'!$B$30 -> T/A & Apprentice | C28: HR | D28: 0 | E28: ='LabourProject Rates_Master'!$E$28 -> 76.806508 | F28: =E28*D28 -> 0
B29: ='LabourProject Rates_Master'!$B$36 -> Crew #1 - InGround Drainage | C29: HR | D29: 0 | E29: ='LabourProject Rates_Master'!$E$36 -> 265.03945 | F29: =E29*D29 -> 0
B30: ='LabourProject Rates_Master'!$B$43 -> Crew #2 - InGround Water/Fire | C30: HR | D30: 0 | E30: ='LabourProject Rates_Master'!$E$43 -> 265.03945 | F30: =E30*D30 -> 0
B33: Demolition & Reinstatement
B34: DEMO
B35: ='Misc Subbie Rates_Master'!A49 -> Asphalt Cutting | C35: m | E35: ='Misc Subbie Rates_Master'!D49+('Misc Subbie Rates_Master'!D49*$L$18) -> 15.525 | F35: =E35*D35 -> 0
B36: ='Misc Subbie Rates_Master'!A50 -> Concrete Cutting | C36: m | E36: ='Misc Subbie Rates_Master'!D50+('Misc Subbie Rates_Master'!D50*$L$18) -> 18.4 | F36: =E36*D36 -> 0
B37: Con Cut Establishemnt Fee | C37: ea | E37: ='Misc Subbie Rates_Master'!D51+('Misc Subbie Rates_Master'!D51*$L$18) -> 92 | F37: =E37*D37 -> 0
B38: REINSTATE - CONCRETE
B39: ='Misc Subbie Rates_Master'!A56 -> Road/Drveway Reinstate; 1mW x 150 Thck, N25/20/80, Incl Reinforcement | C39: m | E39: ='Misc Subbie Rates_Master'!D56 -> 145 | F39: =E39*D39 -> 0
B40: ='Misc Subbie Rates_Master'!A57 -> Kerb & Channel - 1m Wide | C40: ea | E40: ='Misc Subbie Rates_Master'!D57 -> 155 | F40: =E40*D40 -> 0
B41: ='Misc Subbie Rates_Master'!A58 -> Footpath - 1.5mW, N25/20/80, Incl Reinforcement | C41: lm | E41: ='Misc Subbie Rates_Master'!D58 -> 180 | F41: =E41*D41 -> 0
B42: ='Misc Subbie Rates_Master'!A59 -> Footpath - 1.5mW, EXPOSED AGG, N25/20/80, Incl Reinforcement | C42: lm | E42: ='Misc Subbie Rates_Master'!D59 -> 185 | F42: =E42*D42 -> 0
B43: REINSTATE - ASPHALT
B44: ='Misc Subbie Rates_Master'!A64 -> 50mm Thck - Trench Reinstatement Through Road/Driveway | C44: m2 | E44: ='Misc Subbie Rates_Master'!D64 -> 97 | F44: =E44*D44 -> 0
B45: ='Misc Subbie Rates_Master'!A65 -> 50mm Thck - 1.5-2m Wide Footpath reinstatements | C45: m2 | E45: ='Misc Subbie Rates_Master'!D65 -> 97 | F45: =E45*D45 -> 0
B46: ='Misc Subbie Rates_Master'!A66 -> Establishment Fee (1 per stage) | C46: Ea | E46: ='Misc Subbie Rates_Master'!D66 -> 5500 | F46: =E46*D46 -> 0
B48: Equipment & Hire - INCL WET PLANT HIRE
B50: PLANT HIRE - WET
B51: 1.8T Excavator | C51: Hr | E51: ='Misc Subbie Rates_Master'!D10 -> 100 | F51: =E51*D51 -> 0
B52: 3-5 ton Excavator | C52: Hr | E52: ='Misc Subbie Rates_Master'!D11 -> 115 | F52: =E52*D52 -> 0
...

Sheet LabourProject Rates_Master
B1: Project:
B2: Tricore -
B3: Stage 1 Version 1
A4: Item
B6: BASED ON:
B7: ='[2]Staff Costs_Lead Hand'!$B$193 -> Work ROSTER Example #3 - 6-Day Week, 10Hr Days, Stay @ Rocky for W/E, Return Every 2nd W/E. (FLY)
B8: ='[2]Staff Costs_Lead Hand'!$E$212 -> Working Days/Month | C8: ='[2]Staff Costs_Lead Hand'!$F$212 -> 21
B9: ='[2]Staff Costs_Lead Hand'!$E$213 -> No-Work Days/Month | C9: ='[2]Staff Costs_Lead Hand'!$F$213 -> 7
B10: ='[2]Staff Costs_Lead Hand'!$E$214 -> Avrg Hours / Month | C10: ='[2]Staff Costs_Lead Hand'!$F$214 -> 210
B12: STAFF
C13: Unit | D13: REQ | E13: Cost ex GST | F13: Total ex GST
B14: ='[2]Staff Costs_Lead Hand'!$B$4 -> TRADESMAN_LEADING HAND | C14: HR | D14: 1 | E14: =E17/$C$10 -> 123.11429 | F14: =D14*E14 -> 123.11429
B15: ** for Roster Examples # 3 | C15: DAY | D15: 1 | E15: =E17/$C$8 -> 1231.1429 | F15: =D15*E15 -> 1231.1429
B16: =B14 -> TRADESMAN_LEADING HAND | C16: WEEK | D16: 1 | E16: =E17/4 -> 6463.5 | F16: =D16*E16 -> 6463.5
C17: MONTH | D17: 1 | E17: ='[2]Staff Costs_Lead Hand'!$F$211 -> 25854 | F17: =D17*E17 -> 25854
B19: QTY Staff in Crew | C19: =COUNTA(B16,B17,B18) -> 1
B21: ='[2]Staff Costs_Tradesman'!$B$4 -> TRADESMAN_PLUMBER_OPERATOR | C21: HR | D21: 1 | E21: =E24/$C$10 -> 94.116473 | F21: =D21*E21 -> 94.116473
B22: ** for Roster Examples # 3 | C22: DAY | D22: 1 | E22: =E24/$C$8 -> 941.16473 | F22: =D22*E22 -> 941.16473
B23: =B21 -> TRADESMAN_PLUMBER_OPERATOR | C23: WEEK | D23: 1 | E23: =E24/4 -> 4941.1148 | F23: =D23*E23 -> 4941.1148
C24: MONTH | D24: 1 | E24: ='[2]Staff Costs_Tradesman'!$F$121 -> 19764.459 | F24: =D24*E24 -> 19764.459
B26: QTY Staff in Crew | C26: =COUNTA(B23,B24,B25) -> 1
B28: ='[2]Staff Costs_TA'!$B$4 -> T/A & Apprentice | C28: HR | D28: 1 | E28: =E31/$C$10 -> 76.806508 | F28: =D28*E28 -> 76.806508
B29: ** for Roster Examples # 3 | C29: DAY | D29: 1 | E29: =E31/$C$8 -> 768.06508 | F29: =D29*E29 -> 768.06508
B30: =B28 -> T/A & Apprentice | C30: WEEK | D30: 1 | E30: =E31/4 -> 4032.3417 | F30: =D30*E30 -> 4032.3417
C31: MONTH | D31: 1 | E31: ='[2]Staff Costs_TA'!$F$122 -> 16129.367 | F31: =D31*E31 -> 16129.367
B33: QTY Staff in Crew | C33: =COUNTA(B30,B31,B32) -> 1
B36: Crew #1 - InGround Drainage | C36: HR | D36: 1 | E36: =E39/$C$10 -> 265.03945 | F36: =D36*E36 -> 265.03945
B37: ** for Roster Examples # 3 | C37: DAY | D37: 1 | E37: =E39/$C$8 -> 2650.3945 | F37: =D37*E37 -> 2650.3945
B38: =B21 -> TRADESMAN_PLUMBER_OPERATOR | C38: WEEK | D38: 1 | E38: =E39/4 -> 13914.571 | F38: =D38*E38 -> 13914.571
B39: =B21 -> TRADESMAN_PLUMBER_OPERATOR | C39: MONTH | D39: 1 | E39: =(E24*2)+E31 -> 55658.285 | F39: =D39*E39 -> 55658.285
B40: =B28 -> T/A & Apprentice
B41: QTY Staff in Crew | C41: =COUNTA(B38,B39,B40) -> 3
B43: Crew #2 - InGround Water/Fire | C43: HR | D43: 1 | E43: =E46/$C$10 -> 265.03945 | F43: =D43*E43 -> 265.03945
B44: ** for Roster Examples # 3 | C44: DAY | D44: 1 | E44: =E46/$C$8 -> 2650.3945 | F44: =D44*E44 -> 2650.3945
B45: =B21 -> TRADESMAN_PLUMBER_OPERATOR | C45: WEEK | D45: 1 | E45: =E46/4 -> 13914.571 | F45: =D45*E45 -> 13914.571
B46: =B21 -> TRADESMAN_PLUMBER_OPERATOR | C46: MONTH | D46: 1 | E46: =(E24*2)+E31 -> 55658.285 | F46: =D46*E46 -> 55658.285
B47: =B28 -> T/A & Apprentice
B48: QTY Staff in Crew | C48: =COUNTA(B45,B46,B47) -> 3
B51: Crew #3 - Above Ground Drainage | C51: HR | D51: 1 | E51: =E43 -> 265.03945 | F51: =D51*E51 -> 265.03945
B52: =B44 -> ** for Roster Examples # 3 | C52: DAY | D52: 1 | E52: =E44 -> 2650.3945 | F52: =D52*E52 -> 2650.3945
...

Sheet Material Rates_Master
A3: FIRE SERVICES - IN GROUND
A4: Description | B4: Unit | D4: Rate | F4: Total | I4: Qty
A5: 200 HDPE PN16 SDR11 - REDLINE | B5: m | D5: ='[3]240522_Supplier RFQ'!F16 -> 33.920833 | F5: =I5*D5 -> 16282 | G5: COMPLETED don’t edit | I5: 480
A6: 180 HDPE PN16 SDR11 - REDLINE | B6: m | D6: ='[3]240522_Supplier RFQ'!F17 -> 25.466667 | F6: =I6*D6 -> 128657.6 | I6: 5052
A7: 125 HDPE PN16 SDR11 - REDLINE | B7: m | D7: ='[3]240522_Supplier RFQ'!F18 -> 12.314167 | F7: =I7*D7 -> 13151.53 | I7: 1068
A8: 32 HDPE PN16 SDR11 - BLUELINE | B8: m | D8: ='[3]240522_Supplier RFQ'!F19 -> 1.2159 | F8: =I8*D8 -> 121.59 | I8: 100
A10: 200 EF Coupler | B10: ea | D10: ='[3]240522_Supplier RFQ'!F21 -> 44.06 | F10: =I10*D10 -> 1321.8 | G10: COMPLETED don’t edit | I10: 30
A11: 180 EF Coupler | B11: ea | D11: ='[3]240522_Supplier RFQ'!F22 -> 25.72 | F11: =I11*D11 -> 5144 | I11: 200
A12: 125 EF Coupler | B12: ea | D12: ='[3]240522_Supplier RFQ'!F23 -> 14.11 | F12: =I12*D12 -> 1411 | I12: 100
A13: 200 EF 45DFeg Bend | B13: ea | D13: ='[3]240522_Supplier RFQ'!F24 -> 109.16 | F13: =I13*D13 -> 218.32 | I13: 2
A14: 180 EF 45DFeg Bend | B14: ea | D14: ='[3]240522_Supplier RFQ'!F25 -> 97.97 | F14: =I14*D14 -> 12736.1 | I14: 130
A15: 125 EF 45DFeg Bend | B15: ea | D15: ='[3]240522_Supplier RFQ'!F26 -> 44.69 | F15: =I15*D15 -> 1117.25 | G15: COMPLETED don’t edit | I15: 25
A16: 200 EF 90DFeg Bend | B16: ea | D16: ='[3]240522_Supplier RFQ'!F27 -> 109.16 | F16: =I16*D16 -> 654.96 | I16: 6
A17: 180 EF 90DFeg Bend | B17: ea | D17: ='[3]240522_Supplier RFQ'!F28 -> 97.81 | F17: =I17*D17 -> 7824.8 | I17: 80
A18: 125 EF 90DFeg Bend | B18: ea | D18: ='[3]240522_Supplier RFQ'!F29 -> 44.65 | F18: =I18*D18 -> 3572 | I18: 80
A19: 200 EF TEE | B19: ea | D19: ='[3]240522_Supplier RFQ'!F30 -> 109.75 | F19: =I19*D19 -> 329.25 | I19: 3
A20: 180 EF TEE | B20: ea | D20: ='[3]240522_Supplier RFQ'!F31 -> 114.28 | F20: =I20*D20 -> 4571.2 | G20: COMPLETED don’t edit | I20: 40
A21: 125 EF TEE | B21: ea | D21: ='[3]240522_Supplier RFQ'!F32 -> 49.25 | F21: =I21*D21 -> 49.25 | I21: 1
A22: 200*180 EF TEE | B22: ea | D22: ='[3]240522_Supplier RFQ'!F33 -> 209.47 | F22: =I22*D22 -> 418.94 | I22: 2
A23: 200*125 EF TEE | B23: ea | D23: ='[3]240522_Supplier RFQ'!F34 -> 218.42 | F23: =I23*D23 -> 436.84 | I23: 2
A24: 180*125 EF TEE | B24: ea | D24: ='[3]240522_Supplier RFQ'!F35 -> 122.13 | F24: =I24*D24 -> 4885.2 | I24: 40
A25: 200*180 EF Reducer | B25: ea | D25: ='[3]240522_Supplier RFQ'!F36 -> 125.62 | F25: =I25*D25 -> 502.48 | G25: COMPLETED don’t edit | I25: 4
A26: 180*125 EF Reducer | B26: ea | D26: ='[3]240522_Supplier RFQ'!F37 -> 60.1 | F26: =I26*D26 -> 1202 | I26: 20
A27: 200PE*8"(200m) - MaxiStub W/Backing Ring | B27: ea | D27: ='[3]240522_Supplier RFQ'!F38 -> 342.35 | F27: =I27*D27 -> 3423.5 | I27: 10
A28: 180PE*6"(150mm) - MaxiStub W/Backing Ring | B28: ea | D28: ='[3]240522_Supplier RFQ'!F39 -> 129.77 | F28: =I28*D28 -> 7786.2 | I28: 60
A29: 125PE*4" (100mm) - MaxiStub W/Backing Ring | B29: ea | D29: ='[3]240522_Supplier RFQ'!F40 -> 92.67 | F29: =I29*D29 -> 1853.4 | I29: 20
A30: 180mm PE x 150mm GALV ADAPTER - PLASSON Brand | B30: ea | D30: ='[3]240522_Supplier RFQ'!$L$41 -> 313.19 | F30: =I30*D30 -> 3131.9 | G30: COMPLETED don’t edit | I30: 10
A31: 125mm PE x 100mm GALV ADAPTER - PLASSON Brand | B31: ea | D31: ='[3]240522_Supplier RFQ'!$L$42 -> 204.11 | F31: =I31*D31 -> 10205.5 | I31: 50
A33: 180mm PE x 150mm GALV ADAPTER | B33: ea | D33: ='[3]240522_Supplier RFQ'!F44 -> 315.71 | F33: =I33*D33 -> 3157.1 | I33: 10
A34: 125mm PE x 100mm GALV ADAPTER | B34: ea | D34: ='[3]240522_Supplier RFQ'!F45 -> 201.43 | F34: =I34*D34 -> 10071.5 | I34: 50
A35: 200 Long SPIG 45DFeg Bend | B35: ea | D35: ='[3]240522_Supplier RFQ'!F46 -> 68.54 | F35: =I35*D35 -> 137.08 | G35: COMPLETED don’t edit | I35: 2
A36: 180 Long SPIG 45DFeg Bend | B36: ea | D36: ='[3]240522_Supplier RFQ'!F47 -> 64.46 | F36: =I36*D36 -> 8379.8 | I36: 130
A37: 125 Long SPIG 45DFeg Bend | B37: ea | D37: ='[3]240522_Supplier RFQ'!F48 -> 38.76 | F37: =I37*D37 -> 969 | I37: 25
A38: 200 Long SPIG 90DFeg Bend | B38: ea | D38: ='[3]240522_Supplier RFQ'!F49 -> 86.17 | F38: =I38*D38 -> 517.02 | I38: 6
A39: 180 Long SPIG 90DFeg Bend | B39: ea | D39: ='[3]240522_Supplier RFQ'!F50 -> 68.11 | F39: =I39*D39 -> 5448.8 | I39: 80
A40: 125 Long SPIG 90DFeg Bend | B40: ea | D40: ='[3]240522_Supplier RFQ'!F51 -> 31.65 | F40: =I40*D40 -> 2532 | G40: COMPLETED don’t edit | I40: 80
A41: 200 Long SPIG TEE | B41: ea | D41: ='[3]240522_Supplier RFQ'!F52 -> 127.64 | F41: =I41*D41 -> 382.92 | I41: 3
A42: 180 Long SPIG TEE | B42: ea | D42: ='[3]240522_Supplier RFQ'!F53 -> 114.22 | F42: =I42*D42 -> 4568.8 | I42: 40
A43: 125 Long SPIG TEE | B43: ea | D43: ='[3]240522_Supplier RFQ'!F54 -> 38.26 | F43: =I43*D43 -> 38.26 | I43: 1
A44: 200*180 Long SPIG TEE | B44: ea | D44: ='[3]240522_Supplier RFQ'!F55 -> 183.48 | F44: =I44*D44 -> 366.96 | I44: 2
...

Sheet Equip&HIRE_Master
B2: TCS PROJECT USE | F2: COMPLETED don’t edit
A3: DESCRIPTION | B3: Unit | C3: Qty | D3: WEEKLY (5 day)
A4: Skid Steer Loader_Tracked (CAT249+) | B4: Day | D4: ='[4]Hire Items_Dry'!$M$16 -> 225.43333
A5: Skid Steer Loader_Wheeled (CAT226+) | B5: Day | D5: ='[4]Hire Items_Dry'!$M$17 -> 163.96667
A6: Mini Loader, Stand-on Type | B6: Day | D6: ='[4]Hire Items_Dry'!$J$18 -> 180
F7: COMPLETED don’t edit
A8: 1.5-1.8 Ton_Excavator | B8: Day | D8: ='[4]Hire Items_Dry'!$P$20 -> 137.14286
A9: 1.7-2Ton_Excavator | B9: Day
A10: 3-5Ton_Excavator | B10: Day | D10: ='[4]Hire Items_Dry'!$M$22 -> 238.66667
A11: 8Ton_Excavator | B11: Day | D11: ='[4]Hire Items_Dry'!$M$23 -> 261.16667
A12: 10-12Ton_Excavator | B12: Day | F12: COMPLETED don’t edit
A13: 13-16Ton_Excavator | B13: Day | D13: ='[4]Hire Items_Dry'!$M$25 -> 317.2
A14: 20-24Ton_Excavator | B14: Day | D14: ='[4]Hire Items_Dry'!$P$26 -> 314.28571
A16: Ripper_1.7-2T | B16: Day
A17: Ripper_1.5-4T | B17: Day | D17: ='[4]Hire Items_Dry'!$G$29 -> 32.74 | F17: COMPLETED don’t edit
A18: Ripper_3-5T | B18: Day
A19: Ripper_8T | B19: Day | D19: ='[4]Hire Items_Dry'!G31 -> 40.38
A20: Breaker_1.7-2T | B20: Day | D20: ='[4]Hire Items_Dry'!G32 -> 123.33
A21: Breaker_3-5T | B21: Day | D21: ='[4]Hire Items_Dry'!G33 -> 165.89
A22: Breaker_8T | B22: Day | D22: ='[4]Hire Items_Dry'!G34 -> 165.89 | F22: COMPLETED don’t edit
A23: Breaker_10-12T | B23: Day
A24: Breaker_13-15T | B24: Day | D24: ='[4]Hire Items_Dry'!G36 -> 203
A25: Auger Drive_10-12T
A26: 300Dia Auger Drill
F27: COMPLETED don’t edit
A28: 1.25T_Tipper Truck | B28: Day | D28: ='[4]Hire Items_Dry'!$J$40 -> 205
A29: 2-4T_Tipper Truck | B29: Day | D29: ='[4]Hire Items_Dry'!$G$41 -> 166.98
A30: <6T_Tipper Truck | B30: Day | D30: ='[4]Hire Items_Dry'!$P$42 -> 171.42857
A32: <10T_Articulated Site Tipper | B32: Day | F32: COMPLETED don’t edit
A33: Upright Rammer_Wacker | B33: Day | D33: ='[4]Hire Items_Dry'!$P$45 -> 34.285714
A34: Trench Roller_Dbl Drum_Remote | B34: Day | D34: ='[4]Hire Items_Dry'!$J$46 -> 165
A35: <26Ft_Scissor Lift - Diesel | B35: Day
A36: <26Ft_Scissor Lift - Elec | B36: Day
A37: <34Ft_Boom Lift - Diesel | B37: Day | F37: COMPLETED don’t edit
A38: <34Ft_Boom Lift - Elec | B38: Day
A40: Porta Loo_No Tank | B40: Day | D40: ='[4]Hire Items_Dry'!$G$52 -> 5.46
A41: 6*3m Demantable Lunchroom - COMPLETE | B41: Day | D41: ='[4]Hire Items_Dry'!$J$53 -> 23
A42: 6*3m Demantable Office - COMPLETE | B42: Day | D42: ='[4]Hire Items_Dry'!$J$54 -> 23 | F42: COMPLETED don’t edit
A43: 20Ft Shipping Container | B43: Day
A44: Quick Cut Demo Saw | B44: Day
...

Sheet Misc Subbie Rates_Master
A4: DENIS - Cells highlighted GREEN are complete (By Me).
A8: PLANT HIRE - WET | D8: TCS PROJECT USE | G8: COMPLETED don’t edit
A9: DESCRIPTION | B9: Unit | D9: Hr Rate | E9: Total
A10: 1.8T Excavator | B10: Hr | D10: ='[4]Plant Hire_WET'!R16 -> 100
A11: 3-5 ton Excavator | B11: Hr | D11: ='[4]Plant Hire_WET'!R17 -> 115
A12: 3-5T Combo | B12: Hr | D12: ='[4]Plant Hire_WET'!F18 -> 154
A13: Hammer attachment 3.5-4T | B13: Hr | D13: ='[4]Plant Hire_WET'!F19 -> 21 | G13: COMPLETED don’t edit
A14: Ripper 3.5-4T | B14: Hr | D14: ='[4]Plant Hire_WET'!F20 -> 10
A15: 5t Excavator | B15: Hr | D15: ='[4]Plant Hire_WET'!O21 -> 150
A16: Hammer attachment 5T | B16: Hr | D16: ='[4]Plant Hire_WET'!O22 -> 50
A17: Skid steer | B17: Hr | D17: ='[4]Plant Hire_WET'!O23 -> 140
A18: 8T Excavator | B18: Hr | D18: ='[4]Plant Hire_WET'!F24 -> 128 | G18: COMPLETED don’t edit
A19: Hammer attachment 8T | B19: Hr | D19: ='[4]Plant Hire_WET'!F25 -> 26
A20: Ripper 8T | B20: Hr | D20: ='[4]Plant Hire_WET'!F26 -> 10
A21: 13-15T Excavator | B21: Hr | D21: ='[4]Plant Hire_WET'!F27 -> 153
A22: Hammer attachment 14T | B22: Hr | D22: ='[4]Plant Hire_WET'!F28 -> 36
A23: Ripper 14T | B23: Hr | D23: ='[4]Plant Hire_WET'!F29 -> 10 | G23: COMPLETED don’t edit
A24: 3000L Hydro Excavation Truck | B24: Hr | D24: ='[4]Plant Hire_WET'!L30 -> 190
A25: 4500L Hydro Excavation Truck | B25: Hr | D25: ='[4]Plant Hire_WET'!L31 -> 220
A26: 6300L Hydro Excavation Truck | B26: Hr | D26: ='[4]Plant Hire_WET'!L32 -> 250
A27: Water Truck allow for water at cost | B27: Hr | D27: ='[4]Plant Hire_WET'!$R$33 -> 110
