Workbook

Sheet T04-GROUNDWORKS
A1: BUILDING 92
A2: GROUNDWORKS
A3: Code | B3: Description | C3: Quantity | D3: Unit | E3: Rate | F3: Total
B4: WORK MEASURED IN OTHER SECTIONS
A5: T04.1 | B5: Stormwater drainage included in T32 HYDRAULICS | D5: Note
B6: PRELIMINARIES
A7: T04.2 | B7: Site establishment & demobilisation | C7: 1 | D7: item | E7: 51750 | F7: =C7*E7 -> 51750
A8: T04.3 | B8: Survey set-out | C8: 1 | D8: item | E8: 9200 | F8: =C8*E8 -> 9200
A9: T04.4 | B9: As constructed survey | C9: 1 | D9: item | E9: 8050 | F9: =C9*E9 -> 8050
B10: EROSION AND SEDIMENT CONTROL
A11: T04.5 | B11: Allow for erosion and sediment control | C11: 1 | D11: item | E11: 13800 | F11: =C11*E11 -> 13800
B12: EXCAVATION
B13: Siteworks
A14: T04.6 | B14: Clear the site of all vegetable matter, debris, rubbish etc.; including trees <= 500 girth complete with stumps and roots | C14: 8009 | D14: m2 | E14: 5.4625 | F14: =C14*E14 -> 43749.163
A15: T04.7 | B15: Excavate to remove top soil average 200 mm deep | C15: 8009 | D15: m2 | E15: 22.425 | F15: =C15*E15 -> 179601.83
B16: Bulk Excavation
B17: Refer to Addendum 11 for further details
A18: T04.8 | B18: Bulk earthwork; commencing at reduced level; bulk cut | C18: 518 | D18: m3 | E18: 43.7 | F18: =C18*E18 -> 22636.6
A19: T04.9 | B19: Allow for imported fill placed in layers not exceeding 200 mm thick | C19: 2735 | D19: m3 | E19: 105.8 | F19: =C19*E19 -> 289363
A20: T04.10 | B20: Allow to proof roll sub-grade at pad level | C20: 8009 | D20: m2 | E20: 4.025 | F20: =C20*E20 -> 32236.225
A21: T04.11 | B21: Allow to trim, grade open excavated sub-grade | C21: 8009 | D21: m2 | E21: 4.8875 | F21: =C21*E21 -> 39143.988
B22: FILLING AND HARDCORE
A23: T04.12 | B23: 100 mm Thick Type 2.3 (CBR45%) material to building area :[4,291 m2] | C23: 430 | D23: m3 | E23: 135.7 | F23: =C23*E23 -> 58351
B24: Total | F24: =SUM(F7:F23) -> 747881.8
A26: EXTERIOR ELEMENTS
A27: Code | B27: Description | C27: Quantity | D27: Unit | E27: Rate | F27: Total
B28: ROADS, FOOTPATHS AND PAVED AREAS
B29: External Pavements
A30: T37.1 | B30: Concrete Crossover - 175 mm Thick concrete crossover with SL92 reinforcing fabric and necessary formwork as per Rockhampton Regional Council STD drawing CMDG-R-42 | C30: 324 | D30: m2 | E30: 189.75 | F30: =C30*E30 -> 61479
A31: T37.2 | B31: Pavement Type 1 - 125 mm Deep pedestrian grade insitu coloured concrete CCS Prairie with light acid wash finish [PA1] | C31: 118 | D31: m2 | E31: 155.25 | F31: =C31*E31 -> 18319.5
A32: T37.3 | B32: Pavement Type 2 - 125 mm Deep pedestrian grade insitu coloured concrete CCS Paperbark with light acid wash finish [PA2] | C32: 56 | D32: m2 | E32: 155.25 | F32: =C32*E32 -> 8694
A33: T37.4 | B33: Pavement Type 3 - 125 mm Deep pedestrian grade insitu concrete with light acid wash finish [PA3] | C33: 564 | D33: m2 | E33: 155.25 | F33: =C33*E33 -> 87561
A34: T37.5 | B34: Tie into existing pavement | C34: 20 | D34: m | E34: 109.25 | F34: =C34*E34 -> 2185
A35: T37.6 | B35: Allow for joints | C35: 1060 | D35: m2 | E35: 9.775 | F35: =C35*E35 -> 10361.5
B36: 125 mm Deep pedestrian grade insitu coloured concrete footpath to match Landscape [PA1, PA2] | C36: 89 | D36: m2 | E36: 155.25 | F36: =C36*E36 -> 13817.25
B37: External Road Pavements
A38: T37.7 | B38: D&C concrete slab including finish, falls and drainage | C38: 487 | D38: m2 | E38: 212.75 | F38: =C38*E38 -> 103609.25
A39: T37.8 | B39: Proposed Pavement Type 2 - Compacted subgrade, varying depth imported CBR 10%, 125 mm thick Type 2.3 (CBR 45%) subbase, 125 mm thick Type 2.1 (CBR 80%) base and 50 mm thick AC14 dense graded asphalt wearing course | C39: 665 | D39: m2 | E39: 212.75 | F39: =C39*E39 -> 141478.75
A40: T37.9 | B40: Proposed Pavement Type 3 - Compacted subgrade, 120 mm thick Type 2.3 (CBR 45%) subbase and 180 mm thick 32MPa concrete slab with SL82 mesh top cover including necessary formwork | C40: 254 | D40: m2 | E40: 218.5 | F40: =C40*E40 -> 55499
A41: T37.10 | B41: Tie in to existing pavement as per Granular Pavement Joint Detail on Civil drawing C140 | C41: 16 | D41: m | E41: 138 | F41: =C41*E41 -> 2208
...

Sheet Tender Summary
A1: CQU Rockhampton TAFE Consolidation - Stage 2
A2: Civil Construction and Earthworks Tender Pricing
A4: Date | B4: Thursday 30 April, 2026
A5: Quote # | B5: TBC
A6: Prepared For | B6: Estimator
A7: Project | B7: CQU Rockhampton TAFE Consolidation - Stage 2
A8: Tender Basis | B8: Lump Sum construct-only civil pricing - subject to clarifications herein
A9: Validity | B9: 30 days from proposal date
A11: Work Area / Section | B11: Amount ex GST | C11: Reference
A12: ROK092 Groundworks | B12: ='T04-GROUNDWORKS'!F24 -> 747881.8 | C12: T04.2 to T04.12
A13: ROK092 Exterior Elements | B13: =SUM('T04-GROUNDWORKS'!F30:F49) -> 610068.68 | C13: T37.1 to T37.14
A14: ROK021A Groundworks | B14: ='T04-GROUNDWORKS'!F66 -> 10068.538 | C14: T04.2 to T04.7
A15: ROK021A Exterior Elements | B15: ='T04-GROUNDWORKS'!F74 -> 11212.5 | C15: T37.2
A16: ROK033 Groundworks | B16: =SUM('T04-GROUNDWORKS'!F85:F95) -> 72649.238 | C16: T04.2 to T04.9
A17: ROK033 Exterior Elements | B17: =SUM('T04-GROUNDWORKS'!F103:F105) -> 10235 | C17: T37.2 to T37.3
A18: ROK036 Groundworks | B18: =SUM('T04-GROUNDWORKS'!F116:F124) -> 49239.263 | C18: T04.3 to T04.8
A19: ROK036 Exterior Elements | B19: =SUM('T04-GROUNDWORKS'!F131:F144) -> 223613.48 | C19: T37.2 to T37.12
A20: ROK076 Groundworks | B20: =SUM('T04-GROUNDWORKS'!F153:F161) -> 22648.388 | C20: T04.2 to T04.7
A21: ROK076 Exterior Elements | B21: =SUM('T04-GROUNDWORKS'!F169:F171) -> 25857.75 | C21: T37.2 to T37.3
A22: Base BOQ Direct Civil Works | B22: ='T04-GROUNDWORKS'!F173 -> 1783474.6 | C22: Subtotal
A23: Tender Completion / Risk Allowance (7.5%) | B23: ='T04-GROUNDWORKS'!F174 -> 133760.6 | C23: Allowance
A24: Tender Value Excluding GST | B24: ='T04-GROUNDWORKS'!F175 -> 1917235.2 | C24: Lump Sum
A25: GST (10%) | B25: ='T04-GROUNDWORKS'!F176 -> 191723.52 | C25: GST
A26: Tender Value Including GST | B26: ='T04-GROUNDWORKS'!F177 -> 2108958.7 | C26: Lump Sum
